File: example/example_dsc/output_data/single/cleaned_data.txt
	Temperature (C)	Heat Flow (W/g)
0	25.01	-2.29516
4	25.05	-2.2951
8	25.09	-2.29515
12	25.13	-2.2951571428571427
16	25.17	-2.2949333333333333
20	25.21	-2.2952
24	25.25	-2.2954833333333333
28	25.29	-2.2955
32	25.33	-2.2958
36	25.37	-2.296
40	25.41	-2.296275
44	25.45	-2.2965500000000003
48	25.49	-2.2971399999999997
52	25.53	-2.2975000000000003
56	25.57	-2.2979
60	25.61	-2.297625
64	25.65	-2.297216666666667
68	25.69	-2.2972
72	25.73	-2.297433333333333
76	25.77	-2.2979000000000003
80	25.81	-2.2989333333333333
84	25.85	-2.2995200000000002
88	25.89	-2.300433333333333
92	25.93	-2.3007500000000003
96	25.97	-2.301066666666667
100	26.01	-2.3011
104	26.05	-2.3008800000000003
108	26.09	-2.3007833333333334
112	26.13	-2.300675
116	26.17	-2.3006
120	26.21	-2.3002000000000002
124	26.25	-2.300125
128	26.29	-2.30016
132	26.33	-2.30035
136	26.37	-2.300666666666667
140	26.41	-2.30145
144	26.45	-2.30198
148	26.49	-2.302375
152	26.53	-2.302575
156	26.57	-2.3026666666666666
160	26.61	-2.30316
164	26.65	-2.30356
168	26.69	-2.3035333333333337
172	26.73	-2.3036333333333334
176	26.77	-2.3037
180	26.81	-2.3039
184	26.85	-2.304025
188	26.89	-2.3043666666666667
192	26.93	-2.304614285714286
196	26.97	-2.3051999999999997
200	27.01	-2.3060666666666667
204	27.05	-2.30625
208	27.09	-2.306175
212	27.13	-2.306
216	27.17	-2.30674
220	27.21	-2.3074666666666666
224	27.25	-2.3082285714285713
228	27.29	-2.30892
232	27.33	-2.3090333333333333
236	27.37	-2.309366666666667
240	27.41	-2.3095333333333334
244	27.45	-2.309625
248	27.49	-2.30945
252	27.53	-2.3093714285714286
256	27.57	-2.3094571428571427
260	27.61	-2.30962
264	27.65	-2.3095666666666665
268	27.69	-2.3095749999999997
272	27.73	-2.3099
276	27.77	-2.3104
280	27.81	-2.3103
284	27.85	-2.3099
288	27.89	-2.3100857142857145
292	27.93	-2.31036
296	27.97	-2.3105
300	28.01	-2.311
304	28.05	-2.311457142857143
308	28.09	-2.312
312	28.13	-2.3121666666666667
316	28.17	-2.312675
320	28.21	-2.3130333333333333
324	28.25	-2.3131333333333335
328	28.29	-2.31365
332	28.33	-2.3141
336	28.37	-2.314433333333333
340	28.41	-2.31478
344	28.45	-2.3151900000000003
348	28.49	-2.3153333333333332
352	28.53	-2.31585
356	28.57	-2.3160333333333334
360	28.61	-2.3162249999999998
364	28.65	-2.3164666666666665
368	28.69	-2.3167666666666666
372	28.73	-2.3175142857142856
376	28.77	-2.3181999999999996
380	28.81	-2.3186
384	28.85	-2.3191
388	28.89	-2.319266666666667
392	28.93	-2.31914
396	28.97	-2.3189
400	29.01	-2.31878
404	29.05	-2.31894
408	29.09	-2.3192333333333335
412	29.13	-2.31945
416	29.17	-2.319733333333333
420	29.21	-2.3202249999999998
424	29.25	-2.3205333333333336
428	29.29	-2.3205750000000003
432	29.33	-2.3209833333333334
436	29.37	-2.321
440	29.41	-2.3216
444	29.45	-2.32158
448	29.49	-2.322
452	29.53	-2.3219833333333333
456	29.57	-2.3221666666666665
460	29.61	-2.3228666666666666
464	29.65	-2.3229800000000003
468	29.69	-2.323225
472	29.73	-2.3241
476	29.77	-2.32465
480	29.81	-2.32505
484	29.85	-2.325416666666667
488	29.89	-2.32565
492	29.93	-2.32606
496	29.97	-2.32625
500	30.01	-2.326725
504	30.05	-2.3268285714285715
508	30.09	-2.3266400000000003
512	30.13	-2.32676
516	30.17	-2.32765
520	30.21	-2.3286
524	30.25	-2.32944
528	30.29	-2.3303249999999998
532	30.33	-2.331
536	30.37	-2.3312666666666666
540	30.41	-2.3315
544	30.45	-2.331375
548	30.49	-2.3310750000000002
552	30.53	-2.33115
556	30.57	-2.33112
560	30.61	-2.3310333333333335
564	30.65	-2.3313
568	30.69	-2.3317
572	30.73	-2.332325
576	30.77	-2.3326
580	30.81	-2.3329
584	30.85	-2.33332
588	30.89	-2.3337
592	30.93	-2.3342
596	30.97	-2.3350400000000002
600	31.01	-2.3353
604	31.05	-2.3358
608	31.09	-2.3363333333333336
612	31.13	-2.33662
616	31.17	-2.337
620	31.21	-2.337525
624	31.25	-2.3381
628	31.29	-2.3386
632	31.33	-2.339
636	31.37	-2.3394666666666666
640	31.41	-2.3400499999999997
644	31.45	-2.3406142857142855
648	31.49	-2.341
652	31.53	-2.34162
656	31.57	-2.341825
660	31.61	-2.341833333333333
664	31.65	-2.34196
668	31.69	-2.3425
672	31.73	-2.3432999999999997
676	31.77	-2.3445
680	31.81	-2.345166666666667
684	31.85	-2.3458833333333335
688	31.89	-2.346325
692	31.93	-2.3465249999999997
696	31.97	-2.34664
700	32.01	-2.346825
704	32.05	-2.347
708	32.09	-2.3469166666666665
712	32.13	-2.346725
716	32.17	-2.3470285714285715
720	32.21	-2.347025
724	32.25	-2.3471
728	32.29	-2.3473333333333333
732	32.33	-2.34776
736	32.37	-2.3480666666666665
740	32.41	-2.3487
744	32.45	-2.3491166666666667
748	32.49	-2.3495333333333335
752	32.53	-2.3500666666666667
756	32.57	-2.3505
760	32.61	-2.3506666666666667
764	32.65	-2.3512750000000002
768	32.69	-2.35155
772	32.73	-2.3520499999999998
776	32.77	-2.352475
780	32.81	-2.3532333333333333
784	32.85	-2.3537166666666667
788	32.89	-2.354433333333333
792	32.93	-2.35464
796	32.97	-2.3550500000000003
800	33.01	-2.3557
804	33.05	-2.356275
808	33.09	-2.3568399999999996
812	33.13	-2.3570857142857142
816	33.17	-2.3568857142857143
820	33.21	-2.357125
824	33.25	-2.35765
828	33.29	-2.35855
832	33.33	-2.3596250000000003
836	33.37	-2.3602
840	33.41	-2.360925
844	33.45	-2.3611
848	33.49	-2.3613
852	33.53	-2.3613500000000003
856	33.57	-2.3613999999999997
860	33.61	-2.36105
864	33.65	-2.3611428571428577
868	33.69	-2.3609666666666667
872	33.73	-2.3611
876	33.77	-2.3613333333333335
880	33.81	-2.3614
884	33.85	-2.3617749999999997
888	33.89	-2.3623
892	33.93	-2.3625666666666665
896	33.97	-2.362933333333333
900	34.01	-2.363166666666667
904	34.05	-2.3636
908	34.09	-2.364225
912	34.13	-2.3647
916	34.17	-2.36506
920	34.21	-2.36532
924	34.25	-2.36578
928	34.29	-2.366233333333333
932	34.33	-2.36655
936	34.37	-2.367125
940	34.41	-2.367566666666667
944	34.45	-2.36836
948	34.49	-2.3690333333333333
952	34.53	-2.36946
956	34.57	-2.3696333333333333
960	34.61	-2.36975
964	34.65	-2.3705
968	34.69	-2.3708666666666667
972	34.73	-2.3712600000000004
976	34.77	-2.3714500000000003
980	34.81	-2.37208
984	34.85	-2.37275
988	34.89	-2.373525
992	34.93	-2.374283333333333
996	34.97	-2.3750999999999998
1000	35.01	-2.37535
1004	35.05	-2.37596
1008	35.09	-2.37622
1012	35.13	-2.3765
1016	35.17	-2.3765
1020	35.21	-2.3765666666666667
1024	35.25	-2.376533333333333
1028	35.29	-2.3764333333333334
1032	35.33	-2.3765
1036	35.37	-2.3770333333333333
1040	35.41	-2.3774
1044	35.45	-2.3776
1048	35.49	-2.3779399999999997
1052	35.53	-2.37855
1056	35.57	-2.3790666666666667
1060	35.61	-2.3796
1064	35.65	-2.3800666666666666
1068	35.69	-2.3806
1072	35.73	-2.381025
1076	35.77	-2.38148
1080	35.81	-2.38165
1084	35.85	-2.382
1088	35.89	-2.38225
1092	35.93	-2.3827166666666666
1096	35.97	-2.383
1100	36.01	-2.3837
1104	36.05	-2.3843
1108	36.09	-2.38492
1112	36.13	-2.3853
1116	36.17	-2.385975
1120	36.21	-2.38635
1124	36.25	-2.38664
1128	36.29	-2.38678
1132	36.33	-2.3868
1136	36.37	-2.3874750000000002
1140	36.41	-2.3884499999999997
1144	36.45	-2.38966
1148	36.49	-2.39064
1152	36.53	-2.3916
1156	36.57	-2.3925
1160	36.61	-2.3930333333333333
1164	36.65	-2.3932
1168	36.69	-2.39335
1172	36.73	-2.393485714285714
1176	36.77	-2.39376
1180	36.81	-2.3941
1184	36.85	-2.394
1188	36.89	-2.3937999999999997
1192	36.93	-2.3939333333333335
1196	36.97	-2.394
1200	37.01	-2.3943333333333334
1204	37.05	-2.394825
1208	37.09	-2.3954750000000002
1212	37.13	-2.395728571428571
1216	37.17	-2.3959
1220	37.21	-2.39655
1224	37.25	-2.3969666666666662
1228	37.29	-2.3973500000000003
1232	37.33	-2.39784
1236	37.37	-2.3985
1240	37.41	-2.3991333333333333
1244	37.45	-2.399525
1248	37.49	-2.39982
1252	37.53	-2.400375
1256	37.57	-2.4006749999999997
1260	37.61	-2.4014333333333333
1264	37.65	-2.401825
1268	37.69	-2.40228
1272	37.73	-2.403
1276	37.77	-2.40364
1280	37.81	-2.4038666666666666
1284	37.85	-2.40444
1288	37.89	-2.4047
1292	37.93	-2.404425
1296	37.97	-2.4046
1300	38.01	-2.4053666666666667
1304	38.05	-2.406025
1308	38.09	-2.4069249999999998
1312	38.13	-2.4076333333333335
1316	38.17	-2.4082333333333334
1320	38.21	-2.4088499999999997
1324	38.25	-2.409
1328	38.29	-2.409266666666667
1332	38.33	-2.40945
1336	38.37	-2.409466666666667
1340	38.41	-2.4099500000000003
1344	38.45	-2.4099333333333335
1348	38.49	-2.41032
1352	38.53	-2.4103
1356	38.57	-2.4105
1360	38.61	-2.4109499999999997
1364	38.65	-2.411325
1368	38.69	-2.4118500000000003
1372	38.73	-2.4124
1376	38.77	-2.41316
1380	38.81	-2.4139
1384	38.85	-2.4145
1388	38.89	-2.4148199999999997
1392	38.93	-2.41538
1396	38.97	-2.4160666666666666
1400	39.01	-2.41645
1404	39.05	-2.41678
1408	39.09	-2.4174
1412	39.13	-2.4178833333333336
1416	39.17	-2.4187666666666665
1420	39.21	-2.41955
1424	39.25	-2.42
1428	39.29	-2.4204499999999998
1432	39.33	-2.4207
1436	39.37	-2.4213
1440	39.41	-2.4218333333333333
1444	39.45	-2.4225
1448	39.49	-2.423575
1452	39.53	-2.4236000000000004
1456	39.57	-2.423825
1460	39.61	-2.424533333333333
1464	39.65	-2.42515
1468	39.69	-2.42605
1472	39.73	-2.4267
1476	39.77	-2.42762
1480	39.81	-2.4282
1484	39.85	-2.4283
1488	39.89	-2.42855
1492	39.93	-2.428433333333333
1496	39.97	-2.428533333333333
1500	40.01	-2.4286
1504	40.05	-2.4286833333333333
1508	40.09	-2.428933333333333
1512	40.13	-2.42908
1516	40.17	-2.4292
1520	40.21	-2.4293
1524	40.25	-2.4296
1528	40.29	-2.43012
1532	40.33	-2.43058
1536	40.37	-2.4308
1540	40.41	-2.43125
1544	40.45	-2.4318666666666666
1548	40.49	-2.4325200000000002
1552	40.53	-2.43285
1556	40.57	-2.4329666666666667
1560	40.61	-2.4332999999999996
1564	40.65	-2.4335750000000003
1568	40.69	-2.4339500000000003
1572	40.73	-2.434466666666667
1576	40.77	-2.4349
1580	40.81	-2.4351
1584	40.85	-2.435625
1588	40.89	-2.4360999999999997
1592	40.93	-2.43696
1596	40.97	-2.43746
1600	41.01	-2.4380333333333333
1604	41.05	-2.4383833333333333
1608	41.09	-2.439
1612	41.13	-2.43955
1616	41.17	-2.4396
1620	41.21	-2.43945
1624	41.25	-2.4398
1628	41.29	-2.4405
1632	41.33	-2.44072
1636	41.37	-2.44165
1640	41.41	-2.442266666666667
1644	41.45	-2.4426
1648	41.49	-2.4431666666666665
1652	41.53	-2.4433
1656	41.57	-2.44326
1660	41.61	-2.44355
1664	41.65	-2.4436666666666667
1668	41.69	-2.4435
1672	41.73	-2.44365
1676	41.77	-2.4438999999999997
1680	41.81	-2.443966666666667
1684	41.85	-2.4442333333333335
1688	41.89	-2.4446250000000003
1692	41.93	-2.44502
1696	41.97	-2.44545
1700	42.01	-2.445975
1704	42.05	-2.446328571428572
1708	42.09	-2.4466
1712	42.13	-2.4470625
1716	42.17	-2.4478
1720	42.21	-2.44835
1724	42.25	-2.44864
1728	42.29	-2.449075
1732	42.33	-2.4495
1736	42.37	-2.45002
1740	42.41	-2.45065
1744	42.45	-2.45092
1748	42.49	-2.451575
1752	42.53	-2.45224
1756	42.57	-2.4524999999999997
1760	42.61	-2.4531
1764	42.65	-2.45364
1768	42.69	-2.4541500000000003
1772	42.73	-2.4546833333333336
1776	42.77	-2.4551499999999997
1780	42.81	-2.4558
1784	42.85	-2.4559833333333336
1788	42.89	-2.45606
1792	42.93	-2.4566333333333334
1796	42.97	-2.4572
1800	43.01	-2.4581666666666666
1804	43.05	-2.4590833333333335
1808	43.09	-2.4596142857142858
1812	43.13	-2.4603200000000003
1816	43.17	-2.460775
1820	43.21	-2.46102
1824	43.25	-2.461
1828	43.29	-2.46105
1832	43.33	-2.46135
1836	43.37	-2.4614999999999996
1840	43.41	-2.4616333333333333
1844	43.45	-2.4618285714285717
1848	43.49	-2.46224
1852	43.53	-2.46245
1856	43.57	-2.4627
1860	43.61	-2.46335
1864	43.65	-2.4636199999999997
1868	43.69	-2.46395
1872	43.73	-2.46434
1876	43.77	-2.4644333333333335
1880	43.81	-2.4648333333333334
1884	43.85	-2.4651666666666667
1888	43.89	-2.465333333333333
1892	43.93	-2.4661333333333335
1896	43.97	-2.4665666666666666
1900	44.01	-2.4669499999999998
1904	44.05	-2.4672666666666667
1908	44.09	-2.4675777777777776
1912	44.13	-2.4676833333333335
1916	44.17	-2.4681333333333337
1920	44.21	-2.46856
1924	44.25	-2.4688499999999998
1928	44.29	-2.469
1932	44.33	-2.46925
1936	44.37	-2.4696
1940	44.41	-2.47026
1944	44.45	-2.47074
1948	44.49	-2.4715
1952	44.53	-2.4718
1956	44.57	-2.4721
1960	44.61	-2.4725333333333332
1964	44.65	-2.47306
1968	44.69	-2.4739
1972	44.73	-2.4749285714285714
1976	44.77	-2.47615
1980	44.81	-2.4768666666666665
1984	44.85	-2.47734
1988	44.89	-2.4778000000000002
1992	44.93	-2.4776000000000002
1996	44.97	-2.47785
2000	45.01	-2.4777666666666662
2004	45.05	-2.4779166666666668
2008	45.09	-2.4778142857142855
2012	45.13	-2.477775
2016	45.17	-2.4779
2020	45.21	-2.47825
2024	45.25	-2.4784
2028	45.29	-2.478616666666667
2032	45.33	-2.47942
2036	45.37	-2.4795666666666665
2040	45.41	-2.4798
2044	45.45	-2.48002
2048	45.49	-2.480425
2052	45.53	-2.481
2056	45.57	-2.48135
2060	45.61	-2.4821999999999997
2064	45.65	-2.483014285714286
2068	45.69	-2.4834
2072	45.73	-2.4835999999999996
2076	45.77	-2.4840400000000002
2080	45.81	-2.4844000000000004
2084	45.85	-2.4846666666666666
2088	45.89	-2.485371428571429
2092	45.93	-2.48585
2096	45.97	-2.48625
2100	46.01	-2.486466666666667
2104	46.05	-2.4869499999999998
2108	46.09	-2.4873333333333334
2112	46.13	-2.487357142857143
2116	46.17	-2.48775
2120	46.21	-2.4884333333333335
2124	46.25	-2.4890499999999998
2128	46.29	-2.48895
2132	46.33	-2.48922
2136	46.37	-2.4897
2140	46.41	-2.4906666666666664
2144	46.45	-2.49136
2148	46.49	-2.49205
2152	46.53	-2.4924166666666667
2156	46.57	-2.4928333333333335
2160	46.61	-2.4934666666666665
2164	46.65	-2.4941000000000004
2168	46.69	-2.494325
2172	46.73	-2.4945833333333334
2176	46.77	-2.4946200000000003
2180	46.81	-2.49435
2184	46.85	-2.4942
2188	46.89	-2.4943
2192	46.93	-2.4943833333333334
2196	46.97	-2.4948
2200	47.01	-2.4948
2204	47.05	-2.4953
2208	47.09	-2.495425
2212	47.13	-2.496057142857143
2216	47.17	-2.4968
2220	47.21	-2.4970999999999997
2224	47.25	-2.497533333333333
2228	47.29	-2.49805
2232	47.33	-2.4988
2236	47.37	-2.4996
2240	47.41	-2.500175
2244	47.45	-2.5004000000000004
2248	47.49	-2.501075
2252	47.53	-2.501
2256	47.57	-2.501325
2260	47.61	-2.5016249999999998
2264	47.65	-2.501775
2268	47.69	-2.50235
2272	47.73	-2.5029666666666666
2276	47.77	-2.5036
2280	47.81	-2.5038666666666667
2284	47.85	-2.5038799999999997
2288	47.89	-2.5041
2292	47.93	-2.5046333333333335
2296	47.97	-2.505175
2300	48.01	-2.505
2304	48.05	-2.504957142857143
2308	48.09	-2.50554
2312	48.13	-2.5065000000000004
2316	48.17	-2.5074
2320	48.21	-2.5083
2324	48.25	-2.509275
2328	48.29	-2.510033333333333
2332	48.33	-2.510425
2336	48.37	-2.5108333333333333
2340	48.41	-2.5111000000000003
2344	48.45	-2.5112
2348	48.49	-2.5114
2352	48.53	-2.5119
2356	48.57	-2.5120600000000004
2360	48.61	-2.512233333333333
2364	48.65	-2.5126
2368	48.69	-2.5129333333333332
2372	48.73	-2.513128571428571
2376	48.77	-2.5133199999999998
2380	48.81	-2.5141
2384	48.85	-2.5147
2388	48.89	-2.5150666666666663
2392	48.93	-2.515333333333333
2396	48.97	-2.5153499999999998
2400	49.01	-2.5156666666666667
2404	49.05	-2.5159
2408	49.09	-2.51616
2412	49.13	-2.516725
2416	49.17	-2.517175
2420	49.21	-2.5178833333333333
2424	49.25	-2.5183750000000003
2428	49.29	-2.5188
2432	49.33	-2.51956
2436	49.37	-2.5199666666666665
2440	49.41	-2.5208500000000003
2444	49.45	-2.52145
2448	49.49	-2.521975
2452	49.53	-2.5223400000000002
2456	49.57	-2.5226666666666664
2460	49.61	-2.523275
2464	49.65	-2.523733333333333
2468	49.69	-2.5239999999999996
2472	49.73	-2.5246
2476	49.77	-2.5246
2480	49.81	-2.5243200000000003
2484	49.85	-2.5246
2488	49.89	-2.525166666666667
2492	49.93	-2.5256
2496	49.97	-2.5263666666666666
2500	50.01	-2.5270333333333332
2504	50.05	-2.5277
2508	50.09	-2.5281333333333333
2512	50.13	-2.528566666666667
2516	50.17	-2.52865
2520	50.21	-2.5284166666666668
2524	50.25	-2.5284
2528	50.29	-2.5283333333333338
2532	50.33	-2.52846
2536	50.37	-2.5289
2540	50.41	-2.52928
2544	50.45	-2.529425
2548	50.49	-2.5299
2552	50.53	-2.530025
2556	50.57	-2.5305
2560	50.61	-2.530875
2564	50.65	-2.53115
2568	50.69	-2.5315
2572	50.73	-2.532
2576	50.77	-2.5325200000000003
2580	50.81	-2.532775
2584	50.85	-2.533
2588	50.89	-2.533075
2592	50.93	-2.5333
2596	50.97	-2.5337
2600	51.01	-2.5346
2604	51.05	-2.53532
2608	51.09	-2.535633333333333
2612	51.13	-2.5360666666666667
2616	51.17	-2.536466666666667
2620	51.21	-2.5364
2624	51.25	-2.5362
2628	51.29	-2.5361
2632	51.33	-2.5361333333333334
2636	51.37	-2.53625
2640	51.41	-2.5365
2644	51.45	-2.537042857142857
2648	51.49	-2.5378499999999997
2652	51.53	-2.53845
2656	51.57	-2.538816666666667
2660	51.61	-2.53914
2664	51.65	-2.5395833333333333
2668	51.69	-2.540175
2672	51.73	-2.5408500000000003
2676	51.77	-2.5414000000000003
2680	51.81	-2.5420666666666665
2684	51.85	-2.54258
2688	51.89	-2.542666666666667
2692	51.93	-2.542614285714286
2696	51.97	-2.5427400000000002
2700	52.01	-2.543066666666667
2704	52.05	-2.5433499999999998
2708	52.09	-2.5434200000000002
2712	52.13	-2.54336
2716	52.17	-2.5438666666666667
2720	52.21	-2.5438
2724	52.25	-2.544233333333333
2728	52.29	-2.5445333333333333
2732	52.33	-2.54486
2736	52.37	-2.5450666666666666
2740	52.41	-2.545666666666667
2744	52.45	-2.54614
2748	52.49	-2.5466
2752	52.53	-2.54685
2756	52.57	-2.5472
2760	52.61	-2.54764
2764	52.65	-2.54816
2768	52.69	-2.5492000000000004
2772	52.73	-2.549842857142857
2776	52.77	-2.5504666666666664
2780	52.81	-2.5509500000000003
2784	52.85	-2.551633333333333
2788	52.89	-2.552025
2792	52.93	-2.5525200000000003
2796	52.97	-2.553
2800	53.01	-2.5532333333333335
2804	53.05	-2.55374
2808	53.09	-2.5545000000000004
2812	53.13	-2.5551
2816	53.17	-2.55555
2820	53.21	-2.55566
2824	53.25	-2.5559250000000002
2828	53.29	-2.5563
2832	53.33	-2.5567285714285717
2836	53.37	-2.5569
2840	53.41	-2.5568
2844	53.45	-2.5571200000000003
2848	53.49	-2.5576499999999998
2852	53.53	-2.5586333333333333
2856	53.57	-2.5595499999999998
2860	53.61	-2.5605
2864	53.65	-2.56104
2868	53.69	-2.561666666666667
2872	53.73	-2.56195
2876	53.77	-2.561733333333333
2880	53.81	-2.5616499999999998
2884	53.85	-2.5614
2888	53.89	-2.5614999999999997
2892	53.93	-2.562
2896	53.97	-2.56195
2900	54.01	-2.5618600000000002
2904	54.05	-2.5618
2908	54.09	-2.5620833333333333
2912	54.13	-2.56198
2916	54.17	-2.562333333333333
2920	54.21	-2.5628333333333333
2924	54.25	-2.563283333333333
2928	54.29	-2.56365
2932	54.33	-2.5639
2936	54.37	-2.5641
2940	54.41	-2.564666666666667
2944	54.45	-2.565025
2948	54.49	-2.5654166666666667
2952	54.53	-2.5656
2956	54.57	-2.5661
2960	54.61	-2.566433333333333
2964	54.65	-2.56685
2968	54.69	-2.5671
2972	54.73	-2.567525
2976	54.77	-2.5682400000000003
2980	54.81	-2.5685
2984	54.85	-2.5689333333333333
2988	54.89	-2.56955
2992	54.93	-2.5694833333333333
2996	54.97	-2.5695333333333337
3000	55.01	-2.5702
3004	55.05	-2.570625
3008	55.09	-2.5710800000000003
3012	55.13	-2.571466666666667
3016	55.17	-2.571875
3020	55.21	-2.5721333333333334
3024	55.25	-2.57275
3028	55.29	-2.57315
3032	55.33	-2.5737666666666663
3036	55.37	-2.5741666666666667
3040	55.41	-2.57425
3044	55.45	-2.5744249999999997
3048	55.49	-2.5744333333333334
3052	55.53	-2.5744666666666665
3056	55.57	-2.57485
3060	55.61	-2.5754
3064	55.65	-2.575825
3068	55.69	-2.576025
3072	55.73	-2.5766428571428572
3076	55.77	-2.57715
3080	55.81	-2.5774666666666666
3084	55.85	-2.5777
3088	55.89	-2.578
3092	55.93	-2.5780333333333334
3096	55.97	-2.57876
3100	56.02	-2.578816666666667
3104	56.06	-2.5792
3108	56.1	-2.57995
3112	56.14	-2.5802
3116	56.18	-2.58065
3120	56.22	-2.5809333333333337
3124	56.26	-2.581175
3128	56.3	-2.5817333333333337
3132	56.34	-2.5823
3136	56.38	-2.58235
3140	56.42	-2.5827999999999998
3144	56.46	-2.5833
3148	56.5	-2.58365
3152	56.54	-2.5838666666666668
3156	56.58	-2.58412
3160	56.62	-2.5843999999999996
3164	56.66	-2.5843000000000003
3168	56.7	-2.5846400000000003
3172	56.74	-2.5852000000000004
3176	56.78	-2.585725
3180	56.82	-2.58615
3184	56.86	-2.58664
3188	56.9	-2.5868428571428574
3192	56.94	-2.5871250000000003
3196	56.98	-2.5877166666666667
3200	57.02	-2.5881000000000003
3204	57.06	-2.5885499999999997
3208	57.1	-2.58865
3212	57.14	-2.589
3216	57.18	-2.5891333333333333
3220	57.22	-2.5891
3224	57.26	-2.5893
3228	57.3	-2.5896666666666666
3232	57.34	-2.5899
3236	57.38	-2.59014
3240	57.42	-2.5905
3244	57.46	-2.59065
3248	57.5	-2.5906166666666666
3252	57.54	-2.590666666666667
3256	57.58	-2.5907600000000004
3260	57.62	-2.5907
3264	57.66	-2.591066666666667
3268	57.7	-2.5913600000000003
3272	57.74	-2.5914285714285716
3276	57.78	-2.592033333333333
3280	57.82	-2.5921
3284	57.86	-2.5923999999999996
3288	57.9	-2.5925833333333332
3292	57.94	-2.593
3296	57.98	-2.5934
3300	58.02	-2.5936333333333335
3304	58.06	-2.59375
3308	58.1	-2.5943
3312	58.14	-2.594133333333333
3316	58.18	-2.5941571428571426
3320	58.22	-2.59412
3324	58.26	-2.59435
3328	58.3	-2.594375
3332	58.34	-2.5949
3336	58.38	-2.5951
3340	58.42	-2.595166666666667
3344	58.46	-2.5952
3348	58.5	-2.595166666666667
3352	58.54	-2.595466666666667
3356	58.58	-2.5955
3360	58.62	-2.59556
3364	58.66	-2.5955500000000002
3368	58.7	-2.5957333333333334
3372	58.74	-2.5959
3376	58.78	-2.5957333333333334
3380	58.82	-2.59555
3384	58.86	-2.5959
3388	58.9	-2.59624
3392	58.94	-2.5964666666666667
3396	58.98	-2.5967
3400	59.02	-2.5964799999999997
3404	59.06	-2.59685
3408	59.1	-2.5974
3412	59.14	-2.5976999999999997
3416	59.18	-2.5982
3420	59.22	-2.5981666666666663
3424	59.26	-2.59794
3428	59.3	-2.5979
3432	59.34	-2.59794
3436	59.38	-2.5984333333333334
3440	59.42	-2.598325
3444	59.46	-2.598475
3448	59.5	-2.5989500000000003
3452	59.54	-2.59885
3456	59.58	-2.5987999999999998
3460	59.62	-2.5989666666666666
3464	59.66	-2.599
3468	59.7	-2.5989750000000003
3472	59.74	-2.59925
3476	59.78	-2.599275
3480	59.82	-2.599275
3484	59.86	-2.59932
3488	59.9	-2.59932
3492	59.94	-2.5993
3496	59.98	-2.5997
3500	60.02	-2.5997
3504	60.06	-2.5997333333333335
3508	60.1	-2.60004
3512	60.14	-2.60012
3516	60.18	-2.5999
3520	60.22	-2.60005
3524	60.26	-2.5997500000000002
3528	60.3	-2.599466666666667
3532	60.34	-2.5993833333333334
3536	60.38	-2.59954
3540	60.42	-2.6002
3544	60.46	-2.60034
3548	60.5	-2.600175
3552	60.54	-2.6002
3556	60.58	-2.6004
3560	60.62	-2.600433333333333
3564	60.66	-2.6001
3568	60.7	-2.6001857142857143
3572	60.74	-2.6002
3576	60.78	-2.600125
3580	60.82	-2.5999
3584	60.86	-2.599766666666667
3588	60.9	-2.5997
3592	60.94	-2.599816666666667
3596	60.98	-2.59984
3600	61.02	-2.599875
3604	61.06	-2.5998
3608	61.1	-2.5999
3612	61.14	-2.5999
3616	61.18	-2.6000799999999997
3620	61.22	-2.6001666666666665
3624	61.26	-2.600075
3628	61.3	-2.59982
3632	61.34	-2.5998
3636	61.38	-2.599557142857143
3640	61.42	-2.599525
3644	61.46	-2.599275
3648	61.5	-2.59882
3652	61.54	-2.5988
3656	61.58	-2.5989833333333334
3660	61.62	-2.59915
3664	61.66	-2.59925
3668	61.7	-2.59906
3672	61.74	-2.59865
3676	61.78	-2.598725
3680	61.82	-2.5986333333333334
3684	61.86	-2.59885
3688	61.9	-2.5984749999999996
3692	61.94	-2.5983
3696	61.98	-2.598316666666667
3700	62.02	-2.597925
3704	62.06	-2.598
3708	62.1	-2.5979
3712	62.14	-2.5978666666666665
3716	62.18	-2.5983799999999997
3720	62.22	-2.5985
3724	62.26	-2.5980499999999997
3728	62.3	-2.598
3732	62.34	-2.598175
3736	62.38	-2.5983714285714288
3740	62.42	-2.5984749999999996
3744	62.46	-2.5983
3748	62.5	-2.59806
3752	62.54	-2.597975
3756	62.58	-2.5979
3760	62.62	-2.598125
3764	62.66	-2.598133333333333
3768	62.7	-2.5980999999999996
3772	62.74	-2.5979
3776	62.78	-2.5978666666666665
3780	62.82	-2.5981666666666663
3784	62.86	-2.5985199999999997
3788	62.9	-2.598375
3792	62.94	-2.5982
3796	62.98	-2.598757142857143
3800	63.02	-2.5986666666666665
3804	63.06	-2.5984499999999997
3808	63.1	-2.5988
3812	63.14	-2.5987400000000003
3816	63.18	-2.598825
3820	63.22	-2.599133333333333
3824	63.26	-2.5991
3828	63.3	-2.5995
3832	63.34	-2.5997500000000002
3836	63.38	-2.5998799999999997
3840	63.42	-2.5999
3844	63.46	-2.6
3848	63.5	-2.6005
3852	63.54	-2.6007499999999997
3856	63.58	-2.6012666666666666
3860	63.62	-2.60175
3864	63.66	-2.6023
3868	63.7	-2.6028333333333333
3872	63.74	-2.6031400000000002
3876	63.78	-2.6037
3880	63.82	-2.6040666666666668
3884	63.86	-2.6045
3888	63.9	-2.60515
3892	63.94	-2.6056
3896	63.98	-2.606
3900	64.02	-2.6066
3904	64.06	-2.607275
3908	64.1	-2.6081
3912	64.14	-2.6090500000000003
3916	64.18	-2.6096250000000003
3920	64.22	-2.6102333333333334
3924	64.26	-2.611
3928	64.3	-2.6116333333333333
3932	64.34	-2.6123
3936	64.38	-2.6132500000000003
3940	64.42	-2.6140749999999997
3944	64.46	-2.61502
3948	64.5	-2.616275
3952	64.54	-2.6172500000000003
3956	64.58	-2.6183833333333335
3960	64.62	-2.6193000000000004
3964	64.66	-2.6201
3968	64.7	-2.62104
3972	64.74	-2.62215
3976	64.78	-2.6236
3980	64.82	-2.6244
3984	64.86	-2.624925
3988	64.9	-2.62634
3992	64.94	-2.6282
3996	64.98	-2.630075
4000	65.02	-2.63185
4004	65.06	-2.633366666666667
4008	65.1	-2.63495
4012	65.14	-2.63618
4016	65.18	-2.637275
4020	65.22	-2.63888
4024	65.26	-2.64005
4028	65.3	-2.64142
4032	65.34	-2.642533333333333
4036	65.38	-2.64352
4040	65.42	-2.6450199999999997
4044	65.46	-2.6464666666666665
4048	65.5	-2.6481333333333335
4052	65.54	-2.6497333333333333
4056	65.58	-2.6513400000000003
4060	65.62	-2.6529599999999998
4064	65.66	-2.6546333333333334
4068	65.7	-2.656275
4072	65.74	-2.6579
4076	65.78	-2.6595666666666666
4080	65.82	-2.661225
4084	65.86	-2.6628499999999997
4088	65.9	-2.66455
4092	65.94	-2.66685
4096	65.98	-2.6689
4100	66.02	-2.670533333333333
4104	66.06	-2.67256
4108	66.1	-2.6746499999999997
4112	66.14	-2.67672
4116	66.18	-2.67888
4120	66.22	-2.6802333333333337
4124	66.26	-2.6819
4128	66.3	-2.6836
4132	66.34	-2.6855166666666666
4136	66.38	-2.6875714285714283
4140	66.42	-2.6893000000000002
4144	66.46	-2.691133333333333
4148	66.5	-2.6933599999999998
4152	66.54	-2.6947
4156	66.58	-2.696825
4160	66.62	-2.6984250000000003
4164	66.66	-2.6998
4168	66.7	-2.7016400000000003
4172	66.74	-2.7032666666666665
4176	66.78	-2.7046
4180	66.82	-2.70606
4184	66.86	-2.707666666666667
4188	66.9	-2.70944
4192	66.94	-2.71075
4196	66.98	-2.71305
4200	67.02	-2.7148333333333334
4204	67.06	-2.71625
4208	67.1	-2.71802
4212	67.14	-2.719666666666667
4216	67.18	-2.7215000000000003
4220	67.22	-2.7229599999999996
4224	67.26	-2.7243000000000004
4228	67.3	-2.72636
4232	67.34	-2.72805
4236	67.38	-2.7294
4240	67.42	-2.7313
4244	67.46	-2.73265
4248	67.5	-2.733775
4252	67.54	-2.735575
4256	67.58	-2.7368
4260	67.62	-2.738
4264	67.66	-2.7394249999999998
4268	67.7	-2.740677777777778
4272	67.74	-2.74165
4276	67.78	-2.743
4280	67.82	-2.7442
4284	67.86	-2.7457999999999996
4288	67.9	-2.7468
4292	67.94	-2.7475
4296	67.98	-2.748525
4300	68.02	-2.749333333333333
4304	68.06	-2.7499
4308	68.1	-2.7510666666666665
4312	68.14	-2.752133333333333
4316	68.18	-2.7530666666666668
4320	68.22	-2.75405
4324	68.26	-2.754766666666667
4328	68.3	-2.755333333333333
4332	68.34	-2.7563
4336	68.38	-2.7569375000000003
4340	68.42	-2.7574
4344	68.46	-2.757975
4348	68.5	-2.75865
4352	68.54	-2.759225
4356	68.58	-2.760414285714286
4360	68.62	-2.76116
4364	68.66	-2.7620333333333336
4368	68.7	-2.7627666666666664
4372	68.74	-2.7637
4376	68.78	-2.7644200000000003
4380	68.82	-2.76518
4384	68.86	-2.7657249999999998
4388	68.9	-2.7663333333333333
4392	68.94	-2.7670666666666666
4396	68.98	-2.767583333333333
4400	69.02	-2.768725
4404	69.06	-2.7693
4408	69.1	-2.7699
4412	69.14	-2.77056
4416	69.18	-2.7712
4420	69.22	-2.77195
4424	69.26	-2.77215
4428	69.3	-2.77266
4432	69.34	-2.773175
4436	69.38	-2.773875
4440	69.42	-2.7744
4444	69.46	-2.7752714285714286
4448	69.5	-2.77602
4452	69.54	-2.7765
4456	69.58	-2.777225
4460	69.62	-2.7774
4464	69.66	-2.7781
4468	69.7	-2.7786999999999997
4472	69.74	-2.77894
4476	69.78	-2.779925
4480	69.82	-2.7804333333333333
4484	69.86	-2.78085
4488	69.9	-2.7810666666666664
4492	69.94	-2.7816
4496	69.98	-2.782175
4500	70.02	-2.78292
4504	70.06	-2.78322
4508	70.1	-2.7832
4512	70.14	-2.78335
4516	70.18	-2.7836
4520	70.22	-2.7838000000000003
4524	70.26	-2.7842000000000002
4528	70.3	-2.7843
4532	70.34	-2.7847500000000003
4536	70.38	-2.7854
4540	70.42	-2.78584
4544	70.46	-2.78665
4548	70.5	-2.7871285714285716
4552	70.54	-2.78765
4556	70.58	-2.78905
4560	70.62	-2.79018
4564	70.66	-2.791225
4568	70.7	-2.7917
4572	70.74	-2.7924800000000003
4576	70.78	-2.7932200000000003
4580	70.82	-2.7939666666666665
4584	70.86	-2.7942666666666667
4588	70.9	-2.7951
4592	70.94	-2.795666666666667
4596	70.98	-2.79676
4600	71.02	-2.7974333333333337
4604	71.06	-2.798375
4608	71.1	-2.799125
4612	71.14	-2.7999
4616	71.18	-2.8005500000000003
4620	71.22	-2.8013
4624	71.26	-2.801766666666667
4628	71.3	-2.80235
4632	71.34	-2.8028333333333335
4636	71.38	-2.8032285714285714
4640	71.42	-2.804025
4644	71.46	-2.8043666666666667
4648	71.5	-2.80512
4652	71.54	-2.80564
4656	71.58	-2.8058333333333336
4660	71.62	-2.8064
4664	71.66	-2.8068166666666667
4668	71.7	-2.8073799999999998
4672	71.74	-2.808
4676	71.78	-2.8084499999999997
4680	71.82	-2.8089166666666667
4684	71.86	-2.8094
4688	71.9	-2.8097
4692	71.94	-2.8103000000000002
4696	71.98	-2.81095
4700	72.02	-2.8114000000000003
4704	72.06	-2.811825
4708	72.1	-2.8122333333333334
4712	72.14	-2.812583333333333
4716	72.18	-2.813275
4720	72.22	-2.813575
4724	72.26	-2.8139000000000003
4728	72.3	-2.814425
4732	72.34	-2.814742857142857
4736	72.38	-2.8150333333333335
4740	72.42	-2.815533333333333
4744	72.46	-2.815675
4748	72.5	-2.81574
4752	72.54	-2.8163
4756	72.58	-2.8169750000000002
4760	72.62	-2.8173666666666666
4764	72.66	-2.8181666666666665
4768	72.7	-2.8191800000000002
4772	72.74	-2.81965
4776	72.78	-2.8202499999999997
4780	72.82	-2.8211
4784	72.86	-2.821575
4788	72.9	-2.8217499999999998
4792	72.94	-2.82225
4796	72.98	-2.8231
4800	73.02	-2.82396
4804	73.06	-2.8244333333333334
4808	73.1	-2.825075
4812	73.14	-2.8261600000000002
4816	73.18	-2.8273
4820	73.22	-2.827833333333333
4824	73.26	-2.8285
4828	73.3	-2.82914
4832	73.34	-2.82975
4836	73.38	-2.83032
4840	73.42	-2.830716666666667
4844	73.46	-2.8311
4848	73.5	-2.8314
4852	73.54	-2.83164
4856	73.58	-2.83208
4860	73.62	-2.832433333333333
4864	73.66	-2.8331999999999997
4868	73.7	-2.833525
4872	73.74	-2.8336333333333332
4876	73.78	-2.8339166666666666
4880	73.82	-2.8345000000000002
4884	73.86	-2.8353
4888	73.9	-2.83605
4892	73.94	-2.836575
4896	73.98	-2.836875
4900	74.02	-2.837625
4904	74.06	-2.8379
4908	74.1	-2.8388999999999998
4912	74.14	-2.8392749999999998
4916	74.18	-2.840275
4920	74.22	-2.84075
4924	74.26	-2.841475
4928	74.3	-2.8424799999999997
4932	74.34	-2.843557142857143
4936	74.38	-2.84402
4940	74.42	-2.8449666666666666
4944	74.46	-2.8461499999999997
4948	74.5	-2.8466
4952	74.54	-2.8474
4956	74.58	-2.848
4960	74.62	-2.84885
4964	74.66	-2.84956
4968	74.7	-2.85065
4972	74.74	-2.85145
4976	74.78	-2.852375
4980	74.82	-2.852925
4984	74.86	-2.853425
4988	74.9	-2.85425
4992	74.94	-2.85494
4996	74.98	-2.8557
5000	75.02	-2.855975
5004	75.06	-2.8564666666666665
5008	75.1	-2.8571333333333335
5012	75.14	-2.8575600000000003
5016	75.18	-2.8576
5020	75.22	-2.8578
5024	75.26	-2.8582
5028	75.3	-2.858511111111111
5032	75.34	-2.858966666666667
5036	75.38	-2.8593200000000003
5040	75.42	-2.8597
5044	75.46	-2.8597799999999998
5048	75.5	-2.86035
5052	75.54	-2.8606
5056	75.58	-2.8608
5060	75.62	-2.8614
5064	75.66	-2.8625000000000003
5068	75.7	-2.86334
5072	75.74	-2.86435
5076	75.78	-2.8643666666666667
5080	75.82	-2.8645
5084	75.86	-2.864875
5088	75.9	-2.86518
5092	75.94	-2.8658
5096	75.98	-2.86625
5100	76.02	-2.8667
5104	76.06	-2.867125
5108	76.1	-2.8674999999999997
5112	76.14	-2.86786
5116	76.18	-2.8684
5120	76.22	-2.8686
5124	76.26	-2.869125
5128	76.3	-2.8696
5132	76.34	-2.8702666666666663
5136	76.38	-2.8708
5140	76.42	-2.871225
5144	76.46	-2.87154
5148	76.5	-2.872
5152	76.54	-2.8726333333333334
5156	76.58	-2.87316
5160	76.62	-2.873466666666667
5164	76.66	-2.8739500000000002
5168	76.7	-2.874614285714286
5172	76.74	-2.8750666666666667
5176	76.78	-2.87526
5180	76.82	-2.8753333333333337
5184	76.86	-2.8759333333333337
5188	76.9	-2.876533333333333
5192	76.94	-2.87728
5196	76.98	-2.8776571428571427
5200	77.02	-2.8782333333333336
5204	77.06	-2.8783
5208	77.1	-2.8785666666666665
5212	77.14	-2.8785666666666665
5216	77.18	-2.878733333333333
5220	77.22	-2.8783999999999996
5224	77.26	-2.8788666666666667
5228	77.3	-2.8798500000000002
5232	77.34	-2.8805
5236	77.38	-2.88145
5240	77.42	-2.88245
5244	77.46	-2.883233333333333
5248	77.5	-2.8839
5252	77.54	-2.884533333333333
5256	77.58	-2.88485
5260	77.62	-2.8855000000000004
5264	77.66	-2.886433333333333
5268	77.7	-2.88704
5272	77.74	-2.8876666666666666
5276	77.78	-2.8887666666666667
5280	77.82	-2.889466666666667
5284	77.86	-2.88995
5288	77.9	-2.8905999999999996
5292	77.94	-2.8910666666666667
5296	77.98	-2.8915
5300	78.02	-2.891833333333333
5304	78.06	-2.8922
5308	78.1	-2.8926
5312	78.14	-2.892814285714286
5316	78.18	-2.89308
5320	78.22	-2.8937
5324	78.26	-2.8945333333333334
5328	78.3	-2.8951285714285713
5332	78.34	-2.8954500000000003
5336	78.38	-2.8953857142857147
5340	78.42	-2.8951875
5344	78.46	-2.8953333333333333
5348	78.5	-2.895383333333333
5352	78.54	-2.8958666666666666
5356	78.58	-2.8962333333333334
5360	78.62	-2.8974666666666664
5364	78.66	-2.89855
5368	78.7	-2.8998666666666666
5372	78.74	-2.9008333333333334
5376	78.78	-2.9019999999999997
5380	78.82	-2.9029749999999996
5384	78.86	-2.903966666666667
5388	78.9	-2.9044000000000003
5392	78.94	-2.9050000000000002
5396	78.98	-2.90605
5400	79.02	-2.906725
5404	79.06	-2.9069833333333333
5408	79.1	-2.90746
5412	79.14	-2.9082
5416	79.18	-2.9086999999999996
5420	79.22	-2.9092599999999997
5424	79.26	-2.910125
5428	79.3	-2.9110799999999997
5432	79.34	-2.9115200000000003
5436	79.38	-2.9118500000000003
5440	79.42	-2.9123200000000002
5444	79.46	-2.91278
5448	79.5	-2.913325
5452	79.54	-2.9139
5456	79.58	-2.9141333333333335
5460	79.62	-2.9143333333333334
5464	79.66	-2.9149
5468	79.7	-2.9156833333333334
5472	79.74	-2.916233333333333
5476	79.78	-2.917
5480	79.82	-2.91775
5484	79.86	-2.918566666666667
5488	79.9	-2.919275
5492	79.94	-2.919566666666667
5496	79.98	-2.91975
5500	80.02	-2.920425
5504	80.06	-2.921
5508	80.1	-2.92108
5512	80.14	-2.921583333333333
5516	80.18	-2.92238
5520	80.22	-2.92255
5524	80.26	-2.9231
5528	80.3	-2.9239333333333333
5532	80.34	-2.924625
5536	80.38	-2.92492
5540	80.42	-2.9254625
5544	80.46	-2.925925
5548	80.5	-2.9262
5552	80.54	-2.9267333333333334
5556	80.58	-2.926975
5560	80.62	-2.9274750000000003
5564	80.66	-2.92812
5568	80.7	-2.92845
5572	80.74	-2.9288666666666665
5576	80.78	-2.929057142857143
5580	80.82	-2.9295
5584	80.86	-2.9299999999999997
5588	80.9	-2.93044
5592	80.94	-2.9307499999999997
5596	80.98	-2.93134
5600	81.02	-2.9318000000000004
5604	81.06	-2.9319
5608	81.1	-2.9319
5612	81.14	-2.9326666666666665
5616	81.18	-2.9334
5620	81.22	-2.933875
5624	81.26	-2.934475
5628	81.3	-2.9349000000000003
5632	81.34	-2.9356333333333335
5636	81.38	-2.9362250000000003
5640	81.42	-2.9368
5644	81.46	-2.9374000000000002
5648	81.5	-2.93785
5652	81.54	-2.9384
5656	81.58	-2.93866
5660	81.62	-2.9391
5664	81.66	-2.9392
5668	81.7	-2.9396
5672	81.74	-2.9404600000000003
5676	81.78	-2.9410666666666665
5680	81.82	-2.94185
5684	81.86	-2.942525
5688	81.9	-2.9429999999999996
5692	81.94	-2.9432666666666663
5696	81.98	-2.9440714285714287
5700	82.02	-2.9444
5704	82.06	-2.944675
5708	82.1	-2.9450250000000002
5712	82.14	-2.9453
5716	82.18	-2.9459999999999997
5720	82.22	-2.94706
5724	82.26	-2.9478
5728	82.3	-2.94845
5732	82.34	-2.9491666666666667
5736	82.38	-2.949616666666667
5740	82.42	-2.9503500000000003
5744	82.46	-2.9509333333333334
5748	82.5	-2.951233333333333
5752	82.54	-2.951725
5756	82.58	-2.9524666666666666
5760	82.62	-2.9535
5764	82.66	-2.95435
5768	82.7	-2.9548285714285716
5772	82.74	-2.9553999999999996
5776	82.78	-2.955966666666667
5780	82.82	-2.9563666666666664
5784	82.86	-2.9566500000000002
5788	82.9	-2.9576000000000002
5792	82.94	-2.958133333333333
5796	82.98	-2.958528571428572
5800	83.02	-2.9592
5804	83.06	-2.9598
5808	83.1	-2.960825
5812	83.14	-2.96174
5816	83.18	-2.9618
5820	83.22	-2.9621500000000003
5824	83.26	-2.96264
5828	83.3	-2.963533333333333
5832	83.34	-2.964066666666667
5836	83.38	-2.964742857142857
5840	83.42	-2.9653833333333335
5844	83.46	-2.9658
5848	83.5	-2.9657
5852	83.54	-2.96614
5856	83.58	-2.9669
5860	83.62	-2.9674
5864	83.66	-2.968
5868	83.7	-2.96834
5872	83.74	-2.9688600000000003
5876	83.78	-2.9691714285714284
5880	83.82	-2.97
5884	83.86	-2.9707
5888	83.9	-2.971433333333333
5892	83.94	-2.9721666666666664
5896	83.98	-2.9725
5900	84.02	-2.973075
5904	84.06	-2.973733333333333
5908	84.1	-2.9745333333333335
5912	84.14	-2.974816666666667
5916	84.18	-2.9754
5920	84.22	-2.9761
5924	84.26	-2.976566666666667
5928	84.3	-2.9768499999999998
5932	84.34	-2.97748
5936	84.38	-2.97792
5940	84.42	-2.9785600000000003
5944	84.46	-2.9789
5948	84.5	-2.9793
5952	84.54	-2.980066666666667
5956	84.58	-2.98082
5960	84.62	-2.98116
5964	84.66	-2.9815
5968	84.7	-2.98185
5972	84.74	-2.982225
5976	84.78	-2.9826714285714284
5980	84.82	-2.9835333333333334
5984	84.86	-2.984166666666667
5988	84.9	-2.9847
5992	84.94	-2.9852
5996	84.98	-2.9861600000000004
5997	84.99	-2.98625