File: example/example_dsc/output_data/single/cleaned_data.txt
	Temperature (C)	Heat Flow (W/g)
0	25.01	-0.007622586256123665
4	25.05	-0.007173281179661206
8	25.09	-0.006833976089873239
12	25.13	-0.006451813813974638
16	25.17	-0.005838699066725184
20	25.21	-0.005716060356084629
24	25.25	-0.005610088079647468
28	25.29	-0.005237448810949452
32	25.33	-0.0051481424428416744
36	25.37	-0.004958835521321259
40	25.41	-0.0048445279125601814
44	25.45	-0.0047302194699359035
48	25.49	-0.0049309100344876455
52	25.53	-0.004901599435151116
56	25.57	-0.004912287488451739
60	25.61	-0.004247973998271259
64	25.65	-0.0034503254228086533
68	25.69	-0.003044341542676854
72	25.73	-0.002888355462854708
76	25.77	-0.0029657002805394406
80	25.81	-0.003609709085525825
84	25.85	-0.0038070482930310234
88	25.89	-0.004331050975908024
92	25.93	-0.004258383530401755
96	25.97	-0.004185712342061887
100	26.01	-0.0038297037856551697
104	26.05	-0.0032203575588463096
108	26.09	-0.0027343400165218412
112	26.13	-0.0022366508386397754
116	26.17	-0.0017722896982199643
120	26.21	-0.0009829229293876196
124	26.25	-0.0005185501952560401
128	26.29	-0.00016417115612643585
132	26.33	3.521452907939704e-05
136	26.37	0.00010794053526863578
140	26.41	-0.00028599279582230963
144	26.45	-0.00042658512232707224
148	26.49	-0.00043216943531554364
152	26.53	-0.00024274539171065257
156	26.57	5.502068598950416e-05
160	26.61	-4.887085741067665e-05
164	26.65	-5.941967699207851e-05
168	26.69	0.00035670790550401676
172	26.73	0.0006461789016567465
176	26.77	0.0009689936562771173
180	26.81	0.0011584858474908977
184	26.85	0.0014229891533599215
188	26.89	0.0014708372519089963
192	26.93	0.0016127447734510802
196	26.97	0.0014165692053342838
200	27.01	0.0009394537490772237
204	27.05	0.0011456844631743124
208	27.09	0.0016102616916882084
212	27.13	0.0021748524452038787
216	27.17	0.0018244570674625926
220	27.21	0.001487409235455317
224	27.25	0.0011151378641880427
228	27.29	0.0008133575828130901
232	27.33	0.0010896877822497153
236	27.37	0.001146033567593907
240	27.41	0.0013690619485977606
244	27.45	0.0016671066014937175
248	27.49	0.002231834535708188
252	27.53	0.002700150855851291
256	27.57	0.0030041987616815646
260	27.61	0.0032311214528153442
264	27.65	0.00367425260491272
268	27.69	0.00405573541737958
272	27.73	0.0041205702324211835
276	27.77	0.004010424058835227
280	27.81	0.0045002972386516404
284	27.85	0.005290190113731441
288	27.89	0.00549438873992969
292	27.93	0.005610036315586875
296	27.97	0.005859990324518893
300	28.01	0.005749965393150092
304	28.05	0.005682819004807271
308	28.09	0.0055299800712607095
312	28.13	0.005753353694572194
316	28.17	0.005635083071852787
320	28.21	0.005666835209572785
324	28.25	0.005956943780673463
328	28.29	0.005830409124557345
332	28.33	0.005770564913784693
336	28.37	0.005827411487448586
340	28.41	0.00587094918450104
344	28.45	0.0058511783437333875
348	28.49	0.006098099303756932
352	28.53	0.005971712402914164
356	28.57	0.006178684645891774
360	28.61	0.006377349703762469
364	28.65	0.006526041247415737
368	28.69	0.006616426280811272
372	28.73	0.006259219426675067
376	28.77	0.005963944831305579
380	28.81	0.005954412355121175
384	28.85	0.005844908048842523
388	28.89	0.00606876558207059
392	28.93	0.006585985290881169
396	28.97	0.007216567511161287
400	29.01	0.007727179245182736
404	29.05	0.00795782082816654
408	29.09	0.00805515926168665
412	29.13	0.008229194880231994
416	29.17	0.00833659468468495
420	29.21	0.008235692342405176
424	29.25	0.008318154853724113
428	29.29	0.008667315885267257
432	29.33	0.008649842436617039
436	29.37	0.009024068173697053
440	29.41	0.008814993428869045
444	29.45	0.009225951867571247
448	29.49	0.009196943821525583
452	29.53	0.009604636288730983
456	29.57	0.0098123629335789
460	29.61	0.009503457420200423
464	29.65	0.009781253412359359
468	29.69	0.00992741790678986
472	29.73	0.00944361789987802
476	29.77	0.009284853721085451
480	29.81	0.00927612569963765
484	29.85	0.009300767497764983
488	29.89	0.009458779444083909
492	29.93	0.009440161866860475
496	29.97	0.009641581760734486
500	30.01	0.00955803945333722
504	30.05	0.00984596384340497
508	30.09	0.010426069543631122
512	30.13	0.010697642595045576
516	30.17	0.010199254752746079
520	30.21	0.009640906343016287
524	30.25	0.009192597691968007
528	30.29	0.008699329125525512
532	30.33	0.008416100969413698
536	30.37	0.00854124688234048
540	30.41	0.008699767189352503
544	30.45	0.009216662215181692
548	30.49	0.009908598950820746
552	30.53	0.010225577720234025
556	30.57	0.010647598847193684
560	30.61	0.011126329321921258
564	30.65	0.011251769467665262
568	30.69	0.01124391960729998
572	30.73	0.011011113396641292
576	30.77	0.011128351157859928
580	30.81	0.011220633212864595
584	30.85	0.011192959883299824
588	30.89	0.011205331490465653
592	30.93	0.011097748355243464
596	30.97	0.010650210798114124
600	31.01	0.010782719139183161
604	31.05	0.01067527369819432
608	31.09	0.010534541461251656
612	31.13	0.010640522747551895
616	31.17	0.010653217876000376
620	31.21	0.010520960498449305
624	31.25	0.010338750933054364
628	31.29	0.010231589497605054
632	31.33	0.010224476509470115
636	31.37	0.01015074561900553
640	31.41	0.009960397142954935
644	31.45	0.009789145683434697
648	31.49	0.00979651536608106
652	31.53	0.009569649363874166
656	31.57	0.009757833706571795
660	31.61	0.010142735376080125
664	31.65	0.010409354687368477
668	31.69	0.010262691955149617
672	31.73	0.009856080827153502
676	31.77	0.009049521617346734
680	31.81	0.008776347972577092
684	31.85	0.008453226872663144
688	31.89	0.008405158630487186
692	31.93	0.008598810225330933
696	31.97	0.008877515302844419
700	32.01	0.009086274175113651
704	32.05	0.009305087154011904
708	32.09	0.009782287884450014
712	32.13	0.010367876677788601
716	32.17	0.010458282416500264
720	32.21	0.010855886363608125
724	32.25	0.011174974543633809
728	32.29	0.011335785361665351
732	32.33	0.011303319127167644
736	32.37	0.011390909482531963
740	32.41	0.011151890069871495
744	32.45	0.011129594530978615
748	32.49	0.011107356507249921
752	32.53	0.010968509639825541
756	32.57	0.010929720902955964
760	32.61	0.0111576572706098
764	32.65	0.010943985716578286
768	32.69	0.011063706547600027
772	32.73	0.010958486736684758
776	32.77	0.010928326589837667
780	32.81	0.010564893079270554
784	32.85	0.010476519843392929
788	32.89	0.010154873853532198
792	32.93	0.010343288747267199
796	32.97	0.010328431495198132
800	33.01	0.010073635734263231
804	33.05	0.009893901767682234
808	33.09	0.009724229898362857
812	33.13	0.009873906143175404
816	33.17	0.01046935937574478
820	33.21	0.01062558989791107
824	33.25	0.010496169439792258
828	33.29	0.009991812588418636
832	33.33	0.009312519644909756
836	33.37	0.009133290910121161
840	33.41	0.008804126684573976
844	33.45	0.009025027268403374
848	33.49	0.00922099296134693
852	33.53	0.00956702406288068
856	33.57	0.00991312087211682
860	33.61	0.010659283687778576
864	33.65	0.010962655665304855
868	33.69	0.011535141864460918
872	33.73	0.011798171154091541
876	33.77	0.01196126764074057
880	33.81	0.0122910982876836
884	33.85	0.012312663391155887
888	33.89	0.012184296580427745
892	33.93	0.012314331484454488
896	33.97	0.012344435065132053
900	34.01	0.012507940950603924
904	34.05	0.012471516101999036
908	34.09	0.012243494146762846
912	34.13	0.012165542045294409
916	34.17	0.012202660090935513
920	34.21	0.012339848576621737
924	34.25	0.012277107794827824
928	34.29	0.012221104704248198
932	34.33	0.0123018395965242
936	34.37	0.012124312762945788
940	34.41	0.01208019116119008
944	34.45	0.011684475081985113
948	34.49	0.011408831482372594
952	34.53	0.011379927319065786
956	34.57	0.011604429548506712
960	34.61	0.0118856717933995
964	34.65	0.011533654342665844
968	34.69	0.011565044151512271
972	34.73	0.011569841508132228
976	34.77	0.011778046700352984
980	34.81	0.011546326682326136
984	34.85	0.01127468174115398
988	34.89	0.010898112163558071
992	34.93	0.010538284902637862
996	34.97	0.010120200244421174
1000	35.01	0.010268858474549614
1004	35.05	0.010057593211619587
1008	35.09	0.010196404740549614
1012	35.13	0.010315293345865673
1016	35.17	0.010714259311724206
1020	35.21	0.011046636255317654
1024	35.25	0.011479091126832763
1028	35.29	0.011978290876007325
1032	35.33	0.012310902452208783
1036	35.37	0.012176926137732469
1040	35.41	0.012209695547813926
1044	35.45	0.012409210963999495
1048	35.49	0.012468806000842658
1052	35.53	0.012258480939277838
1056	35.57	0.012141569393241625
1060	35.61	0.012008071642878981
1064	35.65	0.011941321301328411
1068	35.69	0.011807985314772118
1072	35.73	0.011783063962269136
1076	35.77	0.011728224189170078
1080	35.81	0.01195846627382835
1084	35.85	0.012008790494285382
1088	35.89	0.012159197128220889
1092	35.93	0.012093019786290071
1096	35.97	0.012210258745535274
1100	36.01	0.011910914282700968
1104	36.05	0.011711653340844563
1108	36.09	0.011492476195966272
1112	36.13	0.011513383123665122
1116	36.17	0.011239374399212299
1120	36.21	0.011265450297588409
1124	36.25	0.011376611093456557
1128	36.29	0.011637857061117973
1132	36.33	0.01201918847458261
1136	36.37	0.011745605607593301
1140	36.41	0.011172108733622732
1144	36.45	0.010363698125882337
1148	36.49	0.009785374057392104
1152	36.53	0.009227136800912916
1156	36.57	0.008728986628974589
1160	36.61	0.008597590480528883
1164	36.65	0.008832948627668813
1168	36.69	0.00908506134224929
1172	36.73	0.009351547943464489
1176	36.77	0.00947955155970659
1180	36.81	0.009541929604708344
1184	36.85	0.010044396634701247
1188	36.89	0.01064695291985096
1192	36.93	0.010916265396669012
1196	36.97	0.011252334334671765
1200	37.01	0.011321826669724366
1204	37.05	0.011233076003843934
1208	37.09	0.010986082605217273
1212	37.13	0.011135608646346995
1216	37.17	0.011367368680400336
1220	37.21	0.011120648688920376
1224	37.25	0.011107353700813505
1228	37.29	0.011127483982754871
1232	37.33	0.011041039801005237
1236	37.37	0.010784688088059546
1240	37.41	0.01055509577607161
1244	37.45	0.010567263130271343
1248	37.49	0.01067619041551815
1252	37.53	0.010525211229674092
1256	37.57	0.010629325836960746
1260	37.61	0.010275201167905035
1264	37.65	0.010287837486084861
1268	37.69	0.010237235054772587
1272	37.73	0.009921727470291408
1276	37.77	0.009686314995399403
1280	37.81	0.009864331225968304
1284	37.85	0.00969577642417141
1288	37.89	0.009840650851799637
1292	37.93	0.010520621436965083
1296	37.97	0.01075068844083038
1300	38.01	0.010389185457587491
1304	38.05	0.010136112747821002
1308	38.09	0.00964147057175646
1312	38.13	0.009338592522623035
1316	38.17	0.009144145526649883
1320	38.21	0.00893312984304595
1324	38.25	0.0091888790641379
1328	38.29	0.009328060115316728
1332	38.33	0.009550673255000586
1336	38.37	0.009940052074649763
1340	38.41	0.009862863498786734
1344	38.45	0.010285774451631813
1348	38.49	0.010305451857129277
1352	38.53	0.010731895972265981
1356	38.57	0.010938440387096016
1360	38.61	0.010895085358013201
1364	38.65	0.010926831141027549
1368	38.69	0.010808677991864801
1372	38.73	0.010665626165887065
1376	38.77	0.010312675918016101
1380	38.81	0.009979827502851535
1384	38.85	0.009787081174660095
1388	38.89	0.009874437187380458
1392	38.93	0.009721895794692514
1396	38.97	0.009442790583403582
1400	39.01	0.009467121806700174
1404	39.05	0.009544889717522764
1408	39.09	0.00933276123512572
1412	39.13	0.009257403278386978
1416	39.17	0.008782149432539299
1420	39.21	0.008406999949114535
1424	39.25	0.008365288412704341
1428	39.29	0.008323681740911582
1432	39.33	0.008482180184358867
1436	39.37	0.00829078399336991
1440	39.41	0.008166160084588814
1444	39.45	0.007908308707699874
1448	39.49	0.007242230112038062
1452	39.53	0.007626257880012588
1456	39.57	0.0078103922604659815
1460	39.61	0.007511300168733914
1464	39.65	0.007303981853295838
1468	39.69	0.006813437562305236
1472	39.73	0.00657300087699797
1476	39.77	0.006062672045016093
1480	39.81	0.005892451313758151
1484	39.85	0.006202338930533902
1488	39.89	0.006362335142533038
1492	39.93	0.0068891068633587516
1496	39.97	0.007199321006408077
1500	40.01	0.007542977818120633
1504	40.05	0.007870077544612997
1508	40.09	0.00803062043166225
1512	40.13	0.008294606724813747
1516	40.17	0.008585370002681003
1520	40.21	0.008896243843490748
1524	40.25	0.0090072284918441
1528	40.29	0.008898324192172957
1532	40.33	0.008849531188645177
1536	40.37	0.009040849725082456
1540	40.41	0.009002280044898558
1544	40.45	0.00879715572454165
1548	40.49	0.008555477006908507
1552	40.53	0.008637244134674482
1556	40.57	0.00893245735025383
1560	40.61	0.009011116895686566
1564	40.65	0.009148223012611645
1568	40.69	0.009185442608861116
1572	40.73	0.00908110925854011
1576	40.77	0.009060223202078443
1580	40.81	0.00927278467952597
1584	40.85	0.009160460597312792
1588	40.89	0.009098251194951334
1592	40.93	0.008651156711708907
1596	40.97	0.008564177386642946
1600	41.01	0.008403980125215593
1604	41.05	0.008467231832620215
1608	41.09	0.008263932747077707
1612	41.13	0.008127416439881685
1616	41.17	0.00849101648202888
1620	41.21	0.009054733110828828
1624	41.25	0.009118566563186992
1628	41.29	0.008832517075649804
1632	41.33	0.009026584884392008
1636	41.37	0.008510770225217623
1640	41.41	0.00830840666690369
1644	41.45	0.008389494444519752
1648	41.49	0.008237367126167072
1652	41.53	0.008518691613045082
1656	41.57	0.00897346813940425
1660	41.61	0.009098363605911874
1664	41.65	0.009396711579661599
1668	41.69	0.009978512294139819
1672	41.73	0.010243765982579145
1676	41.77	0.010409139544634183
1680	41.81	0.010757966546323328
1684	41.85	0.01090691388670173
1688	41.89	0.010930981797854677
1692	41.93	0.010951837178291068
1696	41.97	0.010937813592933221
1700	42.01	0.010828911273043751
1704	42.05	0.010891559020990371
1708	42.09	0.011036471353016886
1712	42.13	0.010990434213633105
1716	42.17	0.010669519261264249
1720	42.21	0.010536226725436748
1724	42.25	0.010663056835376938
1728	42.29	0.010645009819953977
1732	42.33	0.010637085907609922
1736	42.37	0.01053428532639078
1740	42.41	0.010321608304083352
1744	42.45	0.01046905506810214
1748	42.49	0.010231625845588344
1752	42.53	0.009984320863377416
1756	42.57	0.010142140347995099
1760	42.61	0.009960084525700186
1764	42.65	0.009838153622475865
1768	42.69	0.009746347864008964
1772	42.73	0.00963133414236017
1776	42.77	0.009583112682557626
1780	42.81	0.009351683709295955
1784	42.85	0.009587047446895536
1788	42.89	0.009929204119373924
1792	42.93	0.009774820617212132
1796	42.97	0.009627230497286643
1800	43.01	0.009079767316162002
1804	43.05	0.008582431296874748
1808	43.09	0.00847093694797696
1812	43.13	0.008184808301579416
1816	43.17	0.00814952177048811
1820	43.21	0.008324363291075887
1824	43.25	0.008764333085159226
1828	43.29	0.009134431374203889
1832	43.33	0.009254658379315384
1836	43.37	0.009525014321307701
1840	43.41	0.009812166087412866
1844	43.45	0.01003754246931221
1848	43.49	0.010046857972709766
1852	43.53	0.010257731864860453
1856	43.57	0.010428735793640787
1860	43.61	0.010199869978073206
1864	43.65	0.010351134636841675
1868	43.69	0.010442529988277549
1872	43.73	0.01047405625031228
1876	43.77	0.010802380307099568
1880	43.81	0.010824169042372933
1884	43.85	0.010912756006137947
1888	43.89	0.011168141414685362
1892	43.93	0.010790325484001606
1896	43.97	0.010779308429798906
1900	44.01	0.010818423800817989
1904	44.05	0.01092433847876384
1908	44.09	0.011035941567239416
1912	44.13	0.011353233280600339
1916	44.17	0.01132621383274346
1920	44.21	0.011322661214895557
1924	44.25	0.01145590897358506
1928	44.29	0.011729290655011493
1932	44.33	0.011902806471684624
1936	44.37	0.011976456635786281
1940	44.41	0.011740241359029735
1944	44.45	0.011684160852687864
1948	44.49	0.011348215327613431
1952	44.53	0.011472404994322005
1956	44.57	0.011596730062928717
1960	44.61	0.011587857409837365
1964	44.65	0.011485787244402523
1968	44.69	0.011070519775714605
1972	44.73	0.010466817117426697
1976	44.77	0.009670393763795637
1980	44.81	0.00937886897057405
1984	44.85	0.009330814374128416
1988	44.89	0.009296230181977894
1992	44.93	0.009921783268163065
1996	44.97	0.010097473839782989
2000	45.01	0.010606635436840595
2004	45.05	0.010882601598999564
2008	45.09	0.01141108681805525
2012	45.13	0.011876615109388311
2016	45.17	0.012177996202360486
2020	45.21	0.012254516016444672
2024	45.25	0.012531174756370334
2028	45.29	0.01274130595975631
2032	45.33	0.012364909830526294
2036	45.37	0.012645319905605579
2040	45.41	0.012839203054908932
2044	45.45	0.013046559481315168
2048	45.49	0.013069056053957695
2052	45.53	0.01292169297496093
2056	45.57	0.012999470446104056
2060	45.61	0.012577388668707723
2064	45.65	0.012191162129278954
2068	45.69	0.012233648170961064
2072	45.73	0.012461989850649946
2076	45.77	0.01245047308187619
2080	45.81	0.012519098063490386
2084	45.85	0.01268119832716419
2088	45.89	0.012405345499361786
2092	45.93	0.012355825491793926
2096	45.97	0.012385019453863055
2100	46.01	0.012597689486995467
2104	46.05	0.012543835787508506
2108	46.09	0.012590125217941228
2112	46.13	0.012996081783337665
2116	46.17	0.013033134250328704
2120	46.21	0.012779854242342736
2124	46.25	0.0125933848109816
2128	46.29	0.01312372615025037
2132	46.33	0.013284211787103928
2136	46.37	0.013234841914796291
2140	46.41	0.012698950059532255
2144	46.45	0.012436536413759303
2148	46.49	0.01217760116950295
2152	46.53	0.012242144518427533
2156	46.57	0.012256833318486038
2160	46.61	0.012055001093904671
2164	46.65	0.011853314701909756
2168	46.69	0.012060107666048925
2172	46.73	0.012233713509463673
2176	46.77	0.012629132421646538
2180	46.81	0.013331364591842476
2184	46.85	0.01391374354231445
2188	46.89	0.014246269461589911
2192	46.93	0.014595609204450355
2196	46.97	0.01461176295855271
2200	47.01	0.015044730911081938
2204	47.05	0.01497784658208845
2208	47.09	0.015286110157883837
2212	47.13	0.01508737896718948
2216	47.17	0.014778081766790407
2220	47.21	0.014911790170204497
2224	47.25	0.014912313885722561
2228	47.29	0.014829653097373274
2232	47.33	0.014513807988763894
2236	47.37	0.014148112076396213
2240	47.41	0.014007565542967892
2244	47.45	0.014217168570779037
2248	47.49	0.013976921341755322
2252	47.53	0.014486824037442059
2256	47.57	0.014596876838961492
2260	47.61	0.014732079926925046
2264	47.65	0.015017433481322673
2268	47.69	0.014877937681572195
2272	47.73	0.014696926040004943
2276	47.77	0.014499398735274838
2280	47.81	0.014668689279012881
2284	47.85	0.015091464515709863
2288	47.89	0.015307724622782182
2292	47.93	0.015210803110564441
2296	47.97	0.015105700155540358
2300	48.01	0.015717415933727885
2304	48.05	0.016197141096839562
2308	48.09	0.01605130439134861
2312	48.13	0.015528477420391429
2316	48.17	0.01506580321517248
2320	48.21	0.014603281949284508
2324	48.25	0.014065913795828333
2328	48.29	0.013745365594075576
2332	48.33	0.013791637516074928
2336	48.37	0.013821396400062635
2340	48.41	0.01399297575052616
2344	48.45	0.014331375738138252
2348	48.49	0.014569929866569797
2352	48.53	0.014508638305710697
2356	48.57	0.014787501224966082
2360	48.61	0.01505318545991896
2364	48.65	0.015125691179066258
2368	48.69	0.0152316852171559
2372	48.73	0.015475929646643571
2376	48.77	0.015724138920467645
2380	48.81	0.01538393225299739
2384	48.85	0.015223881239148973
2388	48.89	0.015297319378037244
2392	48.93	0.015470913501569594
2396	48.97	0.015894663774460582
2400	49.01	0.016018570361043594
2404	49.05	0.016225966758516286
2408	49.09	0.01640685313029744
2412	49.13	0.01628289630594182
2416	49.17	0.01627409644793154
2420	49.21	0.016007120384953222
2424	49.25	0.015956968278511674
2428	49.29	0.01597364028969528
2432	49.33	0.015655469912484676
2436	49.37	0.01569079064031298
2440	49.41	0.015249602632799064
2444	49.45	0.015091906049202297
2448	49.49	0.015009367714972743
2452	49.53	0.015086987788419215
2456	49.57	0.01520309976080636
2460	49.61	0.015037703789607004
2464	49.65	0.01502246669847862
2468	49.69	0.015199055310575638
2472	49.73	0.015042469781839873
2476	49.77	0.015486043601165456
2480	49.81	0.016209776923748365
2484	49.85	0.016373669904464094
2488	49.89	0.0162510560311655
2492	49.93	0.0162619354579836
2496	49.97	0.015939641671920857
2500	50.01	0.015717508159494464
2504	50.05	0.015495535073462019
2508	50.09	0.015507055899451672
2512	50.13	0.015518737455945786
2516	50.17	0.015880579894299807
2520	50.21	0.01655925003207992
2524	50.25	0.017021414686445357
2528	50.29	0.017533740674123166
2532	50.33	0.017852894811277942
2536	50.37	0.017858877246864857
2540	50.41	0.017925021462647184
2544	50.45	0.018226327606573722
2548	50.49	0.018197795826102592
2552	50.53	0.018519426268129635
2556	50.57	0.018491219079001198
2560	50.61	0.018563174404500504
2564	50.65	0.018735292389956637
2568	50.69	0.018832573180122658
2572	50.73	0.018780016919175413
2576	50.77	0.0187076237507533
2580	50.81	0.01890039381795372
2584	50.85	0.019123327263282697
2588	50.89	0.01949642422868303
2592	50.93	0.01971968485557163
2596	50.97	0.01976810928481232
2600	51.01	0.01931669765667765
2604	51.05	0.019045450110801276
2608	51.09	0.01918103345290989
2612	51.13	0.019196781154743547
2616	51.17	0.019246026687390394
2620	51.21	0.019762103521220542
2624	51.25	0.02041167845933778
2628	51.29	0.02096141830431053
2632	51.33	0.021377989858100577
2636	51.37	0.021711393255293032
2640	51.41	0.021911628629851077
2644	51.45	0.021819172305501233
2648	51.49	0.02146259584333654
2652	51.53	0.02131332794672991
2656	51.57	0.02139755922312858
2660	51.61	0.021525289803026926
2664	51.65	0.021533186482930233
2668	51.69	0.021392916058713407
2672	51.73	0.02116947865890806
2676	51.77	0.021071207744733478
2680	51.81	0.020856436776853116
2684	51.85	0.02079516588199004
2688	51.89	0.021160728519546534
2692	51.93	0.02166550576731785
2696	51.97	0.021992354892844013
2700	52.01	0.022118418877285606
2704	52.05	0.022287983558256563
2708	52.09	0.02267104905837325
2712	52.13	0.023184282166306858
2716	52.17	0.02313101633696002
2720	52.21	0.023651251691375386
2724	52.25	0.023671655016600734
2728	52.29	0.02382555976570222
2732	52.33	0.023952966057694258
2736	52.37	0.02420054067752586
2740	52.41	0.02405495040950445
2744	52.45	0.024036195370510605
2748	52.49	0.024030942343415074
2752	52.53	0.024235858110548403
2756	52.57	0.024340942787013375
2760	52.61	0.024356196487285153
2764	52.65	0.024291619325171876
2768	52.69	0.02370721141363541
2772	52.73	0.02352011572196888
2776	52.77	0.023352237123598574
2780	52.81	0.023325004300916774
2784	52.85	0.023097941173822356
2788	52.89	0.023162714518643046
2792	52.93	0.023124324444420363
2796	52.97	0.023101104392898808
2800	53.01	0.023324721138446858
2804	53.05	0.023275174787998232
2808	53.09	0.022972465447679724
2812	53.13	0.022829926556284352
2816	53.17	0.022837558218686382
2820	53.21	0.023185360539044186
2824	53.25	0.023378333620841296
2828	53.29	0.023461477566904865
2832	53.33	0.023491221050806033
2836	53.37	0.023778278459629654
2840	53.41	0.02433693560838046
2844	53.45	0.024475764025729596
2848	53.49	0.024404763811157526
2852	53.53	0.023880601730132067
2856	53.57	0.023423277880698645
2860	53.61	0.02293279236018142
2864	53.65	0.022852478598571757
2868	53.69	0.02268567002523758
2872	53.73	0.022862366735650674
2876	53.77	0.02353923549130421
2880	53.81	0.024082943053095995
2884	53.85	0.024793489514618017
2888	53.89	0.02515420830201931
2892	53.93	0.025115099507321492
2896	53.97	0.02562616322175648
2900	54.01	0.026177399535761925
2904	54.05	0.026698808539060703
2908	54.09	0.026877056987302694
2912	54.13	0.027442144968700344
2916	54.17	0.02755073923732798
2920	54.21	0.027512839879689555
2924	54.25	0.02752511364804766
2928	54.29	0.02762089396038947
2932	54.33	0.02783351423386282
2936	54.37	0.02809630788480133
2940	54.41	0.027992608328824886
2944	54.45	0.028097415647428292
2948	54.49	0.0281690632546594
2952	54.53	0.028449217897190238
2956	54.57	0.028412879654249767
2960	54.61	0.02854338193751449
2964	54.65	0.028590724824621994
2968	54.69	0.02880490839250216
2972	54.73	0.028844266050714662
2976	54.77	0.028593797874757687
2980	54.81	0.02879850393926997
2984	54.85	0.028830050984726352
2988	54.89	0.02867843908410439
2992	54.93	0.029210334976287555
2996	54.97	0.029625738732772522
3000	55.01	0.029424650424263454
3004	55.05	0.029465403453929007
3008	55.09	0.029476331224051133
3012	55.13	0.029555767136126843
3016	55.17	0.029613711257724606
3020	55.21	0.029821830322336318
3024	55.25	0.029671791062577668
3028	55.29	0.02973859354349262
3032	55.33	0.02958890449590834
3036	55.37	0.02965605731635801
3040	55.41	0.030040052067084932
3044	55.45	0.030332555476152212
3048	55.49	0.03079190093754791
3052	55.53	0.031226421844483543
3056	55.57	0.03131111825599353
3060	55.61	0.03122932356362007
3064	55.65	0.031272704491358105
3068	55.69	0.031541261095659134
3072	55.73	0.0313921362892704
3076	55.77	0.031353901555477126
3080	55.81	0.031506318852772
3084	55.85	0.031742245376746414
3088	55.89	0.03191168117925569
3092	55.93	0.032347959644441815
3096	55.97	0.03209108082209866
3100	56.02	0.03250437809442941
3104	56.06	0.03259118484270651
3108	56.1	0.03231150111404135
3112	56.14	0.03253199362130932
3116	56.18	0.032552662409785604
3120	56.22	0.032740174190518
3124	56.26	0.03296952900703731
3128	56.3	0.032882393568681056
3132	56.34	0.032787101250484785
3136	56.38	0.033208652093239976
3140	56.42	0.0332303794700648
3144	56.46	0.03320228341976872
3148	56.5	0.033324363980262284
3152	56.54	0.033579954521864686
3156	56.58	0.03379905508061043
3160	56.62	0.03399166569164347
3164	56.66	0.03456445305593858
3168	56.7	0.03469741720689745
3172	56.74	0.03461055817700265
3176	56.78	0.03455887599781038
3180	56.82	0.0346073706999066
3184	56.86	0.034591042312834386
3188	56.9	0.034862033722325325
3192	56.94	0.035053916384631734
3196	56.98	0.03493645223125963
3200	57.02	0.03502749843079567
3204	57.06	0.035052055008042426
3208	57.1	0.03542678865355109
3212	57.14	0.035551699390257596
3216	57.18	0.0358934539068585
3220	57.22	0.03640205222448767
3224	57.26	0.03667749436339207
3228	57.3	0.036786447009475864
3232	57.34	0.03702891018097576
3236	57.38	0.03726488389508331
3240	57.42	0.03738103483478383
3244	57.46	0.037707363015433426
3248	57.5	0.03821720178474619
3252	57.54	0.038643884489354186
3256	57.58	0.03902741114141062
3260	57.62	0.039564448418635934
3264	57.66	0.03967499633067373
3268	57.7	0.039859054885793554
3272	57.74	0.04026805266236533
3276	57.78	0.040141037285156944
3280	57.82	0.04055229447309161
3284	57.86	0.040730395658262974
3288	57.9	0.04102534084329568
3292	57.94	0.04108713002989628
3296	57.98	0.041165763218441676
3300	58.02	0.041411240407903005
3304	58.06	0.04177356159597334
3308	58.1	0.04170272677900133
3312	58.14	0.0423487359518977
3316	58.18	0.0428044462512851
3320	58.22	0.04332128624137166
3324	58.26	0.04357116067575717
3328	58.3	0.0440262124022297
3332	58.34	0.043981441410405164
3336	58.38	0.044261847688579437
3340	58.42	0.04467576455681943
3344	58.46	0.04512319200052106
3348	58.5	0.04563746333717322
3352	58.54	0.0458185785496279
3356	58.58	0.046266537619429116
3360	58.62	0.04668800719355293
3364	58.66	0.04717965391773227
3368	58.7	0.0474781444365342
3372	58.74	0.047793478726569916
3376	58.78	0.04844232342972177
3380	58.82	0.049108011853201905
3384	58.86	0.049240543969450545
3388	58.9	0.04938325308290947
3392	58.94	0.04963947249659251
3396	58.98	0.04988920217872561
3400	59.02	0.05059244209625646
3404	59.06	0.0507058588814453
3408	59.1	0.05063945249848256
3412	59.14	0.050823222910174604
3416	59.18	0.050807170077926234
3420	59.22	0.05132462729510845
3424	59.26	0.05203559452046358
3428	59.3	0.05256007171132637
3432	59.34	0.053004725490256366
3436	59.38	0.052996222478479904
3440	59.42	0.05358956262921266
3444	59.46	0.05392474589431684
3448	59.5	0.05393510555745795
3452	59.54	0.05452064156740821
3456	59.58	0.05505635387144947
3460	59.62	0.05537557574878216
3464	59.66	0.055828307143875655
3468	59.7	0.056339547999940454
3472	59.74	0.05655096492541478
3476	59.78	0.05701255786051718
3480	59.82	0.05749932674391722
3484	59.86	0.057941271512745196
3488	59.9	0.058428392102597204
3492	59.94	0.058935688447542045
3496	59.98	0.059023160480081494
3500	60.02	0.0595108081311615
3504	60.06	0.059965297996732225
3508	60.1	0.060146630004464186
3512	60.14	0.06055480408039049
3516	60.18	0.061263153482221
3520	60.22	0.06160167813273354
3524	60.26	0.062390377952941556
3528	60.3	0.06316258619537951
3532	60.34	0.06373496944417845
3536	60.38	0.06406752761505574
3540	60.42	0.06389692728862695
3544	60.46	0.06424650171043744
3548	60.5	0.06490125079088793
3552	60.54	0.065366174438509
3556	60.58	0.06565627256002449
3560	60.62	0.06611321172705509
3564	60.66	0.06693699184285196
3568	60.7	0.06734189852325079
3572	60.74	0.06781840785858728
3576	60.78	0.06838437688979271
3580	60.82	0.0691005197989516
3584	60.86	0.0697251698140553
3588	60.9	0.07028332682797256
3592	60.94	0.0706583240650418
3596	60.98	0.07112682808106374
3600	61.02	0.07158383876326901
3604	61.06	0.07215102266359885
3608	61.1	0.07254337966536584
3612	61.14	0.07303590964986917
3616	61.18	0.07334861249649238
3620	61.22	0.07375482141602818
3624	61.26	0.07433953628402756
3628	61.3	0.07508775697419257
3632	61.34	0.07560115002491896
3636	61.38	0.07633757244865391
3640	61.42	0.0768634526843388
3644	61.46	0.07760736202602736
3648	61.5	0.07855644319412347
3652	61.54	0.07907069604963413
3656	61.58	0.07938178711812727
3660	61.62	0.07970971625639045
3664	61.66	0.08010448331906295
3668	61.7	0.08078942149202772
3672	61.74	0.0816945306257355
3676	61.78	0.08211481056841707
3680	61.82	0.0827019278328236
3684	61.86	0.08298088226286149
3688	61.9	0.0838516737002788
3692	61.94	0.08452263531808812
3696	61.98	0.08500210028717303
3700	62.02	0.085890068442811
3704	62.06	0.08631153961797056
3708	62.1	0.08690818031014258
3712	62.14	0.08743832368117
3716	62.18	0.08742196955728287
3720	62.22	0.08779911776249971
3724	62.26	0.08874643478521271
3728	62.3	0.0892939204448453
3732	62.34	0.08961657455835592
3736	62.38	0.0899179683687703
3740	62.42	0.090312387402387
3744	62.46	0.09098554575459339
3748	62.5	0.09172387180421859
3752	62.54	0.0923073653564015
3756	62.58	0.09288102621402361
3760	62.62	0.09315485417751779
3764	62.66	0.09364551571155078
3768	62.7	0.09417801061178954
3772	62.74	0.09487733867150716
3776	62.78	0.09541016634817634
3780	62.82	0.09560982676360474
3784	62.86	0.09575631970376985
3788	62.9	0.09640131161884824
3792	62.94	0.09707646895661126
3796	62.98	0.09701964863858326
3800	63.02	0.09761061234571722
3804	63.06	0.09832793128027495
3808	63.1	0.09847874807065216
3812	63.14	0.09903972915225578
3816	63.18	0.09945587429132896
3820	63.22	0.0996488499181214
3824	63.26	0.10018365579349675
3828	63.3	0.10028529167564626
3832	63.34	0.10053709065327787
3836	63.38	0.10090905247896886
3840	63.42	0.10139117690249355
3844	63.46	0.10179346367094722
3848	63.5	0.1017959125287593
3852	63.54	0.10204852321769797
3856	63.58	0.10203462881017344
3860	63.62	0.10205422904255146
3864	63.66	0.10200732364856258
3868	63.7	0.1019772456925443
3872	63.74	0.1021739949027185
3876	63.78	0.10211757100451235
3880	63.82	0.10225464038728038
3884	63.86	0.10232520277108614
3888	63.9	0.10217925787322457
3892	63.94	0.10223347207499245
3896	63.98	0.10233784508839383
3900	64.02	0.1022423766228382
3904	64.06	0.10207206638514288
3908	64.1	0.10175191407947093
3912	64.14	0.10130691940721803
3916	64.18	0.10123708206712223
3920	64.22	0.10113406842193884
3924	64.26	0.10087287816505697
3928	64.3	0.10074517765382529
3932	64.34	0.10058429990941553
3936	64.38	0.10014024461678694
3940	64.42	0.0998213447915739
3944	64.46	0.09938260011347122
3948	64.5	0.09863401025954399
3952	64.54	0.09816557490407174
3956	64.58	0.09753896038529364
3960	64.62	0.09712916637215452
3964	64.66	0.09683619253094689
3968	64.7	0.09640337185881132
3972	64.74	0.09580070401703811
3976	64.78	0.09485818866445017
3980	64.82	0.09456582545742931
3984	64.86	0.0945486140498395
3988	64.9	0.09364155409291408
3992	64.94	0.09228964523531769
3996	64.98	0.0909228871233303
4000	65.02	0.0896562794008049
4004	65.06	0.08864815504251577
4008	65.1	0.08757351368761945
4012	65.14	0.0868523549729856
4016	65.18	0.08626634519988485
4020	65.22	0.08517048400067662
4024	65.26	0.08450977100543833
4028	65.3	0.08364920584195268
4032	65.34	0.08304545480236314
4036	65.38	0.08256851750979699
4040	65.42	0.08157839358514973
4044	65.46	0.08064174931379009
4048	65.5	0.07948525097895631
4052	65.54	0.07839556486178223
4056	65.58	0.0772993572413192
4060	65.62	0.07618996106120157
4064	65.66	0.07502737592957276
4068	65.7	0.073896601452343
4072	65.74	0.07278263723328982
4076	65.78	0.07162714954088534
4080	65.82	0.07048013797504371
4084	65.86	0.06936660213379087
4088	65.9	0.06817820827998666
4092	65.94	0.06638995600794706
4096	65.98	0.06485184491008544
4100	66.02	0.06373054124374544
4104	66.06	0.06221604459804286
4108	66.1	0.06063835456050537
4112	66.14	0.05908080405021865
4116	66.18	0.05743339265121916
4120	66.22	0.05659278661274714
4124	66.26	0.055438985515844585
4128	66.3	0.05425198893992178
4132	66.34	0.052848463129499645
4136	66.38	0.05130697908954307
4140	66.42	0.05009182210933982
4144	66.46	0.048772039381583365
4148	66.5	0.047059059049991525
4152	66.54	0.046232880685526556
4156	66.58	0.04462183719123214
4160	66.62	0.04353592813551588
4164	66.66	0.04267515308550429
4168	66.7	0.04134951160702993
4172	66.74	0.040237336598022644
4176	66.78	0.03941862762206627
4180	66.82	0.03847338424168578
4184	66.86	0.03738160601833851
4188	66.9	0.03612329251240354
4192	66.94	0.03532844328324858
4196	66.98	0.033543724555914256
4200	67.02	0.03227580255458218
4204	67.06	0.03137467683587625
4208	67.1	0.030120346955554655
4212	67.14	0.028989479135226315
4216	67.18	0.027672072928893066
4220	67.22	0.026728127889612985
4224	67.26	0.025904310236236405
4228	67.3	0.024360619520223725
4232	67.34	0.02318705529245557
4236	67.38	0.02235361710310446
4240	67.42	0.020970304501662262
4244	67.46	0.020137117037089425
4248	67.5	0.019529054257724887
4252	67.54	0.018246115711320954
4256	67.58	0.01753830094514086
4260	67.62	0.016855609505997293
4264	67.66	0.015948040940288788
4268	67.7	0.015212817016166724
4272	67.74	0.014758270612559965
4276	67.78	0.013926067941380627
4280	67.82	0.01324398632533308
4284	67.86	0.012162025309024216
4288	67.9	0.011680184436668295
4292	67.94	0.011498463252037627
4296	67.98	0.010991861298441208
4300	68.02	0.01070204478543868
4304	68.06	0.010654013255705141
4308	68.1	0.010006099584998651
4312	68.14	0.009458303315356353
4316	68.18	0.009043957321825058
4320	68.22	0.008579727812485949
4324	68.26	0.008382280995069546
4328	68.3	0.008334949743726838
4332	68.34	0.007887733599113655
4336	68.38	0.0077697987683786884
4340	68.42	0.007826978125029527
4344	68.46	0.007771771208844314
4348	68.5	0.007616677559251439
4352	68.54	0.007561696715364885
4356	68.58	0.006892542501688137
4360	68.62	0.006667071599534502
4364	68.66	0.006314093070812543
4368	68.7	0.0061012255009815775
4372	68.74	0.005688468427724747
4376	68.78	0.005489154721849854
4380	68.82	0.005249950587292496
4384	68.86	0.005225855561136861
4388	68.9	0.005138535846816339
4392	68.94	0.0049263243140789115
4396	68.98	0.004930887165795372
4400	69.02	0.004310557271282267
4404	69.06	0.004257000832957214
4408	69.1	0.0041785507197102945
4412	69.14	0.0040402064668390025
4416	69.18	0.00392196760946284
4420	69.22	0.003693833682582248
4424	69.26	0.004015804220929731
4428	69.3	0.004027878758758874
4432	69.34	0.004035056829956307
4436	69.38	0.0038573379682325104
4440	69.42	0.003854721707150066
4444	69.46	0.003505779008650567
4448	69.5	0.003279795120193718
4452	69.54	0.003322483860399572
4456	69.58	0.003120273333516277
4460	69.62	0.0034681630721524748
4464	69.66	0.0032911526086918386
4468	69.7	0.0032142414753755233
4472	69.74	0.0034974292043519206
4476	69.78	0.0030357153277127402
4480	69.82	0.0030507660441347895
4484	69.86	0.003157580885452038
4488	69.9	0.003464492716797718
4492	69.94	0.0034548344032447886
4496	69.98	0.0034036054764663426
4500	70.02	0.003182472134731995
4504	70.06	0.0034064339094719287
4508	70.1	0.003950490331849021
4512	70.14	0.004324640932751755
4516	70.18	0.004598885242988349
4520	70.22	0.00492322279319124
4524	70.26	0.005047653113746886
4528	70.3	0.005472175734855256
4532	70.34	0.005546790186449435
4536	70.38	0.005421495998076953
4540	70.42	0.005506292698984616
4544	70.46	0.005221179818248878
4548	70.5	0.005267585456331325
4552	70.54	0.005271223427768312
4556	70.58	0.004396378975405124
4560	70.62	0.0037916230561454434
4564	70.66	0.0032719551982127726
4568	70.7	0.0033223749298287863
4572	70.74	0.0030678817791010005
4576	70.78	0.0028534752740556613
4580	70.82	0.0026324882759789503
4584	70.86	0.002858253646001341
4588	70.9	0.002550770911724509
4592	70.94	0.0025100396006050296
4596	70.98	0.0019427259066322478
4600	71.02	0.0017954960236732376
4604	71.06	0.0013800161455765902
4608	71.1	0.001156285799535972
4612	71.14	0.0009076378460464163
4616	71.18	0.0007840718121960855
4620	71.22	0.0005605872249336841
4624	71.26	0.0006205169443886938
4628	71.3	0.0005638604972380001
4632	71.34	0.0006072840767465948
4636	71.38	0.0007388824474774403
4640	71.42	0.0004693694214257249
4644	71.46	0.000654696905756591
4648	71.5	0.000428435855206466
4652	71.54	0.00043558579575009304
4656	71.58	0.0007694795865362813
4660	71.62	0.0007301167532971498
4664	71.66	0.0008408301551492414
4668	71.7	0.0008049526511260119
4672	71.74	0.0007124837667662476
4676	71.78	0.000790089694167051
4680	71.82	0.0008511032919851225
4684	71.86	0.0008955240853949498
4688	71.9	0.0011233515994359955
4692	71.94	0.0010512520256669156
4696	71.98	0.0009292248887757815
4700	72.02	0.0010072697132472719
4704	72.06	0.0011103860234218388
4708	72.1	0.001230240010144712
4712	72.14	0.0014084978641850654
4716	72.18	0.0012451591095103964
4720	72.22	0.0014735566032992864
4724	72.26	0.0016770232026104281
4728	72.3	0.0016805584311119226
4732	72.34	0.001891304669480398
4736	72.38	0.002129499536330126
4740	72.42	0.0021582377930098318
4744	72.46	0.0025453761054490265
4748	72.5	0.0030092473299019318
4752	72.54	0.002978184322530719
4756	72.58	0.0028321866060867507
4760	72.62	0.0029695870365289423
4764	72.66	0.0026987184696096733
4768	72.7	0.0022145804274171788
4772	72.74	0.002273839098566377
4776	72.78	0.0022031606716685914
4780	72.82	0.0018825446685970526
4784	72.86	0.0019369906111101898
4788	72.9	0.0022914980208490476
4792	72.94	0.002321066419372908
4796	72.98	0.0020006953280997664
4800	73.02	0.0016703842682570524
4804	73.06	0.0017267994276677356
4808	73.1	0.0016149403273706397
4812	73.14	0.0010598064883984293
4816	73.18	0.00044973076497667464
4820	73.22	0.00044637934439339944
4824	73.26	0.0003097517470056488
4828	73.3	0.00019984749298762594
4832	73.34	0.00011999943564156013
4836	73.38	8.020709469436227e-05
4840	73.42	0.00021380332306675243
4844	73.46	0.0003607876402549337
4848	73.5	0.0005911595657379642
4852	73.54	0.0008815852855299511
4856	73.58	0.0009720643189843337
4860	73.62	0.0011492628520590742
4864	73.66	0.000913180403992353
4868	73.7	0.0011188164938675804
4872	73.74	0.0015411706405865644
4876	73.78	0.0017885756962883193
4880	73.82	0.0017360311796665862
4884	73.86	0.001466869942658544
4888	73.9	0.001247758170463964
4892	73.94	0.001253695381503217
4896	73.98	0.0014846810941739896
4900	74.02	0.0012657148268480078
4904	74.06	0.001521796097889272
4908	74.1	0.0010529244254158243
4912	74.14	0.0012090993271933748
4916	74.18	0.000740320320821386
4920	74.22	0.0007965869237152035
4924	74.26	0.0006028986531507741
4928	74.3	0.0001292550264313519
4932	74.34	-0.0004164872963587918
4936	74.38	-0.00034790022657071873
4940	74.42	-0.0007630794844981637
4944	74.46	-0.0014148826941520198
4948	74.5	-0.0013333103346107045
4952	74.54	-0.001601696215123738
4956	74.58	-0.001670040808186446
4960	74.62	-0.0019883445825423784
4964	74.66	-0.0021666080025291024
4968	74.7	-0.002724831527221916
4972	74.74	-0.0029930156098441074
4976	74.78	-0.00338616069691966
4980	74.82	-0.003404267227241853
4984	74.86	-0.0033723356309467434
4988	74.9	-0.003665366329455466
4992	74.94	-0.00382335973528658
4996	74.98	-0.004051316251438397
5000	75.02	-0.003794236270993512
5004	75.06	-0.003753786843700091
5008	75.1	-0.003888301676089778
5012	75.14	-0.0037827811315054305
5016	75.18	-0.003290558896492435
5020	75.22	-0.0029583019812009503
5024	75.26	-0.002826010720532679
5028	75.3	-0.0026047965529434336
5032	75.34	-0.0025279931321016136
5036	75.38	-0.0023489341050737522
5040	75.42	-0.0021965086681920987
5044	75.46	-0.001744050456316426
5048	75.5	-0.0017815597654542437
5052	75.54	-0.0014990368869187698
5056	75.58	-0.0011664821077608245
5060	75.62	-0.0012338957112580928
5064	75.66	-0.0018012779772282883
5068	75.7	-0.002108629181861943
5072	75.74	-0.0025859495967512913
5076	75.78	-0.002069906154695378
5080	75.82	-0.0016704991159022242
5084	75.86	-0.0015127287351197616
5088	75.9	-0.0012849285958265177
5092	75.94	-0.0013720989443619658
5096	75.98	-0.0012892400235551271
5100	76.02	-0.0012063520727871868
5104	76.06	-0.001098435328294567
5108	76.1	-0.0009404900233467295
5112	76.14	-0.0007675163882976399
5116	76.18	-0.0007745146509767764
5120	76.22	-0.00044148503712326814
5124	76.26	-0.00043342777064525606
5128	76.3	-0.0003753430740429664
5132	76.34	-0.0005088978351945883
5136	76.38	-0.0005090922741888271
5140	76.42	-0.00040092660983548356
5144	76.46	-0.00018273439293325922
5148	76.5	-0.00010951584001528403
5152	76.54	-0.00020960450033102873
5156	76.58	-0.0002030005891819897
5160	76.62	2.362901218155855e-05
5164	76.66	7.361742305445063e-05
5168	76.7	-5.7321284916866944e-05
5172	76.74	2.3669816953564293e-05
5176	76.78	0.0003637333717034785
5180	76.82	0.0008238215462239573
5184	76.86	0.00075726745974114
5188	76.9	0.0006907375648137482
5192	76.94	0.0004775649805388582
5196	76.98	0.0006339399688037872
5200	77.02	0.0005912908866765321
5204	77.06	0.0010581889482907947
5208	77.1	0.0013251101296742895
5212	77.14	0.0018587208829541346
5216	77.18	0.0022256876600961206
5220	77.22	0.0030926769128751808
5224	77.26	0.0031596884262632408
5228	77.3	0.002710055318409843
5232	77.34	0.0025937773739515
5236	77.38	0.002177521044113284
5240	77.42	0.0017112861134260804
5244	77.46	0.0014617390330591284
5248	77.5	0.001328879587412679
5252	77.54	0.001229374227529778
5256	77.58	0.001446556070913374
5260	77.62	0.0013304249015217984
5264	77.66	0.0009309805031318952
5268	77.7	0.000858222659449126
5272	77.74	0.0007654844873972166
5276	77.78	0.00019943243699804825
5280	77.82	3.339962478721148e-05
5284	77.86	8.405250052367919e-05
5288	77.9	-3.194248599447391e-05
5292	77.94	3.5414448409376575e-05
5296	77.98	0.00013612308700716724
5300	78.02	0.00033684987974424985
5304	78.06	0.000504261276485618
5308	78.1	0.0006383570602142008
5312	78.14	0.0009581846328097221
5316	78.18	0.001226600919772558
5320	78.22	0.0011407485606480527
5324	78.26	0.0008415797186391849
5328	78.3	0.0007805227473269838
5332	78.34	0.0009932917145332176
5336	78.38	0.0015917911641154525
5340	78.42	0.0023242351635373026
5344	78.46	0.002712647303908966
5348	78.5	0.0031969083191110137
5352	78.54	0.0032478513238034523
5356	78.58	0.0034154760990925404
5360	78.62	0.002716449092533324
5364	78.66	0.0021674367515465143
5368	78.7	0.00138510552342197
5372	78.74	0.0009527885219258181
5376	78.78	0.00032048552733598967
5380	78.82	-0.0001201370135066604
5384	78.86	-0.0005774126538180546
5388	78.9	-0.0004763416130475484
5392	78.94	-0.0005419241094681837
5396	78.98	-0.001057493693531697
5400	79.02	-0.0011980505806721276
5404	79.06	-0.0009219283169192849
5408	79.1	-0.0008641271120399807
5412	79.14	-0.0010696471734532587
5416	79.18	-0.0010351553730036933
5420	79.22	-0.0010606519131322045
5424	79.26	-0.0013911369935599716
5428	79.3	-0.001811610811142561
5432	79.34	-0.0017170735590270603
5436	79.38	-0.0015125254258085974
5440	79.42	-0.001447966595654826
5444	79.46	-0.0013733972489049506
5448	79.5	-0.0013838175622926663
5452	79.54	-0.0014242277090885658
5456	79.58	-0.0011229611922360938
5460	79.62	-0.0007883515111730688
5464	79.66	-0.000820398829235458
5468	79.7	-0.001069103307452579
5472	79.74	-0.001084465104361776
5476	79.78	-0.0013164843756832134
5480	79.82	-0.0015318279408127466
5484	79.86	-0.0018138292823057789
5488	79.9	-0.0019874885452995095
5492	79.94	-0.001744472537032138
5496	79.98	-0.0013931147265986432
5500	80.02	-0.0015334152452548544
5504	80.06	-0.0015737075537805012
5508	80.1	-0.0011189917758769319
5512	80.14	-0.0010876013649072647
5516	80.18	-0.0013495364378059982
5520	80.22	-0.0009847971085554796
5524	80.26	-0.0010000501545617269
5528	80.3	-0.001298629017031594
5532	80.34	-0.0014555338011654761
5536	80.38	-0.0012157646088897245
5540	80.42	-0.0012234882051691542
5544	80.46	-0.0011512046849175839
5548	80.5	-0.0008914141399420927
5552	80.54	-0.0008899499925814069
5556	80.58	-0.0005968123294630701
5560	80.62	-0.0005620012351919002
5564	80.66	-0.0006721834592950948
5568	80.7	-0.00046735908299044837
5572	80.74	-0.00034919485259266025
5576	80.78	-4.833703656448307e-06
5580	80.82	8.715285754679059e-05
5584	80.86	0.00012200284879337886
5588	80.9	0.00021685904977708503
5592	80.94	0.00044172138300968555
5596	80.98	0.00038658977081951207
5600	81.02	0.00046146413534620123
5604	81.06	0.0008963443985074981
5608	81.1	0.0014312304820087718
5612	81.14	0.001199455640700009
5616	81.18	0.0010010197959542388
5620	81.22	0.0010609228690645622
5624	81.26	0.0009958314479785457
5628	81.3	0.0011057454539056266
5632	81.34	0.0009073314747176653
5636	81.38	0.0008505894316774842
5640	81.42	0.0008105192460696742
5644	81.46	0.0007454541724558617
5648	81.5	0.0008303941320488839
5652	81.54	0.0008153390460727827
5656	81.58	0.0010902888357118279
5660	81.62	0.0011852434221153452
5664	81.66	0.0016202027263303442
5668	81.7	0.0017551666693478296
5672	81.74	0.001430135172174385
5676	81.78	0.001358441489152984
5680	81.82	0.0011100855413679334
5684	81.86	0.0009700672498684781
5688	81.9	0.00103005320236349
5692	81.94	0.0012983766531591279
5696	81.98	0.0010286089517403951
5700	82.02	0.001235035733296197
5704	82.06	0.001495037871110494
5708	82.1	0.001680043857356761
5712	82.14	0.0019400536126727985
5716	82.18	0.0017750670576344163
5720	82.22	0.0012500841126512618
5724	82.26	0.0010451046979227385
5728	82.3	0.0009301287335730102
5732	82.34	0.0007484894730227509
5736	82.38	0.0008335201695039984
5740	82.42	0.0006352207427315903
5744	82.46	0.0005869244457570311
5748	82.5	0.00082196453165162
5752	82.54	0.0008653409200287676
5756	82.58	0.0006587201971139933
5760	82.62	0.00016043561574097254
5764	82.66	-0.0001545129047078042
5768	82.7	-9.803020673038176e-05
5772	82.74	-0.00013440208500004047
5776	82.78	-0.00016600957192114407
5780	82.82	-3.094798527936149e-05
5784	82.86	0.00022078259558089286
5788	82.9	-0.0001941512418492941
5792	82.94	-0.00019241624331911567
5796	82.98	-5.258391612761315e-05
5800	83.02	-0.00018894005290315263
5804	83.06	-0.00025386568383378716
5808	83.1	-0.0007437894575530457
5812	83.14	-0.0011237114504365486
5816	83.18	-0.0006486317371612316
5820	83.22	-0.00046355039004053467
5824	83.26	-0.0004184674795393306
5828	83.3	-0.0007767164081950995
5832	83.34	-0.0007749639105467665
5836	83.38	-0.0009160671956012223
5840	83.42	-0.0010214548990070682
5844	83.46	-0.0009030318446683339
5848	83.5	-0.0002679409492465368
5852	83.54	-0.0001728489369177133
5856	83.58	-0.0003977558643852852
5860	83.62	-0.0003626617878071947
5864	83.66	-0.00042756676235677915
5868	83.7	-0.00023247084203159574
5872	83.74	-0.00021737407957855837
5876	83.78	6.294901899295269e-06
5880	83.82	-0.0002871782344544549
5884	83.86	-0.0004520792538782459
5888	83.9	-0.0006503129685806464
5892	83.94	-0.0008485460941982659
5896	83.98	-0.000646778678019988
5900	84.02	-0.000686677432110816
5904	84.06	-0.0008099090666089381
5908	84.1	-0.001074806956290697
5912	84.14	-0.0008230378071192312
5916	84.18	-0.0008712683226348439
5920	84.22	-0.0010361652042489844
5924	84.26	-0.0009677284845417411
5928	84.3	-0.0007159581936746484
5932	84.34	-0.000810854359545754
5936	84.38	-0.0007157503414672028
5940	84.42	-0.0008206461633055717
5944	84.46	-0.0006255418466745155
5948	84.5	-0.0004904374108765097
5952	84.54	-0.000721999540157281
5956	84.58	-0.0009402282507893212
5960	84.62	-0.0007451235573410209
5964	84.66	-0.0005500188055655997
5968	84.7	-0.00036491400594274026
5972	84.74	-0.00020480916739762378
5976	84.78	-0.00011613286931977385
5980	84.82	-0.0004429327383075332
5984	84.86	-0.000541161162357362
5988	84.9	-0.0005393895760761325
5992	84.94	-0.0005042846509253351
5996	84.98	-0.0009291797237143129
5997	84.99	-0.0008854034918397424