File: example/example_dsc/output_data/single/cleaned_data.txt
	Temperature (C)	Heat Flow (W/g)	baseline
0	25.01	-0.007621462935479606	-0.0028740073837320284
7	25.08	-0.006859839099049303	-0.002821210081741006
14	25.15	-0.006178215148799904	-0.0027684128488663605
21	25.22	-0.005616590821623912	-0.0027156158414947513
28	25.29	-0.005234965706524708	-0.0026628192973633
35	25.36	-0.004953339257013134	-0.0026100235248717476
42	25.43	-0.004871710799314588	-0.0025572288959351016
49	25.5	-0.004965079538764794	-0.002504435839891235
56	25.57	-0.004908444564460712	-0.0024516448399314154
63	25.64	-0.0036601381823060386	-0.0023988564352082813
70	25.71	-0.003045159253492802	-0.002346071217532311
77	25.78	-0.003043506549598174	-0.002293289810838923
84	25.85	-0.0038018454355803755	-0.0022405128565290066
91	25.92	-0.004233507866415298	-0.0021877410182655223
98	25.99	-0.0038934923722133696	-0.002134974997985571
105	26.06	-0.003103464050494331	-0.002082215544808682
112	26.13	-0.002230087906927025	-0.0020294634489038763
119	26.2	-0.001173362206899231	-0.001976719524180795
126	26.27	-0.0003166184968348418	-0.0019239845912272706
133	26.34	0.00011014504023343363	-0.0018712594708022137
140	26.41	-0.00027806976843214315	-0.0018185449832966805
147	26.48	-0.0004462610945221712	-0.001765841948661384
154	26.55	1.0572893296423302e-05	-0.001713151186446252
161	26.62	1.743403380816133e-05	-0.0016604735158526377
168	26.69	0.0003659908365905018	-0.0016078097557006756
175	26.76	0.0009612451454694693	-0.0015551607244080794
182	26.83	0.001263198803885146	-0.001502527239928168
189	26.9	0.0014594727027312793	-0.0014499101196342172
196	26.97	0.0014272115415576714	-0.001397310180237111
203	27.04	0.0010092743053702335	-0.001344728237749356
210	27.11	0.0018913771218147524	-0.0012921651075241869
217	27.18	0.0017735218325314328	-0.001239621604289514
224	27.25	0.0011271388494042966	-0.0011870985420417066
231	27.32	0.0008979442968777285	-0.001134596734069891
238	27.39	0.0011952257263532218	-0.001082116993105787
245	27.46	0.0019358897359680327	-0.001029660131367856
252	27.53	0.002713509588970986	-0.0009772269605031138
259	27.6	0.0031923728325429224	-0.0009248182914512671
266	27.67	0.003969862250866374	-0.0008724349342739867
273	27.74	0.004232408246810149	-0.0008200776980363811
280	27.81	0.004515012650849304	-0.0007677473906717311
287	27.88	0.005397677291484548	-0.0007154448189121196
294	27.95	0.005697070661525139	-0.0006631707881918427
301	28.02	0.005729861251736246	-0.0006109261024878486
308	28.09	0.0055460508841398415	-0.0005587115642529733
315	28.16	0.005778974711904805	-0.0005065279744076823
322	28.23	0.005951967886810738	-0.0004543761323644252
329	28.3	0.0057950322252846576	-0.00040225683604486775
336	28.37	0.005844836207995474	-0.00035017088186354775
343	28.44	0.005811381647035763	-0.00029811906473481826
350	28.51	0.005919670351806516	-0.0002461021780882435
357	28.58	0.00637803746334642	-0.00019412101386585023
364	28.65	0.006544818121506868	-0.00014217636249893784
371	28.72	0.006295014131292298	-9.026901285596606e-05
378	28.79	0.00597862729612908	-3.839975220208202e-05
385	28.86	0.005922326084096596	1.3430633741271026e-05
392	28.93	0.006606112294278876	6.522136070747194e-05
399	29.0	0.007609987724313427	0.00011697164588212034
406	29.07	0.008142525599172057	0.00016868070804574786
413	29.14	0.008364680094990362	0.00022034776776301942
420	29.21	0.008257167290178558	0.0002719720474838791
427	29.28	0.00849141754639371	0.00032355277158318906
434	29.35	0.008717432651998536	0.0003750891663702961
441	29.42	0.009085214393072416	0.00042658046012446487
448	29.49	0.009219764553256127	0.0004780258831492276
455	29.56	0.009684418246887816	0.0005294246678269882
462	29.63	0.009655843919685658	0.0005807760486679281
469	29.7	0.009774043348733663	0.0006320792623626389
476	29.77	0.009309018308780281	0.0006833335477991218
483	29.84	0.009344103905376766	0.0007345381460343208
490	29.91	0.00940430190839514	0.000785692300212566
497	29.98	0.009714614084485707	0.0008367952555557994
504	30.05	0.00987147076777184	0.0008878462593776246
511	30.12	0.010685588003380708	0.0009388445611036271
518	30.19	0.010051253261125215	0.0009897894123474555
525	30.26	0.009123706387211161	0.0010406800669970101
532	30.33	0.008442949129505717	0.0010915157810925582
539	30.4	0.008628983232830123	0.0011422958126115674
546	30.47	0.009715143772182078	0.0011930194213305096
553	30.54	0.010351432486455092	0.0012436858688610428
560	30.61	0.01115451777836629	0.0012942944188314564
567	30.68	0.011294401381270358	0.0013448443370718127
574	30.75	0.01098608502547549	0.0013953348917489972
581	30.82	0.011272903771315956	0.001445765353393475
588	30.89	0.011234859343054016	0.001496134994873763
595	30.96	0.010721953462084155	0.0015464430913952954
602	31.03	0.010723473560723562	0.0015966889204778862
609	31.1	0.010696564210038506	0.0016468717618879224
616	31.17	0.01068408426290457	0.001696990897585352
623	31.24	0.010471749711887135	0.0017470456116972309
630	31.31	0.010334562261288927	0.0017970351905056306
637	31.38	0.010187523611731919	0.001846958922389343
644	31.45	0.009821349745926966	0.0018968160977633243
651	31.52	0.009623899500349253	0.0019466060090264818
658	31.59	0.010112317422534378	0.0019963279504882844
665	31.66	0.010434224247678259	0.0020459812183297246
672	31.73	0.009889621660495784	0.0020955651106621584
679	31.8	0.00865351134230119	0.0021450789275731215
686	31.87	0.008517561637778837	0.002194521970983239
693	31.94	0.008656774222173258	0.00224389354443578
700	32.01	0.00912115076794029	0.002293192953000347
707	32.08	0.009710692944459698	0.0023424195032954857
714	32.15	0.010325402418749796	0.0023915725035765813
721	32.22	0.010990280854914047	0.0024406512638746117
728	32.29	0.011371996579945698	0.0024896550961365045
735	32.36	0.011462217917884043	0.0025385833143455956
742	32.43	0.011319279855714015	0.0025874352345995073
749	32.5	0.011051517376232667	0.0026362101751090865
756	32.57	0.010967265458307729	0.0026849074561615094
763	32.64	0.011291525744209885	0.0027335264000708124
770	32.71	0.011129299873378962	0.0027820663311545805
777	32.78	0.011015589481527588	0.0028305265757391485
784	32.85	0.010515396200561078	0.002878906462135493
791	32.92	0.010423721659369	0.0029272053205806185
798	32.99	0.010315567483562216	0.002975422483143328
805	33.06	0.0099742686289912	0.0030235572836675426
812	33.13	0.009914112429273203	0.003071609057730882
819	33.2	0.01065891002423447	0.003119577142574654
826	33.27	0.01008485350326671	0.003167460877128364
833	33.34	0.00924432542893916	0.0032152596020893053
840	33.41	0.008845660741475303	0.003262972659823881
847	33.48	0.009013861044846028	0.003310599394174687
854	33.55	0.009632261273536447	0.0033581391503632184
861	33.62	0.010650863025965407	0.003405591275022467
868	33.69	0.01157800123123609	0.003452955116331288
875	33.76	0.012038677481428728	0.003500230024215121
882	33.83	0.01234956003147536	0.003547415350523543
889	33.9	0.012367317132898847	0.0035945104491432347
896	33.97	0.012388617033478155	0.003641514676052925
903	34.04	0.012466794644170776	0.003688427389326906
910	34.11	0.012336851539751503	0.003735247949141645
917	34.18	0.0122821226246419	0.003781975717774747
924	34.25	0.012322609465621692	0.003828610059562689
931	34.32	0.012398313625332502	0.0038751503408817915
938	34.39	0.012169236662614491	0.003921595930142454
945	34.46	0.011740380132770678	0.003967946197769381
952	34.53	0.011426745588032805	0.004014200516148159
959	34.6	0.01193333457703849	0.004060358259524887
966	34.67	0.011580148644612986	0.0041064188039579685
973	34.74	0.011510522665062695	0.004152381527343558
980	34.81	0.01159445817575655	0.004198245809378984
987	34.88	0.011055290044301724	0.004244011031553493
994	34.95	0.010453019802043162	0.004289676577118097
1001	35.02	0.010267648977098087	0.004335241830950512
1008	35.09	0.010245845761374994	0.004380706179402512
1015	35.16	0.010664278344071576	0.004426069010232755
1022	35.23	0.011237948244221752	0.004471329712615726
1029	35.3	0.012111856977703006	0.004516487677222552
1036	35.37	0.012227672724225425	0.00456154229636489
1043	35.44	0.012385396993384923	0.004606492964150242
1050	35.51	0.01236003129024299	0.004651339076529027
1057	35.58	0.01197419616401918	0.00469608003131225
1064	35.65	0.011993369304091228	0.004740715228154071
1071	35.72	0.011885409349304155	0.0047852440684842895
1078	35.79	0.011927698744617743	0.004829665955466205
1085	35.86	0.012141905644896145	0.00487398029396519
1092	35.93	0.012146364867898551	0.00491818649055676
1099	36.0	0.011964411228020388	0.004962283953552973
1106	36.07	0.011616046202997943	0.005006272093008371
1113	36.14	0.011467937934191763	0.0050501503206652676
1120	36.21	0.011320087893214037	0.005093918049869448
1127	36.28	0.011572497547770677	0.005137574695510157
1134	36.35	0.012025168362283623	0.005181119673981849
1141	36.42	0.011128101798084877	0.005224552403234396
1148	36.49	0.009841299312905782	0.005267872302793956
1155	36.56	0.008924762360849936	0.005311078793574961
1162	36.63	0.008788492393292824	0.005354171297602842
1169	36.7	0.00914249085973573	0.005397149237791419
1176	36.77	0.009536759207934953	0.005440012037884726
1183	36.84	0.009844156026115769	0.005482759122531219
1190	36.91	0.010939444661008046	0.005525389917359942
1197	36.98	0.011211197980155685	0.005567903849087838
1204	37.05	0.011291560276639245	0.0056103003456986775
1211	37.12	0.011172199649742254	0.005652578836534103
1218	37.19	0.011278117529049503	0.005694738752298941
1225	37.26	0.011267648674778474	0.005736779525041386
1232	37.33	0.011100794511202494	0.005778700588143655
1239	37.4	0.010714223126031097	0.005820501376303966
1246	37.47	0.010587935936952952	0.0058621813254761575
1253	37.54	0.010595267692323773	0.005903739872797304
1260	37.61	0.01033621980397248	0.005945176456555523
1267	37.68	0.010410793680168062	0.005986490516166288
1274	37.75	0.009785657392368918	0.006027681492112638
1281	37.82	0.009794145675404486	0.0060687488258992965
1288	37.89	0.009902926594013373	0.0061096919599685886
1295	37.96	0.010745334876570922	0.0061505103376579065
1302	38.03	0.010354705248505791	0.0061912034032590435
1309	38.1	0.009481039098460098	0.0062317706021212714
1316	38.17	0.009207671144741969	0.0062722113805734345
1323	38.24	0.00915126943552691	0.006312525185762775
1330	38.31	0.009561835349772174	0.00635271146553929
1337	38.38	0.009839370264058456	0.0063927696684415265
1344	38.45	0.010350542219294212	0.006432699243772627
1351	38.52	0.010715352587109095	0.006472499641680033
1358	38.59	0.011021421783788732	0.006512170313222877
1365	38.66	0.010885894031974264	0.006551710710464446
1372	38.73	0.010731627836590096	0.006591120286534912
1379	38.8	0.01002767217622269	0.006630398495603438
1386	38.87	0.009957361741467441	0.006669544792808629
1393	38.94	0.009545697887287652	0.006708558634139783
1400	39.01	0.009534348632224798	0.006747439476362524
1407	39.08	0.00949831532485268	0.006786186776958088
1414	39.15	0.009037599310327327	0.006824799994090272
1421	39.22	0.00852720193089862	0.006863278586571806
1428	39.29	0.008392124525929301	0.006901622013747577
1435	39.36	0.008257368432317946	0.006939829735370758
1442	39.43	0.008022934983986652	0.006977901211556593
1449	39.5	0.007355492178301226	0.007015835902745936
1456	39.57	0.007880041343496291	0.0070536332696162305
1463	39.64	0.0074715838054557615	0.0070912927729931755
1470	39.71	0.006788454220824747	0.007128813873847183
1477	39.78	0.005905653911088216	0.007166196032089297
1484	39.85	0.0062731841959120516	0.007203438697988358
1491	39.92	0.006791046393156641	0.007240541299239398
1498	39.99	0.007309241818919343	0.007277503241292817
1505	40.06	0.008127771786964999	0.007314323918690959
1512	40.13	0.00836663760891243	0.0073510027246337225
1519	40.2	0.008925840594552703	0.0073875390524682245
1526	40.27	0.009025382051377928	0.007423932295784657
1533	40.34	0.009045263285039518	0.0074601818485162015
1540	40.41	0.00907548559858995	0.0074962871049782135
1547	40.48	0.008679383625656012	0.007532247459866867
1554	40.55	0.008911403108407878	0.007568062308236736
1561	40.62	0.009288212008747188	0.007603731045435513
1568	40.69	0.0092598116190179	0.007639253067126766
1575	40.76	0.009011758784947421	0.007674627769348338
1582	40.83	0.009304054794466055	0.007709854548526082
1589	40.9	0.009148129503710134	0.007744932801452668
1596	40.97	0.008639698479090185	0.007779861925286764
1603	41.04	0.008473048712203113	0.007814641317490562
1610	41.11	0.008296752906908011	0.007849270375725885
1617	41.18	0.008670812336794231	0.007883748497812646
1624	41.25	0.009195228272631972	0.007918075081707039
1631	41.32	0.009170001982093279	0.007952249525574438
1638	41.39	0.008295134729846332	0.007986271227864796
1645	41.46	0.008445627777189824	0.008020139587259546
1652	41.53	0.008596482381768134	0.00805385400257157
1659	41.6	0.00918936646520141	0.008087413872713754
1666	41.67	0.00954928127970378	0.008120818596750692
1673	41.74	0.010420672518604679	0.008154067574007284
1680	41.81	0.01083687476058115	0.008187160204193284
1687	41.88	0.011056222581141029	0.008220095887537991
1694	41.95	0.010925939441556842	0.008252874024891286
1701	42.02	0.010962693244075616	0.008285494017767372
1708	42.09	0.011116485220960648	0.008317955268327468
1715	42.16	0.010845649935017576	0.008350257179365975
1722	42.23	0.010850188612657075	0.008382399154319884
1729	42.3	0.010655102476713196	0.008414380597223858
1736	42.37	0.010615392747244101	0.00844620091267236
1743	42.44	0.010499393974904514	0.00847785950579922
1750	42.51	0.010322107374013179	0.008509355782246073
1757	42.58	0.010178534155964147	0.008540689148125719
1764	42.65	0.009920342195720355	0.008571859009975223
1771	42.72	0.009892532698343448	0.00860286477470458
1778	42.79	0.009491773532217085	0.008633705849555086
1785	42.86	0.00985806589676308	0.00866438164204631
1792	42.93	0.00985807765529767	0.00869489155992536
1799	43.0	0.009225143334299801	0.008725235011199392
1806	43.07	0.008659264123053845	0.008755411404131526
1813	43.14	0.008293774540252485	0.008785420146726192
1820	43.21	0.008408675768440954	0.00881526064285907
1827	43.28	0.00916396898816485	0.008844932286455458
1834	43.35	0.009432988710964096	0.008874434464055003
1841	43.42	0.010002402779258457	0.008903766561011528
1848	43.49	0.010132212366443127	0.008932927962817139
1855	43.56	0.010309085309638366	0.00896191805520493
1862	43.63	0.010446356109394372	0.008990736224211059
1869	43.7	0.010584025929977425	0.009019381856199582
1876	43.77	0.010888762599248203	0.009047854337876426
1883	43.84	0.010920567274920412	0.009076153056323961
1890	43.91	0.011124441111139305	0.009104277399043827
1897	43.98	0.010938718591959606	0.009132226753996801
1904	44.05	0.011011734197288181	0.009160000509603071
1911	44.12	0.011318489069324755	0.00918759805471035
1918	44.19	0.011418984346595717	0.009215018778617553
1925	44.26	0.011624887831273245	0.009242262071124423
1932	44.33	0.011991200655433687	0.009269327322559747
1939	44.4	0.01186292394796995	0.009296213923829517
1946	44.47	0.011800058834414706	0.009322921266470363
1953	44.54	0.01166760643656728	0.009349448742639073
1960	44.61	0.011677234539085646	0.009375795745060315
1967	44.68	0.011333944256553874	0.009401961667006862
1974	44.75	0.00989773670011429	0.009427945902296153
1981	44.82	0.009441946310639882	0.009453747845168996
1988	44.89	0.009386574192252528	0.009479366889955975
1995	44.96	0.010217335731991462	0.009504802429860779
2002	45.03	0.010737089172042413	0.009530053856823931
2009	45.1	0.011447978466717412	0.009555120562807235
2016	45.17	0.012269290424852475	0.009580001940085053
2023	45.24	0.012476026138148022	0.00960469738141479
2030	45.31	0.012713186695383794	0.009629206280183966
2037	45.38	0.012677439849011485	0.009653528030482557
2044	45.45	0.013138786680983117	0.009677662027119487
2051	45.52	0.013132228268868396	0.009701607665643317
2058	45.59	0.012767210129226214	0.009725364342401455
2065	45.66	0.012255399996524918	0.009748931454547088
2072	45.73	0.012555132268806446	0.009772308399981274
2079	45.8	0.012545296895768665	0.009795494577251328
2086	45.87	0.012689228267513286	0.009818489385545711
2093	45.94	0.012486927437502793	0.009841292224732009
2100	46.01	0.012691728788920553	0.009863902495353634
2107	46.08	0.012685300034557923	0.009886319598588733
2114	46.15	0.013187642217242779	0.009908542936260303
2121	46.22	0.012765423042353508	0.009930571910880568
2128	46.29	0.01321864354404756	0.009952405925706164
2135	46.36	0.013255638085438726	0.009974044384704452
2142	46.43	0.012676407691811331	0.009995486692588752
2149	46.5	0.012230953384213095	0.010016732254838137
2156	46.57	0.012352609512662927	0.010037780477580596
2163	46.64	0.011874710422731027	0.010058630767505487
2170	46.71	0.012347257122522937	0.010079282531814417
2177	46.78	0.012953583949788072	0.010099735178175518
2184	46.85	0.01401035857220867	0.010119988114781904
2191	46.92	0.014700915320552621	0.01014004075052514
2198	46.99	0.014925255189092379	0.01015989249521177
2205	47.06	0.015208379167928943	0.010179542759701262
2212	47.13	0.015184812053210539	0.010198990955987202
2219	47.2	0.014967650066051608	0.010218236497252585
2226	47.27	0.01501760847103828	0.01023727879786468
2233	47.34	0.014320402528472442	0.010256117273336978
2240	47.41	0.014105795113355413	0.010274751340305997
2247	47.48	0.014266644334611556	0.010293180416430715
2254	47.55	0.01456295115430395	0.010311403920320117
2261	47.62	0.014944716530327362	0.010329421271545881
2268	47.69	0.014976941416793288	0.010347231890709664
2275	47.76	0.014789626763394015	0.01036483519950629
2282	47.83	0.015002773515019108	0.010382230620723095
2289	47.9	0.01558304927888221	0.010399417578205861
2296	47.97	0.015205454990844913	0.010416395496914246
2303	48.04	0.016194991582089813	0.010433163802983642
2310	48.11	0.015829993313352997	0.010449721923760995
2317	48.18	0.014958794441746637	0.010466069287928812
2324	48.25	0.014166395886884064	0.010482205325452075
2331	48.32	0.013974465230436106	0.010498129467389589
2338	48.39	0.013874670049731197	0.010513841145717944
2345	48.46	0.014567011251773287	0.010529339793237993
2352	48.53	0.014609823073814088	0.01054462484358083
2359	48.6	0.015011439749055722	0.01055969573130913
2366	48.67	0.015280195505574135	0.010574551891988384
2373	48.74	0.015516091233851448	0.010589192762257385
2380	48.81	0.015485794486253646	0.010603617779884321
2387	48.88	0.015430972809888033	0.010617826383831293
2394	48.95	0.015759960413479046	0.010631818014255882
2401	49.02	0.016137758168609295	0.010645592112478435
2408	49.09	0.01650936694260441	0.01065914812104581
2415	49.16	0.016441454264594313	0.010672485483827123
2422	49.23	0.01609735432523607	0.010685603646060323
2429	49.3	0.016037067977890285	0.010698502054336463
2436	49.37	0.015793929404763762	0.010711180156544505
2443	49.44	0.015184606116470434	0.010723637401819495
2450	49.51	0.015184098952436997	0.010735873240473297
2457	49.58	0.015334075414600967	0.010747887123914295
2464	49.65	0.015126203000550564	0.010759678504622467
2471	49.72	0.015285482536892658	0.010771246836146374
2478	49.79	0.015811914846624475	0.01078259157309206
2485	49.86	0.01652216741562107	0.010793712171141709
2492	49.93	0.016366241058616726	0.010804608087192219
2499	50.0	0.0158941365855485	0.010815278779474054
2506	50.07	0.015622521469214945	0.010825723707511312
2513	50.14	0.015721396511647168	0.01083594233203566
2520	50.21	0.01666409584360684	0.010845934114937597
2527	50.28	0.017420620258839392	0.010855698519309476
2534	50.35	0.017840970547136514	0.010865235009630226
2541	50.42	0.01809681416044251	0.010874543051955855
2548	50.49	0.018303151879438317	0.010883622114026428
2555	50.56	0.018618317813518637	0.010892471665332549
2562	50.63	0.01885064606742537	0.010901091177178239
2569	50.7	0.018830137407626513	0.010909480122716298
2576	50.77	0.01881345926227418	0.01091763797698383
2583	50.84	0.019117279054416514	0.010925564216922756
2590	50.91	0.019701597534510285	0.010933258321389439
2597	50.98	0.019603082113586634	0.010940719771221423
2604	51.05	0.019151733530462067	0.010947948049344873
2611	51.12	0.019407552518282856	0.010954942640765894
2618	51.19	0.01954387313755257	0.010961703032495983
2625	51.26	0.020630696109946278	0.01096822871355467
2632	51.33	0.02148468881779575	0.010974519175061963
2639	51.4	0.02208085197038212	0.010980573910450975
2646	51.47	0.021819186271475388	0.010986392415673214
2653	51.54	0.021383025753367146	0.01099197418930393
2660	51.61	0.021632371109565174	0.010997318732506743
2667	51.68	0.021662223028561023	0.011002425548975084
2674	51.75	0.021177582193739664	0.011007294144945666
2681	51.82	0.02104344928263968	0.011011924029173182
2688	51.89	0.021268158300495443	0.011016314712851675
2695	51.96	0.021951709913747397	0.011020465709583697
2702	52.03	0.02228577145047206	0.01102437653544548
2709	52.1	0.022862010232976182	0.011028046709124155
2716	52.17	0.02323876024459226	0.01103147575201718
2723	52.24	0.02379935546318901	0.011034663188362248
2730	52.31	0.02379379652725877	0.011037608545356072
2737	52.38	0.02434875073553222	0.011040311353236989
2744	52.45	0.024144218714333032	0.011042771145348297
2751	52.52	0.024223058226741756	0.011044987458191867
2758	52.59	0.0243266984582311	0.011046959831423833
2765	52.66	0.024173711444518187	0.01104868780786911
2772	52.73	0.02362838350004326	0.011050170933547963
2779	52.8	0.023355000933540815	0.011051408757630126
2786	52.87	0.02341785004783059	0.011052400832313024
2793	52.94	0.02336693142545565	0.011053146712751009
2800	53.01	0.02343319802346233	0.01105364595704254
2807	53.08	0.02321665041252663	0.011053898126223722
2814	53.15	0.022967289157260318	0.011053902784274112
2821	53.22	0.023368448149683196	0.01105365949808085
2828	53.29	0.023570127942456942	0.011053167837412049
2835	53.36	0.02377232908157545	0.011052427374970985
2842	53.43	0.0246417187720942	0.011051437686447322
2849	53.5	0.02439496421174514	0.011050198350610529
2856	53.57	0.023532065924880996	0.011048708949436582
2863	53.64	0.023053024428846935	0.011046969068068582
2870	53.71	0.02289117356750614	0.011044978294656508
2877	53.78	0.02369651384488325	0.011042736220233353
2884	53.85	0.02490237909166071	0.011040242438714556
2891	53.92	0.02539448408383249	0.011037496547069984
2898	53.99	0.02611568644769946	0.011034498145568653
2905	54.06	0.026898129517543	0.011031246837928966
2912	54.13	0.027551099478890784	0.011027742231471967
2919	54.2	0.027739596796547694	0.011023983937306222
2926	54.27	0.027728621927853414	0.01101997157046837
2933	54.34	0.027938175323269476	0.01101570474998869
2940	54.41	0.028101590759614048	0.011011183098916183
2947	54.48	0.02827886867319096	0.011006406244369524
2954	54.55	0.028510009493804223	0.011001373817576487
2961	54.62	0.02866168031111238	0.010996085453910566
2968	54.69	0.028913881540736597	0.010990540792927503
2975	54.76	0.028626613591322236	0.010984739478410773
2982	54.83	0.02885654353102174	0.01097868115842785
2989	54.9	0.02898224318147502	0.010972365485328591
2996	54.97	0.029734665308415398	0.010965792115754946
3003	55.04	0.029516191240863687	0.01095896071069728
3010	55.11	0.029698249919446695	0.01095187093558619
3017	55.18	0.02991417503893201	0.01094452246030627
3024	55.25	0.029780633618996077	0.010936914959221538
3031	55.32	0.02962762600460378	0.010929048111216394
3038	55.39	0.030015152533103606	0.010920921599703298
3045	55.46	0.03055821353435162	0.010912535112613097
3052	55.53	0.03133514266305415	0.010903888342460498
3059	55.6	0.03124594023198135	0.010894980986474036
3066	55.67	0.031490606545629074	0.010885812746742501
3073	55.74	0.03146080856689881	0.010876383330266795
3080	55.81	0.03161487991744227	0.010866692448993468
3087	55.88	0.03215666703141773	0.01085673981982783
3094	55.95	0.03246213171953105	0.010846525164673354
3101	56.03	0.03264697937392835	0.010836048210523882
3108	56.1	0.03241986409668263	0.010825308689534468
3115	56.17	0.03261328613611658	0.01081430633907133
3122	56.24	0.03295057906654009	0.01080304090172455
3129	56.31	0.03307507645463925	0.01079151212533059
3136	56.38	0.03331677852614634	0.010779719763025419
3143	56.45	0.03330901883129034	0.01076766357328501
3150	56.52	0.03356846424406745	0.010755343319970497
3157	56.59	0.03384511496275966	0.010742758772357867
3164	56.66	0.034672304509614005	0.010729909705192133
3171	56.73	0.034720033064293165	0.010716795898791747
3178	56.8	0.03466163413059675	0.010703417139175596
3185	56.87	0.034790441203119915	0.010689773218121828
3192	56.94	0.03516145443409613	0.01067586393316473
3199	57.01	0.035066340633109316	0.010661689087624222
3206	57.08	0.03537176659996266	0.010647248490651197
3213	57.15	0.03582773245834803	0.01063254195726497
3220	57.22	0.03650923832283626	0.010617569308426321
3227	57.29	0.036741284298864585	0.010602330371149419
3234	57.36	0.037307203815841294	0.010586824978633473
3241	57.43	0.03755699696128545	0.010571052970385722
3248	57.5	0.03832399714597656	0.010555014192313032
3255	57.57	0.0390082044366169	0.010538708496823418
3262	57.64	0.03984961888978411	0.010522135742995913
3269	57.71	0.04004490721743714	0.010505295796766765
3276	57.78	0.040247402787123576	0.010488188531073717
3283	57.85	0.04071710562218378	0.010470813825952592
3290	57.92	0.041314015735346654	0.010453171568625552
3297	57.99	0.04129146646221038	0.010435261653590594
3304	58.06	0.041879457794312014	0.010417083982711843
3311	58.13	0.042267989713083765	0.010398638465278337
3318	58.2	0.04315706218969417	0.010379925018093138
3325	58.27	0.04386667518662346	0.010360943565613095
3332	58.34	0.04408682865859159	0.01034169404015732
3339	58.41	0.04466085588479585	0.010322176382074489
3346	58.48	0.0455937568001219	0.010302390539840122
3353	58.55	0.04591053132944278	0.010282336470186972
3360	58.62	0.046792846053177684	0.010262014138284845
3367	58.69	0.04746236753880462	0.010241423517885366
3374	58.76	0.04813909567507446	0.010220564591493791
3381	58.83	0.049183030339272626	0.010199437350555115
3388	58.9	0.04948750473051433	0.010178041795651406
3395	58.97	0.05001251870297008	0.0101563779367032
3402	59.04	0.05085807209866333	0.010134445793078328
3409	59.11	0.05081416474732858	0.010112245393717799
3416	59.18	0.05091079646602026	0.01008977677728668
3423	59.25	0.05208296705882587	0.01006703999222742
3430	59.32	0.052855676316784894	0.010044035096829025
3437	59.39	0.053287257350532524	0.010020762159441284
3444	59.46	0.054027709923859746	0.009997221258679226
3451	59.53	0.05450203378718488	0.009973412483564585
3458	59.6	0.05550189534351846	0.009949335933661598
3465	59.67	0.05597729431514953	0.009924991719235493
3472	59.74	0.05665323041108428	0.009900379961441554
3479	59.81	0.05752136999316404	0.00987550079249535
3486	59.88	0.05829004607577426	0.009850354355849807
3493	59.95	0.05911925832574383	0.009824940806392726
3500	60.02	0.05961233972853819	0.00979926031064865
3507	60.09	0.06016595658860302	0.009773313046953832
3514	60.16	0.06102010852980699	0.009747099205594587
3521	60.23	0.06190812849482441	0.009720618988970144
3528	60.3	0.06326334941133549	0.00969387261179665
3535	60.37	0.06405243752493472	0.009666860301357405
3542	60.44	0.0641420590645212	0.009639582297786185
3549	60.51	0.0652322135756962	0.009612038854252566
3556	60.58	0.06575623392103891	0.009584230237056129
3563	60.65	0.06679983389930122	0.009556156725813537
3570	60.72	0.06777253681649142	0.009527818613649633
3577	60.79	0.06876481834275561	0.009499216207424487
3584	60.86	0.06982429698802317	0.009470349827963555
3591	60.93	0.07085097219653047	0.00944121981031406
3598	61.0	0.0714115100613113	0.009411826504025604
3605	61.07	0.0722392433243999	0.009382170273355453
3612	61.14	0.07313417137689271	0.00935225149745309
3619	61.21	0.07379629359153306	0.009322070570565064
3626	61.28	0.0748089426562708	0.009291627902230953
3633	61.35	0.07597211790724678	0.009260923917478705
3640	61.42	0.07696081866096449	0.00922995905707708
3647	61.49	0.07831004421538124	0.00919873377781248
3654	61.56	0.07928146051684504	0.009167248552757969
3661	61.63	0.07985506682591614	0.009135503871575874
3668	61.7	0.08088586238411155	0.009103500240759878
3675	61.77	0.08198717974632475	0.009071238183806818
3682	61.84	0.08287901811294152	0.009038718241458148
3689	61.91	0.08404637666290338	0.009005940971974765
3696	61.98	0.08509758788818722	0.00897290695137176
3703	62.05	0.08630765092735082	0.008939616773672545
3710	62.12	0.08732656489801016	0.00890607105119777
3717	62.19	0.08777099556229784	0.00887227041483856
3724	62.26	0.08884094199312553	0.008838215514269976
3731	62.33	0.08964140324141079	0.008803907018107935
3738	62.4	0.09009237833615735	0.008769345614145286
3745	62.47	0.09133719961719411	0.008734532009577727
3752	62.54	0.09240086606837083	0.008699466931170791
3759	62.61	0.09314837665131126	0.008664151125510935
3766	62.68	0.09386425411449029	0.008628585359271388
3773	62.75	0.0949615926112366	0.00859277041942005
3780	62.82	0.09570229579434475	0.008556707113426702
3787	62.89	0.09639350538721514	0.008520396269503966
3794	62.96	0.09701855356539202	0.008483838736788795
3801	63.03	0.09796077248056267	0.00844703538550828
3808	63.1	0.09857016092710902	0.008409987107162047
3815	63.17	0.09947171767548157	0.008372694814718725
3822	63.24	0.10006377480537187	0.00833515944281789
3829	63.31	0.10050133103877235	0.008297381947957509
3836	63.38	0.10099938507325623	0.008259363308645042
3843	63.45	0.1018329355806582	0.008221104525529025
3850	63.52	0.10195698120738461	0.00818260662153738
3857	63.59	0.10211652057500542	0.008143870642032895
3864	63.66	0.10209655228043335	0.008104897654893846
3871	63.73	0.1022170748959006	0.008065688750548333
3878	63.8	0.10227808696929186	0.00802624504198601
3885	63.87	0.10248958702393063	0.007986567664785175
3892	63.94	0.10232157355822702	0.007946657777154233
3899	64.01	0.10247904504556216	0.00790651655995574
3906	64.08	0.10193699993353045	0.007866145216713777
3913	64.15	0.10132043664412782	0.007825544973618993
3920	64.22	0.10122102024136082	0.007784717079461239
3927	64.29	0.10093874909845857	0.00774366280552955
3934	64.36	0.10045695489725404	0.007702383445536101
3941	64.43	0.0998589692943721	0.007660880315555694
3948	64.5	0.09871979058789071	0.007619154753933215
3955	64.57	0.09788108371838344	0.007577208121126722
3962	64.64	0.09712784693563936	0.007535041799474604
3969	64.71	0.09623007846525722	0.007492657192982158
3976	64.78	0.09494277650926408	0.007450055727153775
3983	64.85	0.09458093924569377	0.00740723884879233
3990	64.92	0.09297956482873193	0.007364208025748446
3997	64.99	0.0908086513890698	0.0073209647467597705
4004	65.06	0.0887315303672076	0.007277510521114032
4011	65.13	0.08720486651419357	0.007233846878135288
4018	65.2	0.08567865789240336	0.007189975366701694
4025	65.27	0.08450290254303461	0.007145897554887534
4032	65.34	0.08312759848596363	0.007101615029627077
4039	65.41	0.081969410386324	0.0070571293963974085
4046	65.48	0.0801450028883508	0.007012442278949801
4053	65.55	0.07826270728153695	0.006967555318998462
4060	65.62	0.07627085483373763	0.006922470175805243
4067	65.69	0.07415777679228164	0.006877188525722992
4074	65.76	0.07214347105241625	0.006831712061727657
4081	65.83	0.07007293549034843	0.006786042492953318
4088	65.9	0.06825783462998869	0.006740181544236885
4095	65.97	0.0656281663105327	0.006694130955648016
4102	66.04	0.06306559502101372	0.00664789248197263
4109	66.11	0.060661785234075616	0.006601467892121106
4116	66.18	0.05751173473974047	0.0065548589685368525
4123	66.25	0.05572210797941102	0.006508067506584341
4130	66.32	0.053686236046516456	0.006461095313946032
4137	66.39	0.05098411668752112	0.006413944210121381
4144	66.46	0.04884908096909868	0.006366616025920867
4151	66.53	0.04660612661172969	0.006319112602898224
4158	66.6	0.043913584656410265	0.006271435792783406
4165	66.67	0.04211978613253908	0.006223587456926645
4172	66.74	0.04031306205873797	0.006175569465782359
4179	66.81	0.03888007677708227	0.006127383698441775
4186	66.88	0.036947494619637755	0.006079032042201079
4193	66.95	0.03502197990769984	0.006030516392187778
4200	67.02	0.032350196952245724	0.005981838650930938
4207	67.09	0.030485476722104554	0.005933000727869295
4214	67.16	0.02852115017876322	0.005884004538803253
4221	67.23	0.026590548276459458	0.005834852005427084
4228	67.3	0.024433668628172533	0.005785545054859334
4235	67.37	0.022697175505809408	0.005736085619189577
4242	67.44	0.0207010665089693	0.005686475635002604
4249	67.51	0.019205339232037044	0.005636717042912386
4256	67.58	0.017609991265001845	0.005586811787141861
4263	67.65	0.016215020193632856	0.005536761815145068
4270	67.72	0.014987090265140335	0.005486569077260693
4277	67.79	0.013826199054952859	0.005436235526401713
4284	67.86	0.012232344133747297	0.00538576311776601
4291	67.93	0.01153885640099972	0.005335153808553304
4298	68.0	0.010912400085397067	0.005284409557661513
4305	68.07	0.010495829887219532	0.005233532325486109
4312	68.14	0.00952723859743898	0.005182524073791115
4319	68.21	0.008768528526945651	0.005131386765576291
4326	68.28	0.008310173412259925	0.005080122364903923
4333	68.35	0.00788550413071265	0.00502873283673311
4340	68.42	0.007894518223522162	0.004977220146816443
4347	68.49	0.007753879895659566	0.004925586261622976
4354	68.56	0.0073802533488613875	0.004873833148312896
4361	68.63	0.006552207543724098	0.004821962774729028
4368	68.7	0.006167359058008692	0.004769977109288922
4375	68.77	0.0055697530389746674	0.0047178781208325506
4382	68.84	0.0053558155848887345	0.00466566777852285
4389	68.91	0.005183877554064686	0.004613348051754098
4396	68.98	0.004995603136241922	0.004560920910094469
4403	69.05	0.0042243231858902774	0.004508388323243278
4410	69.12	0.004103368555244291	0.004455752260193207
4417	69.19	0.004016070094633228	0.004403014685659538
4424	69.26	0.0040790919854698515	0.00435017755698778
4431	69.33	0.004082431740753734	0.0042972428205049346
4438	69.4	0.0038894202055343996	0.004244212412345355
4445	69.47	0.003570054889801888	0.004191088261618785
4452	69.54	0.0033843333017324895	0.004137872288583012
4459	69.61	0.0035489196151790026	0.004084566398223883
4466	69.68	0.0034138113367641054	0.004031172476148819
4473	69.75	0.003412339305128409	0.003977692390990371
4480	69.82	0.0031111676907946695	0.003924127995763242
4487	69.89	0.003380293995608241	0.0038704811275921376
4494	69.96	0.003543049052840974	0.0038167536066347134
4501	70.03	0.0031927636935957793	0.0037629472410511127
4508	70.1	0.004009435413987017	0.0037090638293831952
4515	70.17	0.004576395042451331	0.003655105161762109
4522	70.24	0.0048769734064153525	0.003601073026473101
4529	70.31	0.005536167998470454	0.00354696921198028
4536	70.38	0.00547897630988059	0.003492795507083385
4543	70.45	0.005439919640270574	0.0034385537010331157
4550	70.52	0.0052654240499023786	0.003384245583573325
4557	70.59	0.00416739178844816	0.003329872944930103
4564	70.66	0.0033279631989988623	0.0032754375757537875
4571	70.73	0.003205469098930269	0.003220941266913152
4578	70.8	0.0027415736379565736	0.0031663858090789573
4585	70.87	0.002844607631229401	0.0031117729911824244
4592	70.94	0.0025645685590811595	0.003057104595394572
4599	71.01	0.0017847872336163029	0.003002382395348991
4606	71.08	0.0012469277986166816	0.002947608148689576
4613	71.15	0.0009148766193933788	0.002892783585668871
4620	71.22	0.00061363117152613	0.002837910398772625
4627	71.29	0.0006848555966305625	0.00278299023429091
4634	71.36	0.00045632514678350944	0.00272802468825718
4641	71.43	0.0006780372958501424	0.002673015305862794
4648	71.5	0.00047998951724537164	0.0026179635825882594
4655	71.57	0.0007221792828868701	0.0025628709657197265
4662	71.64	0.0008646040640263308	0.0025077388531896377
4669	71.71	0.000647261331187643	0.002452568598070808
4676	71.78	0.00084014855274539	0.0023973615136102474
4683	71.85	0.0010532631953421578	0.0023421188728112554
4690	71.92	0.001286602724696717	0.002286841910885748
4697	71.99	0.0010268312723464845	0.0022315318316520716
4704	72.06	0.0011589463019410218	0.002176189810709593
4711	72.13	0.0015329452763737095	0.002120816995802832
4718	72.2	0.0014321589913111055	0.002065414511311323
4725	72.27	0.0017565849076981443	0.0020099834639058403
4732	72.34	0.0019383633418583734	0.0019545249459470213
4739	72.41	0.0022393965137381677	0.0018990400413693529
4746	72.48	0.0028311104518747854	0.0018435298314531381
4753	72.55	0.0031063597554519262	0.00178799539744438
4760	72.62	0.0030151418801236396	0.0017324378208123756
4767	72.69	0.002407454280115573	0.0016768581833162689
4774	72.76	0.0023332944087708363	0.001621257566986702
4781	72.83	0.0018843263849435132	0.0015656370540462925
4788	72.9	0.0023355476591744306	0.001509997726861948
4795	72.97	0.0020119556800115568	0.0014543406679172549
4802	73.04	0.001858547894475926	0.001398666959847407
4809	73.11	0.0016986550820665691	0.001342977685427452
4816	73.18	0.0004922746885789309	0.0012872739274891601
4823	73.25	0.00048607082595131246	0.0012315567659628853
4830	73.32	0.00039670760473287103	0.0011758272664674947
4837	73.39	1.4182467223733397e-05	0.0011200864747006284
4844	73.46	0.0004018261877805074	0.0010643354150097826
4851	73.53	0.0009096362067548824	0.0010085750902615
4858	73.6	0.001140943297659458	0.0009528064885522119
4865	73.67	0.0010857448997616537	0.0008970305930589468
4872	73.74	0.0015807051167779917	0.0008412483864608778
4879	73.81	0.0018424880513672193	0.0007854608515014985
4886	73.88	0.0016710911391872862	0.0007296689710911229
4893	73.95	0.0011998451482631012	0.0006738737283712956
4900	74.02	0.0013037475123240938	0.0006180761066696418
4907	74.09	0.001237795665478103	0.0005622770894735065
4914	74.16	0.0009669870419806159	0.0005064776604582512
4921	74.23	0.0007829857421595143	0.00045067880346353923
4928	74.3	0.00016578919944709725	0.0003948815024416531
4935	74.37	-0.00022460515362654476	0.00033908674108303256
4942	74.44	-0.0008805808357466027	0.00028329549763820064
4949	74.51	-0.0011983308803191761	0.00022750873427389092
4956	74.58	-0.0016350006789793703	0.00017172738424456416
4963	74.65	-0.00210487844753926	0.0001159523430727509
4970	74.72	-0.0025746333126255294	6.018446144730367e-05
4977	74.79	-0.0033642676807223992	4.424535471080999e-06
4984	74.86	-0.0033387838920599933	-5.1326705826063235e-05
4991	74.93	-0.003883184209480639	-0.0001070686109272901
4998	75.0	-0.00390247081341899	-0.00016280060971671023
5005	75.07	-0.003801645794388797	-0.0002185222189767209
5012	75.14	-0.0037507111499186507	-0.00027423304336133414
5019	75.21	-0.0030346687856481758	-0.00032993277326207694
5026	75.28	-0.002528520519645916	-0.00038562117931772706
5033	75.35	-0.002557268096531562	-0.0004412980970567179
5040	75.42	-0.0021659131973157386	-0.0004969634156959908
5047	75.49	-0.001834457444657378	-0.0005526170718576735
5054	75.56	-0.0013362357438646555	-0.0006082590404506136
5061	75.63	-0.0013045829597366776	-0.0006638893236575865
5068	75.7	-0.002079500590862704	-0.0007195079422311058
5075	75.77	-0.002157656765613414	-0.0007751149369345069
5082	75.84	-0.0016757195629062416	-0.0008307103794748039
5089	75.91	-0.0012436903441850333	-0.0008862943728995334
5096	75.98	-0.0012615704304757003	-0.00094186703990512
5103	76.05	-0.0010793611102495326	-0.0009974285138427473
5110	76.12	-0.0007970636428544786	-0.001052978933874418
5117	76.19	-0.0006346792617968333	-0.0011085184415981129
5124	76.26	-0.0004072091805782385	-0.0011640471789126233
5131	76.33	-0.0004496545971468535	-0.0012195652876063109
5138	76.4	-0.00041701669677607356	-0.0012750729092998487
5145	76.47	-0.00028429665366713763	-0.0013305701854256125
5152	76.54	-0.0001848289666255276	-0.0013860572571969389
5159	76.61	1.4718537482139027e-05	-0.0014415342655563382
5166	76.68	-2.565529671683109e-05	-0.001497001351159648
5173	76.75	9.023885379910723e-05	-0.0015524586543260437
5180	76.82	0.0008471617412664223	-0.001607906315008988
5187	76.89	0.000653683641966385	-0.0016633444727447034
5194	76.96	0.0005969462606412179	-0.0017187732665389112
5201	77.03	0.0007302817780510118	-0.001774192834833161
5208	77.1	0.001347022373835216	-0.001829603315515147
5215	77.17	0.0021916113371625023	-0.0018850048458584838
5222	77.24	0.0033307141787397576	-0.0019403975623667885
5229	77.31	0.0027893297417809215	-0.00199578160054744
5236	77.38	0.0021980124239777687	-0.0020511570947399876
5243	77.45	0.0014817610662931635	-0.0021065241781519756
5250	77.52	0.0014155745085204785	-0.0021618829829833973
5257	77.59	0.001332784922745578	-0.0022172336405452387
5264	77.66	0.0009500578134420401	-0.0022725762813036615
5271	77.73	0.0007673920176749505	-0.0023279110348837393
5278	77.8	1.4530389345068784e-06	-0.0023832380301250277
5285	77.87	1.8906379513516924e-05	-0.002438557395142552
5292	77.94	5.308420695193661e-05	-0.0024938692574243172
5299	78.01	0.00032065202237863133	-0.0025491737438688346
5306	78.08	0.0005382753278979635	-0.002604470980763122
5313	78.15	0.0010226196254188302	-0.0026597610937046236
5320	78.22	0.001157017082934253	-0.0027150442075105797
5327	78.29	0.000791466534479035	-0.00277032044612033
5334	78.36	0.0010759668136754996	-0.0028255899325715333
5341	78.43	0.0026605167536462027	-0.0028808527890223147
5348	78.5	0.003211781851462092	-0.0029361091366231864
5355	78.57	0.0036630942686186607	-0.002991359095260306
5362	78.64	0.0024519528324939976	-0.0030466027833770727
5369	78.71	0.0013991897029090872	-0.0031018403179491933
5376	78.78	0.00033397037227445026	-0.0031570718146495835
5383	78.85	-0.0003312063344429461	-0.0032122973880683967
5390	78.92	-0.0003820558767415605	-0.0032675171519347887
5397	78.99	-0.001194769896179615	-0.0033227312192688845
5404	79.06	-0.0009098257335371507	-0.003377939702444198
5411	79.13	-0.0010715102294724943	-0.0034331427132627402
5418	79.2	-0.0010564911543564648	-0.0034883403629380073
5425	79.27	-0.0013714362552592618	-0.003543532762089346
5432	79.34	-0.0017063465862960925	-0.0035987200207616863
5439	79.41	-0.0014178898330707845	-0.003653902248494719
5446	79.48	-0.0012660669749076092	-0.003709079554355328
5453	79.55	-0.0013665932414426152	-0.003764252046881604
5460	79.62	-0.0007789933532671434	-0.0038194198340503888
5467	79.69	-0.000985411047977447	-0.0038745830232343377
5474	79.76	-0.001275132896653819	-0.0039297417211182776
5481	79.83	-0.0016148263982085354	-0.0039848960336992
5488	79.9	-0.0019794923528984043	-0.0040400460663357046
5495	79.97	-0.001302464854861629	-0.004095191923812257
5502	80.04	-0.0014837446228948004	-0.0041503337103643385
5509	80.11	-0.0010983323387390165	-0.004205471529616867
5516	80.18	-0.00134289531666143	-0.004260605484538016
5523	80.25	-0.0008774341755106718	-0.004315735677379981
5530	80.32	-0.001358616173089633	-0.004370862209653039
5537	80.39	-0.0011964418741445826	-0.004425985182091512
5544	80.46	-0.0011459118131220691	-0.0044811046946813295
5551	80.53	-0.0007520264948066568	-0.004536220846643726
5558	80.6	-0.0005997863968842942	-0.0045913337363868816
5565	80.67	-0.0005475253095212906	-0.004646443461424309
5572	80.74	-0.0003452436734336928	-0.004701550118319734
5579	80.81	2.3724751552212098e-05	-0.004756653802649256
5586	80.88	0.00023271287911663663	-0.004811754608917382
5593	80.95	0.00042838695707159147	-0.004866852630473864
5600	81.02	0.00046407989898034074	-0.004921947959454096
5607	81.09	0.0011797912839073277	-0.004977040686730345
5614	81.16	0.0010105206905421937	-0.005032130901852212
5621	81.23	0.001096267696495179	-0.005087218692918567
5628	81.3	0.0011070318775403543	-0.005142304146555576
5635	81.37	0.0008628128077390329	-0.005197387347914308
5642	81.44	0.0007452767271955985	-0.0052524683806633304
5649	81.51	0.0008644232086472137	-0.005307547327012234
5656	81.58	0.001090251823440358	-0.0053626242677032865
5663	81.65	0.0015360954754104483	-0.005417699281979653
5670	81.72	0.0016552870668533615	-0.005472772447525536
5677	81.79	0.001207826165097181	-0.005527843840376261
5684	81.86	0.0009687123356796334	-0.0055829135348849195
5691	81.93	0.001096278475839707	-0.0056379816037761925
5698	82.0	0.001045524148962862	-0.005693048118173761
5705	82.07	0.0015264489178150598	-0.005748113147577959
5712	82.14	0.001937385677468928	-0.005803176759823966
5719	82.21	0.001423333988546549	-0.005858239020993505
5726	82.28	0.0010292934099136453	-0.005913299995344934
5733	82.35	0.0007452634994034035	-0.005968359745384578
5740	82.42	0.0006312438136046872	-0.006023418331955057
5747	82.49	0.0007172339084111634	-0.006078475814266254
5754	82.56	0.0007782333392172269	-0.006133532249917282
5761	82.63	0.00016924166066889512	-0.006188587694875221
5768	82.7	-0.00010331300122468079	-0.006243642203483782
5775	82.77	-0.00033871680462960185	-0.006298695828563404
5782	82.84	0.0001639821912591266	-0.0063537486214581785
5789	82.91	-0.00023331168643414557	-0.006408800632031924
5796	82.98	-5.917029800261986e-05	-0.006463851908622003
5803	83.05	-0.00021454645254115334	-0.006518902498047002
5810	83.12	-0.0009084881932022171	-0.006573952445609514
5817	83.19	-0.000489091173815126	-0.006629001795123819
5824	83.26	-0.0004263557917694172	-0.006684050588999202
5831	83.33	-0.0005902824284795827	-0.006739098868201427
5838	83.4	-0.0009475381179937514	-0.006794146672215123
5845	83.47	-0.000728123209495557	-0.006849194039083728
5852	83.54	-0.00018203802988292495	-0.006904241005434937
5859	83.61	-0.0003809495563658061	-0.0069592876064001824
5866	83.68	-0.000419858091704306	-0.00701433387552944
5873	83.75	-3.3763928555252676e-05	-0.007069379844797144
5880	83.82	-0.0002976673503534144	-0.007124425544575895
5887	83.89	-0.0007215686348365224	-0.007179471003582429
5894	83.96	-0.0008588013852333098	-0.007234516248884265
5901	84.03	-0.000703651569335495	-0.007289561305970672
5908	84.1	-0.0010865956122403375	-0.007344606198771875
5915	84.17	-0.0008004908730501192	-0.007399650949645902
5922	84.24	-0.0009560518334268409	-0.007454695579391052
5929	84.31	-0.0007249453357869307	-0.007509740107234935
5936	84.38	-0.0007288382016543693	-0.007564784550826433
5943	84.45	-0.0008127305669152207	-0.007619828926205614
5950	84.52	-0.0005509082617232153	-0.007674873247797485
5957	84.59	-0.0009205142413963863	-0.007729917528367592
5964	84.66	-0.0005644057297913285	-0.007784961778996253
5971	84.73	-0.00017829707398853145	-0.007840006009097329
5978	84.8	-0.00045885498815367853	-0.007895050226352146
5985	84.87	-0.0005132223690154092	-0.007950094436627113
5992	84.94	-0.0005199706759659861	-0.008005138643970932
5997	84.99	-0.0009013215026199006	-0.008044455934457876