File: output_data/single/cleaned_data.txt
	Temperature (C)	Heat Flow (W/g)
437	25.01	-0.02707690107442584
441	25.05	-0.026565763813304777
445	25.09	-0.02616462655117635
449	25.13	-0.02572063214287512
453	25.17	-0.025045685346670954
457	25.21	-0.02486121472903413
461	25.25	-0.0246934107598773
465	25.29	-0.024258940098230042
469	25.33	-0.02410780273516
473	25.37	-0.02385666532711106
477	25.41	-0.02368052786255559
481	25.45	-0.023504390328668467
485	25.49	-0.02364325271136014
489	25.53	-0.023552114995243567
493	25.57	-0.02350097716361521
497	25.61	-0.02277483919849166
501	25.65	-0.021915367747280978
505	25.69	-0.021447562789470354
509	25.73	-0.0212297576366689
513	25.77	-0.02124528559932548
517	25.81	-0.021827479986781917
521	25.85	-0.0219630074406032
525	25.89	-0.02242520126785852
529	25.93	-0.022290728107738467
533	25.97	-0.022156254598151737
537	26.01	-0.021738447375808434
541	26.05	-0.021067306409563002
545	26.09	-0.020519498333702924
549	26.13	-0.019960023114697023
553	26.17	-0.019433880717963703
557	26.21	-0.0185827377744876
561	26.25	-0.01805659424751216
565	26.29	-0.017640450099286387
569	26.33	-0.017379305291064018
573	26.37	-0.017244826449837714
577	26.41	-0.01757701353502794
581	26.45	-0.017655866505175588
585	26.49	-0.017599718651239993
589	26.53	-0.017348569929918956
593	26.57	-0.01698908696361645
597	26.61	-0.017031269707154628
601	26.65	-0.016980118114551246
605	26.69	-0.016502298805619375
609	26.73	-0.016151145065872896
613	26.77	-0.015766656846564864
617	26.81	-0.015515500764681
621	26.85	-0.015189343436332159
625	26.89	-0.015079851476803796
629	26.93	-0.014876310548158855
633	26.97	-0.015010863454496981
637	27.01	-0.015426367284776976
641	27.05	-0.015158536269909817
645	27.09	-0.014632370354216384
649	27.13	-0.014006202814557334
653	27.17	-0.014295033593720419
657	27.21	-0.014570529300493185
661	27.25	-0.014881261304784399
665	27.29	-0.015121515261431462
669	27.33	-0.014783672062564701
673	27.37	-0.014665826885225997
677	27.41	-0.014381313000917828
681	27.45	-0.014021797013755943
685	27.49	-0.013395612193809026
689	27.53	-0.012865853715144038
693	27.57	-0.012500378655897482
697	27.61	-0.012212044093536711
701	27.65	-0.011707516628633119
705	27.69	-0.011264653337240471
709	27.73	-0.011138454151818689
713	27.77	-0.011187252337447884
717	27.81	-0.010636047825238748
721	27.85	-0.009784840545635554
725	27.89	-0.009519344714209677
729	27.93	-0.009342417403157999
733	27.97	-0.009031201398474131
737	28.01	-0.009079982342710569
741	28.05	-0.009085903020721986
745	28.09	-0.009177534788269437
749	28.13	-0.008892972810141675
753	28.17	-0.008950074155375187
757	28.21	-0.008857172082932685
761	28.25	-0.008505933184518533
765	28.29	-0.00857135738455339
769	28.33	-0.008570111273592751
773	28.37	-0.008452194775045552
777	28.41	-0.008347607811869828
781	28.45	-0.008306350306532817
785	28.49	-0.007998422180944598
789	28.53	-0.00806382335646827
793	28.57	-0.007795887087314934
797	28.61	-0.007536279960600023
801	28.65	-0.007326668562980476
805	28.69	-0.007175386147340035
809	28.73	-0.007471718347127787
813	28.77	-0.0077061412715502264
817	28.81	-0.007654845315033576
821	28.85	-0.0077035446810111985
825	28.89	-0.007418905953298083
829	28.93	-0.00684092904852962
833	28.97	-0.006149613882918015
837	29.01	-0.005578293705633897
841	29.05	-0.00528696843216192
845	29.09	-0.005128971310965902
849	29.13	-0.004894302256865046
853	29.17	-0.004726294517677143
857	29.21	-0.004766614674251546
861	29.25	-0.004623595973866745
865	29.29	-0.004213904996843709
869	29.33	-0.0041708749898758946
873	29.37	-0.0037361725327365036
877	29.41	-0.003884797538341367
881	29.45	-0.0034134165860746357
885	29.49	-0.0033820295884794405
889	29.53	-0.002913969791203286
893	29.57	-0.0026459037730046653
897	29.61	-0.002894498112430366
901	29.65	-0.002556419387813591
905	29.69	-0.002350000843915012
909	29.73	-0.002773575725217192
913	29.77	-0.0028721439426417916
917	29.81	-0.0028207054069309123
921	29.85	-0.002735926695240476
925	29.89	-0.00251780771779897
929	29.93	-0.0024763483845520184
933	29.97	-0.0022148819384515406
937	30.01	-0.002238408288863347
941	30.05	-0.001890498773587268
945	30.09	-0.0012504390160414935
949	30.13	-0.0009189432109177886
953	30.17	-0.00135743983842751
957	30.21	-0.0018559288071662294
961	30.25	-0.0022444100255176735
965	30.29	-0.0026778834016063513
969	30.33	-0.002901348843217022
973	30.37	-0.0027164729245345853
977	30.41	-0.002498255552777273
981	30.45	-0.0019216966348509779
985	30.49	-0.0011701294108061866
989	30.53	-0.0007935537871945897
993	30.57	-0.0003119696703794972
997	30.61	0.0002262897000062658
1001	30.65	0.00041122441763841167
1005	30.69	0.0004628345760551156
1009	30.73	0.00028945360198884273
1013	30.77	0.00046608158877337047
1017	30.81	0.0006177186296723036
1021	30.85	0.0006493648177809952
1025	30.89	0.0007210202460612436
1029	30.93	0.0006726850073848212
1033	30.97	0.00028435919455249703
1037	31.01	0.0004760429003356492
1041	31.05	0.0004277362174591737
1045	31.09	0.00034610590525163687
1049	31.13	0.0005111520562484095
1053	31.17	0.0005828747628515707
1057	31.21	0.000509607450685845
1061	31.25	0.00038635021196675723
1065	31.29	0.0003381031388833833
1069	31.33	0.00038986632357485007
1073	31.37	0.00037497319144286223
1077	31.41	0.0002434238343944628
1081	31.45	0.000130932629839986
1085	31.49	0.00019702347886640936
1089	31.53	2.883933010666695e-05
1093	31.57	0.00027566598923911556
1097	31.61	0.000719170214278364
1101	31.65	0.0010443520965068842
1105	31.69	0.0009562117271211257
1109	31.73	0.0006080825305727622
1113	31.77	-0.00014003540211948717
1117	31.81	-0.0003548086467448641
1121	31.85	-0.000619570445783868
1125	31.89	-0.0006093207082886742
1129	31.93	-0.0003573926764448565
1133	31.97	-2.045292559715861e-05
1137	32.01	0.0002464986356311982
1141	32.05	0.0005234620985254956
1145	32.09	0.001058770887464533
1149	32.13	0.0017024250932822227
1153	32.17	0.0018508533780905445
1157	32.21	0.002306436784798027
1161	32.25	0.0026834611181381085
1165	32.29	0.002902164563728604
1169	32.33	0.0029275472118381884
1173	32.37	0.0030729424859412546
1177	32.41	0.002891683809346901
1181	32.45	0.00292710460517398
1185	32.49	0.002962538296443995
1189	32.53	0.002881318306025893
1193	32.57	0.0029001113900863906
1197	32.61	0.0031855843047110532
1201	32.65	0.003029403805876907
1205	32.69	0.0032065699828249805
1209	32.73	0.0031587495913858454
1213	32.77	0.003185942720693724
1217	32.81	0.002879816126503343
1221	32.85	0.002848703231202343
1225	32.89	0.0025842707904990547
1229	32.93	0.0028298522266858583
1233	32.97	0.0028721142952625733
1237	33.01	0.0026743904183086364
1241	33.05	0.0025516806844274598
1245	33.09	0.002438985182121378
1249	33.13	0.0026455897141506313
1253	33.17	0.0032979229403244936
1257	33.21	0.0035109849488592637
1261	33.25	0.0034383472563894735
1265	33.29	0.0029907242366364883
1269	33.33	0.0023681159775676974
1273	33.37	0.0022455225670738876
1277	33.41	0.001972944093024065
1281	33.45	0.0022503806432681017
1285	33.49	0.0025028323056028867
1289	33.53	0.0029052991677342987
1293	33.57	0.003307781317268166
1297	33.61	0.004110278841648718
1301	33.65	0.004469934685275234
1305	33.69	0.005098653697165556
1309	33.73	0.005417864535781192
1313	33.77	0.0056370910975815924
1317	33.81	0.006023000136025303
1321	33.85	0.0061005917378404995
1325	33.89	0.006028199323070194
1329	33.93	0.00621415631168265
1333	33.97	0.006300129456819459
1337	34.01	0.00651945217825789
1341	34.05	0.0065387912289947
1345	34.09	0.006366480028574539
1349	34.13	0.006344185329794527
1353	34.17	0.006436907218672072
1357	34.21	0.006629645781116356
1361	34.25	0.006622401102958531
1365	34.29	0.006621839936560736
1369	34.33	0.006757962367395898
1373	34.37	0.006635768480701465
1377	34.41	0.006646925028259254
1381	34.45	0.00630643209507431
1385	34.49	0.006085956432754891
1389	34.53	0.006112164792750008
1393	34.57	0.006391723926468806
1397	34.61	0.006727967251966671
1401	34.65	0.0064308948538944755
1405	34.69	0.006517173483520544
1409	34.73	0.0065768032253603614
1413	34.77	0.006839784163790608
1417	34.81	0.006662783049699694
1421	34.85	0.0064457999671474475
1425	34.89	0.0061238350000576425
1429	34.93	0.005818554898890049
1433	34.97	0.005454959747297927
1437	35.01	0.005658049628846751
1441	35.05	0.005501157960253522
1445	35.09	0.005694284824747875
1449	35.13	0.005867430305508403
1453	35.17	0.006320594485676345
1457	35.21	0.006707110781615455
1461	35.25	0.007193645942883631
1465	35.29	0.007746866718866485
1469	35.33	0.008133439858803104
1473	35.37	0.008053365445189087
1477	35.41	0.008139976893721812
1481	35.45	0.008393274286613739
1485	35.49	0.008506591039316724
1489	35.53	0.008349927233759491
1493	35.57	0.008286616285036352
1497	35.61	0.008206658274853673
1501	35.65	0.008193386618130738
1505	35.69	0.008113468063022378
1509	35.73	0.008141902691005676
1513	35.77	0.008140357250098873
1517	35.81	0.008423831821510852
1521	35.85	0.008527326486384101
1525	35.89	0.00873084132577917
1529	35.93	0.008717709753969682
1533	35.97	0.008887931851758069
1537	36.01	0.008641507699797657
1541	36.05	0.008495104045232793
1545	36.09	0.008328720968430403
1549	36.13	0.008402358549663536
1553	36.17	0.008181016869091895
1557	36.21	0.008259696006783113
1561	36.25	0.008423396042770204
1565	36.29	0.008737117057018295
1569	36.33	0.009170859129377984
1573	36.37	0.008949622339570418
1577	36.41	0.00842840676719625
1581	36.45	0.007672212491695696
1585	36.49	0.007146039592345943
1589	36.53	0.006639888148331163
1593	36.57	0.006193758238714597
1597	36.61	0.006114316609084014
1601	36.65	0.0064015633383167625
1605	36.69	0.006705498505195084
1609	36.73	0.0070237412359972495
1613	36.77	0.007203434466508618
1617	36.81	0.0073174354182774515
1621	36.85	0.007871458455673608
1625	36.89	0.0085255036572498
1629	36.93	0.00884623776805249
1633	36.97	0.009233660866327043
1637	37.01	0.009354439696881656
1641	37.05	0.009316907671077512
1645	37.09	0.009121064866758122
1649	37.13	0.009321673266455832
1653	37.17	0.009604447233567015
1657	37.21	0.009408672559891862
1661	37.25	0.009446254084732875
1665	37.29	0.009517191885398901
1669	37.33	0.009481486039157883
1673	37.37	0.009275803289944484
1677	37.41	0.009096810381600928
1681	37.45	0.009159507391161448
1685	37.49	0.009318894395546451
1689	37.53	0.009218304804913924
1693	37.57	0.009372738695952343
1697	37.61	0.00906886281185848
1701	37.65	0.009131677229035962
1705	37.69	0.009131182023812912
1709	37.73	0.008865710605803656
1713	37.77	0.008680263051206172
1717	37.81	0.008908172769414247
1721	37.85	0.008789439836340396
1725	37.89	0.008984064327786978
1729	37.93	0.009713712986139988
1733	37.97	0.009993385887076212
1737	38.01	0.009681416439533574
1741	38.05	0.009477804719034477
1745	38.09	0.009032550801013173
1749	38.13	0.008778988094143791
1753	38.17	0.008633783340334933
1757	38.21	0.008471936614752096
1761	38.25	0.008776781325819716
1765	38.29	0.008964984215138916
1769	38.33	0.009236545357507175
1773	38.37	0.009674798160915099
1777	38.41	0.00964640936659622
1781	38.45	0.010118045715683976
1785	38.49	0.010186373949170768
1789	38.53	0.010661394141223912
1793	38.57	0.010916439699218738
1797	38.61	0.010921510697088799
1801	38.65	0.011001607208623199
1805	38.69	0.010931729307518179
1809	38.73	0.010836877067428752
1813	38.77	0.010532050561865347
1817	38.81	0.010247249864066
1821	38.85	0.010102475047073511
1825	38.89	0.01023772618376606
1829	38.93	0.010133003346892266
1833	38.97	0.009901639942449858
1837	39.01	0.009973636042979184
1841	39.05	0.010098991720894013
1845	39.09	0.009934373715176026
1849	39.13	0.009906448764676057
1853	39.17	0.009478550274781838
1857	39.21	0.009150678317462635
1861	39.25	0.00915616629786875
1865	39.29	0.009161680954425488
1869	39.33	0.009367222358793281
1873	39.37	0.009222790582499307
1877	39.41	0.009145052363753514
1881	39.45	0.008934007773985009
1885	39.49	0.008314656884509386
1889	39.53	0.00874533309985992
1893	39.57	0.00897603649111467
1897	39.61	0.008723433795867486
1901	39.65	0.008562525084913286
1905	39.69	0.008118310428890663
1909	39.73	0.007924123231612956
1913	39.77	0.0074599635633938455
1917	39.81	0.007335831494428735
1921	39.85	0.007691727094796708
1925	39.89	0.007897650434500303
1929	39.93	0.008470268250063029
1933	39.97	0.008826247277891497
1937	40.01	0.009215587587583673
1941	40.05	0.009588289248611659
1945	40.09	0.009794352330251499
1949	40.13	0.010103776901634998
1953	40.17	0.010439896365168178
1957	40.21	0.010796044123208226
1961	40.25	0.010952220244722533
1965	40.29	0.01088842479856611
1969	40.33	0.010884657853471147
1973	40.37	0.011120919478163849
1977	40.41	0.011127209741304878
1981	40.45	0.01096686204481534
1985	40.49	0.010769876457159544
1989	40.53	0.010896253046700277
1993	40.57	0.011235991881716867
1997	40.61	0.011359093030431922
2001	40.65	0.011540556561023152
2005	40.69	0.011622049208292573
2009	40.73	0.011561904373626586
2013	40.77	0.011585122125036484
2017	40.81	0.011841702530436038
2021	40.85	0.011773312324204088
2025	40.89	0.011754951573821337
2029	40.93	0.011351620346591318
2033	40.97	0.011308318709630782
2037	41.01	0.011191713396546454
2041	41.05	0.01129847114080107
2045	41.09	0.01113859200906342
2049	41.13	0.011045409401197581
2053	41.17	0.01145225671695993
2057	41.21	0.01205913402257508
2061	41.25	0.012166041384117587
2065	41.29	0.011922978867568101
2069	41.33	0.01215994653879493
2073	41.37	0.011686944463495497
2077	41.41	0.011527306040580942
2081	41.45	0.01165103133549028
2085	41.49	0.011541453746888752
2089	41.53	0.011865240006602829
2093	41.57	0.012362390179594396
2097	41.61	0.012529570997314554
2101	41.65	0.012870115857686049
2105	41.69	0.01349402482513895
2109	41.73	0.013801297964065817
2113	41.77	0.014008602005453952
2117	41.81	0.014399270346795667
2121	41.85	0.014589969718759477
2125	41.89	0.014655700185222553
2129	41.93	0.014718128476595815
2133	41.97	0.014745587989815512
2137	42.01	0.01467807878832561
2141	42.05	0.014782029506895888
2145	42.09	0.014968154494536368
2149	42.13	0.014963239528780647
2153	42.17	0.01468335610135263
2157	42.21	0.014591004275253283
2161	42.25	0.014758684113389986
2165	42.29	0.014781395678560738
2169	42.33	0.014814139033445528
2173	42.37	0.014751914240638708
2177	42.41	0.014579721362645959
2181	42.45	0.0147675604618831
2185	42.49	0.014570431600724909
2189	42.53	0.014363334841443365
2193	42.57	0.014561270246148172
2197	42.61	0.014419237876898805
2201	42.65	0.014337237795675861
2205	42.69	0.014285270064362532
2209	42.73	0.014210001411393947
2213	42.77	0.014201431898482664
2217	42.81	0.014009561587282171
2221	42.85	0.014284390539307523
2225	42.89	0.014665918815921941
2229	42.93	0.014550813144988517
2233	42.97	0.014442406920851969
2237	43.01	0.013934033537663204
2241	43.05	0.013475693056077986
2245	43.09	0.013403099822347997
2249	43.13	0.013155777706371552
2253	43.17	0.013159202958800797
2257	43.21	0.013372661353956428
2261	43.25	0.01385115295178263
2265	43.29	0.014259677812155758
2269	43.33	0.014418235994817508
2273	43.37	0.014726827559412126
2277	43.41	0.015052119232149774
2281	43.45	0.015315539643865783
2285	43.49	0.015362803139506997
2289	43.53	0.015611528825781651
2293	43.57	0.015820288190157683
2297	43.61	0.015629081291380853
2301	43.65	0.015817908188079155
2305	43.69	0.01594676893873448
2309	43.73	0.016015663601605556
2313	43.77	0.016381258901392304
2317	43.81	0.0164402215626267
2321	43.85	0.01656588497639344
2325	43.89	0.016858249200331077
2329	43.93	0.016517314291930152
2333	43.97	0.016543080308505154
2337	44.01	0.016618880640521194
2341	44.05	0.016761382011611925
2345	44.09	0.016909473367492378
2349	44.13	0.017263154764876276
2353	44.17	0.017272426260344087
2357	44.21	0.017305065688116184
2361	44.25	0.01747440643783893
2365	44.29	0.01778378189909935
2369	44.33	0.01799319212805317
2373	44.37	0.01810263718074978
2377	44.41	0.017902117113089755
2381	44.45	0.017881631980803725
2385	44.49	0.01758118183955748
2389	44.53	0.017740766744937186
2393	44.57	0.01790038675244876
2397	44.61	0.017926708584070195
2401	44.65	0.01785973229499671
2405	44.69	0.01747945794029615
2409	44.73	0.01691064747968829
2413	44.77	0.0161490152537076
2417	44.81	0.015892180364575292
2421	44.85	0.015878714295292085
2425	44.89	0.015878617100146375
2429	44.93	0.01653855549993377
2433	44.97	0.01674852954859407
2437	45.01	0.017291872633242278
2441	45.05	0.017601918140863315
2445	45.09	0.018164380410634173
2449	45.13	0.018663783305293613
2453	45.17	0.01899893640168715
2457	45.21	0.019109125466993948
2461	45.25	0.019419350553899317
2465	45.29	0.019662945048236402
2469	45.33	0.01931990900234304
2473	45.37	0.01963357580169589
2477	45.41	0.019860612164928515
2481	45.45	0.020101018143876992
2485	45.49	0.020156460456954406
2489	45.53	0.020041939155776678
2493	45.57	0.020152454291836097
2497	45.61	0.019763005916500376
2501	45.65	0.019409308366696187
2505	45.69	0.019484218836330225
2509	45.73	0.019744880233480977
2513	45.77	0.019765578323195587
2517	45.81	0.019866313156052584
2521	45.85	0.02006041811576198
2525	45.89	0.01981646468111853
2529	45.93	0.019798738616453537
2533	45.97	0.01985962092403737
2537	46.01	0.020103873558336094
2541	46.05	0.020081496568893797
2545	46.09	0.02015915667182222
2549	46.13	0.02059637772601075
2553	46.17	0.020664588352103053
2557	46.21	0.020442360027658868
2561	46.25	0.020286835658573033
2565	46.29	0.0208480152934718
2569	46.33	0.02103923231411864
2573	46.37	0.021020486768776436
2577	46.41	0.020515112038843153
2581	46.45	0.020283108172268527
2585	46.49	0.020054475216908063
2589	46.53	0.020149213220536755
2593	46.57	0.02019398889741275
2597	46.61	0.020022135628330773
2601	46.65	0.019850320127329457
2605	46.69	0.020086875774909085
2609	46.73	0.020290135951353427
2613	46.77	0.020715100703369238
2617	46.81	0.021446770077409916
2621	46.85	0.02205847745306988
2625	46.89	0.02242022287645451
2629	46.93	0.022798673060202557
2633	46.97	0.02284382805015417
2637	47.01	0.023305687891994165
2641	47.05	0.023267585964557025
2645	47.09	0.023604522313196874
2649	47.13	0.023434354126045776
2653	47.17	0.023153510019692458
2657	47.21	0.02331556146770719
2661	47.25	0.023344318038712508
2665	47.29	0.02328977977730906
2669	47.33	0.023001946727933653
2673	47.37	0.022664152268218274
2677	47.41	0.02255139644231985
2681	47.45	0.022788679294199365
2685	47.49	0.02257600086758904
2689	47.53	0.023113361205978844
2693	47.57	0.02325076035271323
2697	47.61	0.02341319835103617
2701	47.65	0.02372567524401248
2705	47.69	0.023613191074489226
2709	47.73	0.02345907921858048
2713	47.77	0.02328833971900135
2717	47.81	0.023484305951700257
2721	47.85	0.023933644625814487
2725	47.89	0.02417635578364541
2729	47.93	0.024105772800657288
2733	47.97	0.0240268957187868
2737	48.01	0.02466472457970026
2741	48.05	0.0251704499010299
2745	48.09	0.025050500295459077
2749	48.13	0.024553447232578574
2753	48.17	0.024116433610334997
2757	48.21	0.023679459469378106
2761	48.25	0.023167524850197463
2765	48.29	0.02287229645972877
2769	48.33	0.02294377433800543
2773	48.37	0.022998625191466893
2777	48.41	0.023195182393037417
2781	48.45	0.02355844598223511
2785	48.49	0.023821749331832898
2789	48.53	0.02378509248115357
2793	48.57	0.024088475469361548
2797	48.61	0.024378565002158403
2801	48.65	0.024475361118510897
2805	48.69	0.024605530523920116
2809	48.73	0.024873835161833835
2813	48.77	0.02514598935646406
2817	48.81	0.024829612193780548
2821	48.85	0.024693275140537096
2825	48.89	0.024790311568131163
2829	48.93	0.024987388181131553
2833	48.97	0.025434505017273512
2837	49.01	0.025581662114144255
2841	49.05	0.02581219284248437
2845	49.09	0.026016097239507374
2849	49.13	0.025915042008967326
2853	49.17	0.02592902718779344
2857	49.21	0.02568471947947426
2861	49.25	0.02565711892067224
2865	49.29	0.025696225547860774
2869	49.33	0.02540037273061735
2873	49.37	0.02545789383832142
2877	49.41	0.02503878890679001
2881	49.45	0.02490305797161252
2885	49.49	0.024842367734854598
2889	49.53	0.024941718231680454
2893	49.57	0.025079442830463705
2897	49.61	0.024935541566116992
2901	49.65	0.024941681140083105
2905	49.69	0.025139528253641075
2909	49.73	0.02500408294117218
2913	49.77	0.025468678570203185
2917	49.81	0.026213315174655527
2921	49.85	0.026397992788193214
2925	49.89	0.026296044777594396
2929	49.93	0.026327471176050832
2933	49.97	0.02602560534991971
2937	50.01	0.025823780665404694
2941	50.05	0.025621997155247378
2945	50.09	0.02565358818533303
2949	50.13	0.02568522045462318
2953	50.17	0.026066893995157603
2957	50.21	0.02676527550547325
2961	50.25	0.02724703168390885
2965	50.29	0.027778829228600088
2969	50.33	0.028117334837511887
2973	50.37	0.028142548541777668
2977	50.41	0.028227803705809684
2981	50.45	0.02854810036061073
2985	50.49	0.028538438537065947
2989	50.53	0.02887881826595029
2993	50.57	0.028869239577871575
2997	50.61	0.02895970250319424
3001	50.65	0.02915020707213145
3005	50.69	0.029265753314778653
3009	50.73	0.029231341261081845
3013	50.77	0.029176970940796743
3017	50.81	0.029387642383523982
3021	50.85	0.02962835561863697
3025	50.89	0.030019110675242544
3029	50.93	0.030259907582209422
3033	50.97	0.030325746368217832
3037	51.01	0.029891627061840786
3041	51.05	0.02963754969152932
3045	51.09	0.029790180952240508
3049	51.13	0.02982285420548081
3053	51.17	0.029888902812594154
3057	51.21	0.030421660134748674
3061	51.25	0.03108779286623964
3065	51.29	0.031653967701125385
3069	51.33	0.03208685133327993
3073	51.37	0.03243644378967181
3077	51.41	0.032652745096989566
3081	51.45	0.032576231472209116
3085	51.49	0.032235474370274186
3089	51.53	0.032101902388838255
3093	51.57	0.032201706030122956
3097	51.61	0.03234488531986779
3101	51.65	0.03236810695024639
3105	51.69	0.03224303761317637
3109	51.73	0.032034677333688144
3113	51.77	0.03195135946986927
3117	51.81	0.03175141737956588
3121	51.85	0.03170485108714649
3125	51.89	0.03208499395016906
3129	51.93	0.032604226945063264
3133	51.97	0.03294540723858841
3137	52.01	0.033085677711590655
3141	52.05	0.03326932410187178
3145	52.09	0.033666346432780436
3149	52.13	0.03419341139416199
3153	52.17	0.034153852342330815
3157	52.21	0.03468766930008771
3161	52.25	0.03472152895665337
3165	52.29	0.03488876466773627
3169	52.33	0.03502937645561621
3173	52.37	0.03529003100911643
3177	52.41	0.03515739501692128
3181	52.45	0.03515146850086115
3185	52.49	0.03515891814923311
3189	52.53	0.03537641065012975
3193	52.57	0.03549394602478939
3197	52.61	0.03552152429434541
3201	52.65	0.03546914547980373
3205	52.69	0.034896809601972834
3209	52.73	0.03472165953854178
3213	52.77	0.03456560007175424
3217	52.81	0.03455005979316805
3221	52.85	0.034334562532212676
3225	52.89	0.03441077497522693
3229	52.93	0.03438369714168532
3233	52.97	0.03437166238421918
3237	53.01	0.03460633738863095
3241	53.05	0.034567722173863835
3245	53.09	0.034275816758672306
3249	53.13	0.0341439544949762
3253	53.17	0.03416213540122115
3257	53.21	0.03452035949564358
3261	53.25	0.03472362679630159
3265	53.29	0.03481693732107871
3269	53.33	0.034856719659108304
3273	53.37	0.035153688113665815
3277	53.41	0.03572212841634226
3281	53.45	0.03587061201273656
3285	53.49	0.03580913891964732
3289	53.53	0.035294375820277946
3293	53.57	0.034846322730935686
3297	53.61	0.034364979667732776
3301	53.65	0.034293679979882974
3305	53.69	0.03413575701630123
3309	53.73	0.03432121079227901
3313	53.77	0.03500670798956396
3317	53.81	0.035558915289670256
3321	53.85	0.0362778327072073
3325	53.89	0.03664679358981804
3329	53.93	0.03661579795150338
3333	53.97	0.037134845806104266
3337	54.01	0.037693937167251335
3341	54.05	0.038223072048358286
3345	54.09	0.03840891712936223
3349	54.13	0.03898147242335659
3353	54.17	0.03909740460991307
3357	54.21	0.039066713701708444
3361	54.25	0.03908606637793488
3365	54.29	0.03918879598427738
3369	54.33	0.03940823586619491
3373	54.37	0.039677719368906406
3377	54.41	0.03958057983737007
3381	54.45	0.039691817282959896
3385	54.49	0.03976976505011276
3389	54.53	0.04005608981630937
3393	54.57	0.040025791592132265
3397	54.61	0.04016220372134427
3401	54.65	0.04021532621414847
3405	54.69	0.04043515908048079
3409	54.73	0.040480035663370995
3413	54.77	0.04023495597234694
3417	54.81	0.04044492001674138
3421	54.85	0.04048159447241506
3425	54.89	0.040334979348437106
3429	54.93	0.040871741320360755
3433	54.97	0.041291880396871594
3437	55.01	0.041095396586461774
3441	55.05	0.041140623230688345
3445	55.09	0.04115589367092154
3449	55.13	0.041239541248395906
3453	55.17	0.04130156597087531
3457	55.21	0.04151363451263368
3461	55.25	0.04136741354776374
3465	55.29	0.04143790308348372
3469	55.33	0.04129176979342297
3473	55.37	0.04136234701762964
3477	55.41	0.04174963476250948
3481	55.45	0.04204529970089288
3485	55.49	0.042507675172146264
3489	55.53	0.04294509451543771
3493	55.57	0.04303255773635062
3497	55.61	0.042953398173616986
3501	55.65	0.042999282499120106
3505	55.69	0.04327021071790149
3509	55.73	0.043123325691949876
3513	55.77	0.04308719885445056
3517	55.81	0.04324159211448819
3521	55.85	0.043479362618925155
3525	55.89	0.043650510371543216
3529	55.93	0.044088368709258585
3533	55.97	0.04383293763535567
3537	56.02	0.04424755048614015
3541	56.06	0.04433554059772282
3545	56.1	0.04405690797276174
3549	56.14	0.04427831928042414
3553	56.18	0.04429977452306977
3557	56.22	0.04448794036961301
3561	56.26	0.044717816822148926
3565	56.3	0.044631070549214336
3569	56.34	0.044536034885802156
3573	56.38	0.044957709833353565
3577	56.42	0.044979428726464654
3581	56.46	0.04495119156620353
3585	56.5	0.04507299835344769
3589	56.54	0.04532818242215608
3593	56.58	0.04554674377273127
3597	56.62	0.04573868240540779
3601	56.66	0.04631066498697223
3605	56.7	0.04644269151739211
3609	56.74	0.046354761996394434
3613	56.78	0.04630187642337358
3617	56.82	0.0463490347974016
3621	56.86	0.04633123711736653
3625	56.9	0.046600626239116316
3629	56.94	0.04679077358964934
3633	56.98	0.04667144107193222
3637	57.02	0.04676048582676939
3641	57.06	0.0467829078518629
3645	57.1	0.04715537381136281
3649	57.14	0.04727788370259667
3653	57.18	0.047617104189376924
3657	57.22	0.04812303526863593
3661	57.26	0.04839567693706526
3665	57.3	0.048501695857809946
3669	57.34	0.04874109202713717
3673	57.38	0.048973865441057196
3677	57.42	0.04908668276206862
3681	57.46	0.04940954398581576
3685	57.5	0.04991578244106254
3689	57.54	0.05033873145635859
3693	57.58	0.05071839102669484
3697	57.62	0.05125142781347636
3701	57.66	0.051357841811131344
3705	57.7	0.05153763301377401
3709	57.74	0.05194222998673892
3713	57.78	0.05181068034271785
3717	57.82	0.05221726978935459
3721	57.86	0.05239056974824852
3725	57.9	0.05268058021216193
3729	57.94	0.052737301173649165
3733	57.98	0.05281073262504865
3737	58.02	0.05305087455837176
3741	58.06	0.053407726965382096
3745	58.1	0.05333128983765256
3749	58.14	0.05397156316643548
3753	58.18	0.0544214040855997
3757	58.22	0.054932241157367834
3761	58.26	0.05517597913422856
3765	58.3	0.05562476086370882
3769	58.34	0.05557358633596188
3773	58.38	0.05584745554081305
3777	58.42	0.05625470180117009
3781	58.46	0.05669532510636799
3785	58.5	0.057202658778818805
3789	58.54	0.05737670280741858
3793	58.58	0.05781745718091846
3797	58.62	0.05823158855452215
3801	58.66	0.05871576358313746
3805	58.7	0.059006648921385185
3809	58.74	0.059314244556885054
3813	58.78	0.05995521714351337
3817	58.82	0.06061290000145636
3821	58.86	0.060737293117229196
3825	58.9	0.06087172981045752
3829	58.94	0.06111954340047765
3833	58.98	0.06136073387294383
3837	59.02	0.0620553012131877
3841	59.06	0.06215991207288063
3845	59.1	0.06208456643679261
3849	59.14	0.062259264289467264
3853	59.18	0.062234005615167565
3857	59.22	0.06274212373118493
3861	59.26	0.06344361862115244
3865	59.3	0.06395849026842093
3869	59.34	0.06439340532284499
3873	59.38	0.06437503043409887
3877	59.42	0.06495836558489332
3881	59.46	0.0652834107575937
3885	59.5	0.06528349926761567
3889	59.54	0.0658586310967566
3893	59.58	0.0663838062264821
3897	59.62	0.06669235797127193
3901	59.66	0.06713428631194285
3905	59.7	0.06763459122902349
3909	59.74	0.06783493936944707
3913	59.78	0.06828533071319765
3917	59.82	0.0687607652399782
3921	59.86	0.069191242929171
3925	59.9	0.06966676375982761
3929	59.94	0.07016232771067221
3933	59.98	0.07023793476002549
3937	60.02	0.0707135848858429
3941	60.06	0.0711559447325043
3945	60.1	0.07132501427750926
3949	60.14	0.07172079349818228
3953	60.18	0.07241661570499769
3957	60.22	0.0727424808748589
3961	60.26	0.07351838898442242
3965	60.3	0.07427767334332991
3969	60.34	0.07483700059417586
3973	60.38	0.07515637071253689
3977	60.42	0.07497245034037947
3981	60.46	0.07530857278600056
3985	60.5	0.07594973802410054
3989	60.54	0.07640094602905867
3993	60.58	0.07667719677498042
3997	60.62	0.07712015690240337
4001	60.66	0.07792982638489487
4005	60.7	0.07832049091000481
4009	60.74	0.07878262664113311
4013	60.78	0.07933409069372876
4017	60.82	0.08003559732581689
4021	60.86	0.08064547984273052
4025	60.9	0.08118873821611672
4029	60.94	0.08154870575061146
4033	60.98	0.0820020490838731
4037	61.02	0.0824437681865402
4041	61.06	0.0829955296955247
4045	61.1	0.08337233358069085
4049	61.14	0.08384917981150952
4053	61.18	0.08414606835713778
4057	61.22	0.08453633251972237
4061	61.26	0.08510497226770752
4065	61.3	0.08583698756923175
4069	61.34	0.08633404505885656
4073	61.38	0.0870540018471182
4077	61.42	0.08756328647284395
4081	61.46	0.08829047033164539
4085	61.5	0.08922269624734991
4089	61.54	0.08971996418631845
4093	61.58	0.0900139407812448
4097	61.62	0.09032462599774238
4101	61.66	0.09070201980104375
4105	61.7	0.09136945548946063
4109	61.74	0.092256933027687
4113	61.78	0.09265945238011764
4117	61.82	0.09322868017743202
4121	61.86	0.09348961638321773
4125	61.9	0.09434226096070919
4129	61.94	0.0949949472060716
4133	61.98	0.0954560084151046
4137	62.02	0.09632544454989844
4141	62.06	0.09672825557215248
4145	62.1	0.09730610810986251
4149	62.14	0.09781733545735838
4153	62.18	0.0977819375752933
4157	62.22	0.09813991442394743
4161	62.26	0.09906793262985092
4165	62.3	0.09959599215248316
4169	62.34	0.09989909295095867
4173	62.38	0.1001808064126104
4177	62.42	0.10055541821013492
4181	62.46	0.1012086425873191
4185	62.5	0.10192690807329274
4189	62.54	0.10249021462532193
4193	62.58	0.10304356220017796
4197	62.62	0.10329695075416989
4201	62.66	0.10376704690982619
4205	62.7	0.10427885062258824
4209	62.74	0.10495736184754811
4213	62.78	0.10546924720614825
4217	62.82	0.10564783998616223
4221	62.86	0.10577314014164818
4225	62.9	0.10639681429291947
4229	62.94	0.1070505290598498
4233	62.98	0.10697214153809931
4237	63.02	0.10754141358481828
4241	63.06	0.10823691658059875
4245	63.1	0.10836579333423302
4249	63.14	0.10890471046361405
4253	63.18	0.10929866791966081
4257	63.22	0.10946933231964184
4261	63.26	0.10998170361388526
4265	63.3	0.11006078175240752
4269	63.34	0.11028990001814387
4273	63.38	0.11063905836024235
4277	63.42	0.11109825672742701
4281	63.46	0.11147749506808591
4285	63.5	0.11145677333026827
4289	63.54	0.11168609146165664
4293	63.58	0.11164878274286094
4297	63.62	0.11164484712073941
4301	63.66	0.11157428454173424
4305	63.7	0.11152042828520292
4309	63.74	0.11169327829677878
4313	63.78	0.11161283452171
4317	63.82	0.1117257635715303
4321	63.86	0.11177206539076279
4325	63.9	0.1116017399235556
4329	63.94	0.11163145378032313
4333	63.98	0.11171120690433822
4337	64.02	0.11159099923830551
4341	64.06	0.11139583072447268
4345	64.1	0.11105070130467931
4349	64.14	0.11058061092041749
4353	64.18	0.11048555951284644
4357	64.22	0.11035721368941998
4361	64.26	0.11007057339058246
4365	64.3	0.1099173052231266
4369	64.34	0.10973074246021008
4373	64.38	0.10926088504136544
4377	64.42	0.10891606623911354
4381	64.46	0.10845128599223353
4385	64.5	0.10767654423913209
4389	64.54	0.10718184091780225
4393	64.58	0.10652884263244777
4397	64.62	0.10609254932022472
4401	64.66	0.1057729609178959
4405	64.7	0.10531341069519584
4409	64.74	0.10468389858816618
4413	64.78	0.1037144245325945
4417	64.82	0.1033949884639016
4421	64.86	0.10335059031718119
4425	64.9	0.10241623002717581
4429	64.94	0.10103690752830463
4433	64.98	0.09964262275463343
4437	65.02	0.09834837563984289
4441	65.06	0.09731249945048637
4445	65.1	0.09620999411945386
4449	65.14	0.09546085957935846
4453	65.18	0.09484676242924817
4457	65.22	0.0937227026012879
4461	65.26	0.09303368002732748
4465	65.3	0.09214469463888841
4469	65.34	0.0915124130337821
4473	65.38	0.09100683514277108
4477	65.42	0.08998796089627925
4481	65.46	0.08902245689106358
4485	65.5	0.08783698972354559
4489	65.54	0.08671822598982581
4493	65.58	0.08559283228562986
4497	65.62	0.08445414187308797
4501	65.66	0.08326215468075615
4505	65.7	0.08210187063688901
4509	65.74	0.08095828966942253
4513	65.78	0.07977307837260028
4517	65.82	0.07859623667367677
4521	65.86	0.07745276449951266
4525	65.9	0.07623432844329381
4529	65.94	0.0744159284311694
4533	65.98	0.07284756438895901
4537	66.02	0.07169590290889971
4541	66.06	0.07015094391630416
4545	66.1	0.06854268733627267
4549	66.14	0.06695446642701786
4553	66.18	0.06527628111315353
4557	66.22	0.06440479798557908
4561	66.26	0.06322001696821422
4565	66.3	0.06200193798472986
4569	66.34	0.06056722762528155
4573	66.38	0.05899445724171892
4577	66.42	0.05774791247134914
4581	66.46	0.056396640855974844
4585	66.5	0.054652070889510185
4589	66.54	0.05379420249423017
4593	66.58	0.052151368925606345
4597	66.62	0.05103357010552578
4601	66.66	0.05014080595561765
4605	66.7	0.04878307639731583
4609	66.74	0.04763871468519776
4613	66.78	0.04678772074032089
4617	66.82	0.04581009448348761
4621	66.86	0.04468583583517427
4625	66.9	0.04339494471565297
4629	66.94	0.042567421044946485
4633	66.98	0.04074993140948635
4637	67.02	0.03944914239543307
4641	67.06	0.03851505392204535
4645	67.1	0.03722766590833215
4649	67.14	0.03606364493982017
4653	67.18	0.03471299093519331
4657	67.22	0.033735703812925344
4661	67.26	0.032878450157821426
4665	67.3	0.03130122988778661
4669	67.34	0.030094042920547626
4673	67.38	0.029226889173612935
4677	67.42	0.02780976856425177
4681	67.46	0.02694268100948971
4685	67.5	0.0263006264260488
4689	67.54	0.024983604730377973
4693	67.58	0.02424161583872797
4697	67.62	0.023524659667199188
4701	67.66	0.02258273613175943
4705	67.7	0.021813067370427763
4709	67.74	0.021323986632124203
4713	67.78	0.020457160498916327
4717	67.82	0.01974036666382606
4721	67.86	0.018623605041965252
4725	67.9	0.018106875548371537
4729	67.94	0.017890178098041165
4733	67.98	0.017348512605786848
4737	68.02	0.01702354565293307
4741	68.06	0.01694027715406854
4745	68.1	0.01625704035693687
4749	68.14	0.015673835175813444
4753	68.18	0.015223994858161394
4757	68.22	0.014724185984590576
4761	68.26	0.01449107513557868
4765	68.3	0.014407995558189945
4769	68.34	0.01392494716606052
4773	68.38	0.013771096539325622
4777	68.42	0.013792276924633473
4781	68.46	0.0137009882351391
4785	68.5	0.013509730383875596
4789	68.54	0.013418503283888938
4793	68.58	0.012713021133805125
4797	68.62	0.012451140989161225
4801	68.66	0.012061672286197034
4805	68.7	0.011812233984785259
4809	68.74	0.011362825997031756
4813	68.78	0.011126781568215893
4817	68.82	0.010850767276776363
4821	68.86	0.01078978303435818
4825	68.9	0.010665495419071913
4829	68.94	0.010416237675430207
4833	68.98	0.010383676381089835
4837	69.02	0.009726144780304757
4841	69.06	0.009635309450608087
4845	69.1	0.00951950363604448
4849	69.14	0.009343727247258737
4853	69.18	0.009187980194809153
4857	69.22	0.008922262389135849
4861	69.26	0.009206573740463853
4865	69.3	0.009180914158851028
4869	69.34	0.009150283554201888
4873	69.38	0.008934681836231029
4877	69.42	0.008894108914466514
4881	69.46	0.008507136126814085
4885	69.5	0.008243049096716693
4889	69.54	0.008247562018904642
4893	69.58	0.008007103373663504
4897	69.62	0.008316673069673985
4901	69.66	0.008101271015426903
4905	69.7	0.007985897119304752
4909	69.74	0.008230551289591492
4913	69.78	0.007730233434441569
4917	69.82	0.007706610128497271
4921	69.86	0.0077746812795260745
4925	69.9	0.008042780128436622
4929	69.94	0.007994239915938284
4933	69.98	0.007904060549242864
4937	70.02	0.007643908602150695
4941	70.06	0.007828783981602694
4945	70.1	0.008333686594291123
4949	70.14	0.008668616346661384
4953	70.18	0.008903573145040866
4957	70.22	0.009188556895584288
4961	70.26	0.009273567504334945
4965	70.3	0.009658604877268218
4969	70.34	0.009693668920134346
4973	70.38	0.00952875953849297
4977	70.42	0.009573876637829493
4981	70.46	0.009249020123520246
4985	70.5	0.009255618472244098
4989	70.54	0.009219385874921215
4993	70.58	0.008304607950968101
4997	70.62	0.007659856033967571
5001	70.66	0.00710013002889287
5005	70.7	0.007110429840652799
5009	70.74	0.00681575537401935
5013	70.78	0.006561106533634842
5017	70.82	0.006299816557388205
5021	70.86	0.0064852186830388625
5025	70.9	0.006137312814838314
5029	70.94	0.006056098856826786
5033	70.98	0.005448243379561291
5037	71.02	0.005260412953465909
5041	71.06	0.004804274148869858
5045	71.1	0.004539826869269792
5049	71.14	0.004250404351315851
5053	71.18	0.00408600649816071
5057	71.22	0.0038216332128269137
5061	71.26	0.00384061773160127
5065	71.3	0.0037429599574152483
5069	71.34	0.0037453264598217295
5073	71.38	0.0038358123797199717
5077	71.42	0.0035251319055098485
5081	71.46	0.003669237320704344
5085	71.5	0.0034016999562802575
5089	71.54	0.0033675197144815705
5093	71.58	0.0036600298307618573
5097	71.62	0.0035792302071078197
5101	71.66	0.0036484540787329323
5105	71.7	0.003571034680856844
5109	71.74	0.003436971915289355
5113	71.78	0.0034729323503257525
5117	71.82	0.0034922492207836164
5121	71.86	0.0034949224280458324
5125	71.9	0.003680951873399785
5129	71.94	0.003567004124751083
5133	71.98	0.003403079083221794
5137	72.02	0.0034391766497336995
5141	72.06	0.003500296725106544
5145	72.1	0.0035781058766826135
5149	72.14	0.003714270671668185
5153	72.18	0.0035087910105455755
5157	72.22	0.0036950001271525146
5161	72.26	0.003856231255310316
5165	72.3	0.003817484295408402
5169	72.34	0.003985902004836728
5173	72.38	0.004181722378981068
5177	72.42	0.004168040556006503
5181	72.46	0.004512713578738836
5185	72.5	0.004934074680301936
5189	72.54	0.004860457093692094
5193	72.58	0.0046718607184708105
5197	72.62	0.0047666187874058075
5201	72.66	0.00445306453322214
5205	72.7	0.003926197855244951
5209	72.74	0.003942685319430872
5213	72.78	0.0038291934916072634
5217	72.82	0.003465722270829197
5221	72.86	0.0034772715560920098
5225	72.9	0.0037888412463393806
5229	72.94	0.0037754312404825185
5233	72.98	0.0034120414372460495
5237	73.02	0.0030386717351924553
5241	73.06	0.0030519886994442302
5245	73.1	0.0028969922283228478
5249	73.14	0.0022986822199859702
5253	73.18	0.0016453919058130317
5257	73.22	0.0015987878504155617
5261	73.26	0.001418869951578472
5265	73.3	0.0012656381069517941
5269	73.34	0.0011424255474552503
5273	73.38	0.0010592321705948926
5277	73.42	0.0011493912071234291
5281	73.46	0.0012529025544112393
5285	73.5	0.001439766109777807
5289	73.54	0.0016866484370412493
5293	73.58	0.001733549433159176
5297	73.62	0.0018671356615946877
5301	73.66	0.001587407018963205
5305	73.7	0.001749363401730708
5309	73.74	0.002128004706229536
5313	73.78	0.002331664162043001
5317	73.82	0.002235341665339785
5321	73.86	0.0019223704454827129
5325	73.9	0.0016594170649950613
5329	73.94	0.0016214814195292249
5333	73.98	0.0018085634045905685
5337	74.02	0.0015456629155514712
5341	74.06	0.0017577798476691164
5345	74.1	0.0012449140960981708
5349	74.14	0.0013570655557857414
5353	74.18	0.000844234121467391
5357	74.22	0.000856419687753629
5361	74.26	0.0006186221491533139
5365	74.3	0.0001008414000445157
5369	74.34	-0.0004890655225580076
5373	74.38	-0.0004646701531885178
5377	74.42	-0.000924067835938569
5381	74.46	-0.0016201158195614518
5385	74.5	-0.0015828142097351616
5389	74.54	-0.0018954964453059553
5393	74.58	-0.0020081626315588963
5397	74.62	-0.0023708128735187017
5401	74.66	-0.00259344727603672
5405	74.7	-0.003196065943756654
5409	74.74	-0.0035086689810222005
5413	74.78	-0.003946256491851319
5417	74.82	-0.0040088285800381485
5421	74.86	-0.0040213853491715135
5425	74.9	-0.004358926902531035
5429	74.94	-0.0045614533430775595
5433	74.98	-0.0048339647733848246
5437	75.02	-0.004621461295732043
5441	75.06	-0.004625609678769127
5445	75.1	-0.004804743357544439
5449	75.14	-0.00474386243349878
5453	75.18	-0.0042963003410587675
5457	75.22	-0.004008723847525708
5461	75.26	-0.003921133053197412
5465	75.3	-0.003744639169138253
5469	75.34	-0.0037125756282851974
5473	75.38	-0.0035782758632425526
5477	75.42	-0.0034706288618755465
5481	75.46	-0.0030629680562457295
5485	75.5	-0.003145293544739136
5489	75.54	-0.0029076054255150474
5493	75.58	-0.0026199037964884653
5497	75.62	-0.0027321887553100055
5501	75.66	-0.0033444603994130517
5505	75.7	-0.0036967188259997563
5509	75.74	-0.004218964131966985
5513	75.78	-0.0037478630806235813
5517	75.82	-0.00339341576837926
5521	75.86	-0.003280622291405688
5525	75.9	-0.003097816078907023
5529	75.94	-0.0032299972264739907
5533	75.98	-0.003192165829458471
5537	76.02	-0.003154321982973496
5541	76.06	-0.0030914657818930102
5545	76.1	-0.002978597320837384
5549	76.14	-0.0028507166941427187
5553	76.18	-0.002902823995885928
5557	76.22	-0.00261491931988056
5561	76.26	-0.0026520027597496387
5565	76.3	-0.002639074409006792
5569	76.34	-0.002817801027607647
5573	76.38	-0.002863182708474632
5577	76.42	-0.002800219544201621
5581	76.46	-0.0026272449604851644
5585	76.5	-0.002599259049548497
5589	76.54	-0.002744595236733982
5593	76.58	-0.0027832536137792907
5597	76.62	-0.0026019009389091075
5601	76.66	-0.0025972039701325222
5605	76.7	-0.002773448512827681
5609	76.74	-0.0027377775149695083
5613	76.78	-0.002443048210093224
5617	76.82	-0.0020283083077803354
5621	76.86	-0.002140224564976645
5625	76.9	-0.00225213040496941
5629	76.94	-0.0025106925841038574
5633	76.98	-0.0023997207156147837
5637	77.02	-0.0024877863172938497
5641	77.06	-0.0020663180495721356
5645	77.1	-0.0018448398107739905
5649	77.14	-0.0013566850228916572
5653	77.18	-0.0010351871077332042
5657	77.22	-0.00021367948690631522
5661	77.26	-0.00019216224852902641
5665	77.3	-0.00068730214732593
5669	77.34	-0.0008490992712633094
5673	77.38	-0.0013108870414728635
5677	77.42	-0.001822665545504698
5681	77.46	-0.0021177682040249834
5685	77.5	-0.0022961951041775563
5689	77.54	-0.0024412796662387493
5693	77.58	-0.0022696886436390784
5697	77.62	-0.0024314221229637667
5701	77.66	-0.0028764801905953874
5705	77.7	-0.002994862932628184
5709	77.74	-0.003133237101548225
5713	77.78	-0.0037449361162398276
5717	77.82	-0.003956626728689017
5721	77.86	-0.003951642357279628
5725	77.9	-0.0041133164201330175
5729	77.94	-0.004091649001757958
5733	77.98	-0.004036640186355633
5737	78.02	-0.0038816233911105336
5741	78.06	-0.0037599320328993713
5745	78.1	-0.003671566194968001
5749	78.14	-0.0033974783411956366
5753	78.18	-0.003174811411269296
5757	78.22	-0.00330642263027503
5761	78.26	-0.0036513596992229225
5765	78.3	-0.003758194128325343
5769	78.34	-0.0035912117132124166
5773	78.38	-0.0030385077730454846
5777	78.42	-0.002351868102993482
5781	78.46	-0.0020092689742208236
5785	78.5	-0.0015708295147929263
5789	78.54	-0.0015657164715534577
5793	78.58	-0.0014439299244606296
5797	78.62	-0.0021888032866423934
5801	78.66	-0.00278366997102264
5805	78.7	-0.0036118633903474695
5809	78.74	-0.0040900502904546165
5813	78.78	-0.004768230750204605
5817	78.82	-0.005254738181423857
5821	78.86	-0.0057579059955732426
5825	78.9	-0.0057027342704483175
5829	78.94	-0.005814223083495218
5833	78.98	-0.006375705845042656
5837	79.02	-0.006562182631645541
5841	79.06	-0.00633198685270564
5845	79.1	-0.006320118583856171
5849	79.14	-0.0065715779003778785
5853	79.18	-0.0065830315438173415
5857	79.22	-0.00665447958855836
5861	79.26	-0.0070309221085134155
5865	79.3	-0.007497359177184748
5869	79.34	-0.007448790867739419
5873	79.38	-0.007290217252888365
5877	79.42	-0.00727163840485856
5881	79.46	-0.007243054395317028
5885	79.5	-0.0072994652954334605
5889	79.54	-0.007385871175952019
5893	79.58	-0.007130605440541338
5897	79.62	-0.006842001492500582
5901	79.66	-0.006920059401412715
5905	79.7	-0.007214779236435653
5909	79.74	-0.007276161066318121
5913	79.78	-0.00755420495943282
5917	79.82	-0.00781557765043539
5921	79.86	-0.008143612540238987
5925	79.9	-0.008363309695849086
5929	79.94	-0.008166335850364081
5933	79.98	-0.007861024402966432
5937	80.02	-0.008047375418966496
5941	80.06	-0.008133722296491452
5945	80.1	-0.00772506509979376
5949	80.14	-0.007739737225867405
5953	80.18	-0.008047738737860577
5957	80.22	-0.0077290696984357865
5961	80.26	-0.007790396836370839
5965	80.3	-0.008135053546610926
5969	80.34	-0.008338039890237958
5973	80.38	-0.00814435592780871
5977	80.42	-0.008198168385952442
5981	80.46	-0.008171977324147761
5985	80.5	-0.007958282801474592
5989	80.54	-0.008002918209806698
5993	80.58	-0.0077558836072548765
5997	80.62	-0.007767179051444195
6001	80.66	-0.007923471266169546
6005	80.7	-0.00776476030809814
6009	80.74	-0.007692712900101206
6013	80.78	-0.0073944719550746996
6017	80.82	-0.007348608956870173
6021	80.86	-0.007359885864961502
6025	80.9	-0.00731115987639841
6029	80.94	-0.0071324310449387696
6033	80.98	-0.007233699423910611
6037	81.02	-0.007204965066188951
6041	81.06	-0.0068162280242241025
6045	81.1	-0.006327488349944677
6049	81.14	-0.006605412761496066
6053	81.18	-0.006850001309942844
6057	81.22	-0.006836254045974766
6061	81.26	-0.006947504353262968
6065	81.3	-0.006883752281756195
6069	81.34	-0.007128331214262484
6073	81.38	-0.007231241199860516
6077	81.42	-0.007317482287226618
6081	81.46	-0.00742872119131599
6085	81.5	-0.007389957959989868
6089	81.54	-0.007451192640705706
6093	81.58	-0.007222425280469569
6097	81.62	-0.007173655925816647
6101	81.66	-0.0067848846227587245
6105	81.7	-0.006696111416775619
6109	81.74	-0.00706733635282486
6113	81.78	-0.007185226142002676
6117	81.82	-0.007479780828209659
6121	81.86	-0.0076660004548618765
6125	81.9	-0.007652218398217503
6129	81.94	-0.007430101367293496
6133	81.98	-0.007746077975324006
6137	82.02	-0.007585862549272182
6141	82.06	-0.007372074177467436
6145	82.1	-0.007233284328668876
6149	82.14	-0.007019493042580205
6153	82.18	-0.007230700358347164
6157	82.22	-0.007801906314674145
6161	82.26	-0.008053110949877595
6165	82.3	-0.008214314301878467
6169	82.34	-0.008442183074787835
6173	82.38	-0.00840338397216156
6177	82.42	-0.00864791703034351
6181	82.46	-0.008742448951850612
6185	82.5	-0.008553646438660412
6189	82.54	-0.008556509525540879
6193	82.58	-0.008809371580092762
6197	82.62	-0.009353899302725566
6201	82.66	-0.00971509272657567
6205	82.7	-0.009704856646091553
6209	82.74	-0.009787476807359141
6213	82.78	-0.00986533419385971
6217	82.82	-0.009776524074144533
6221	82.86	-0.009571046478126899
6225	82.9	-0.01003223476853865
6229	82.94	-0.010076755640873625
6233	82.98	-0.009983180551860205
6237	83.02	-0.0101657952433869
6241	83.06	-0.010276980694857052
6245	83.1	-0.010813165504126143
6249	83.14	-0.011239349697138579
6253	83.18	-0.010810533299312475
6257	83.22	-0.010671716335515224
6261	83.26	-0.010672898830170752
6265	83.3	-0.011077414140622466
6269	83.34	-0.011121928957152694
6273	83.38	-0.011309300445752513
6277	83.42	-0.011460957200449595
6281	83.46	-0.01138880400516884
6285	83.5	-0.010799983738549734
6289	83.54	-0.010751163088174476
6293	83.58	-0.01102234207431918
6297	83.62	-0.01103352071663366
6301	83.66	-0.01114469903423343
6305	83.7	-0.010995877045653746
6309	83.74	-0.01102705476880228
6313	83.78	-0.010849660792432658
6317	83.82	-0.011189409419086527
6321	83.86	-0.011400586379357147
6325	83.9	-0.011645096450969561
6329	83.94	-0.011889606315897527
6333	83.98	-0.011734115988935034
6337	84.02	-0.011820292150937828
6341	84.06	-0.011989801482195528
6345	84.1	-0.01230097732915425
6349	84.14	-0.0120954863710665
6353	84.18	-0.01218999528661957
6357	84.22	-0.012401170753952417
6361	84.26	-0.012379012784040633
6365	84.3	-0.012173521387319752
6369	84.34	-0.012314696573650252
6373	84.38	-0.012265871685698926
6377	84.42	-0.012417046732277726
6381	84.46	-0.012268221721642103
6385	84.5	-0.012179396661387898
6389	84.54	-0.012457238225170197
6393	84.58	-0.01272174641950885
6397	84.62	-0.012572921250354696
6401	84.66	-0.012424096056330658
6405	84.7	-0.012285270842146367
6409	84.74	-0.012171445612040088
6413	84.78	-0.012129048941239784
6417	84.82	-0.012502128452042793
6421	84.86	-0.012646636528145017
6425	84.9	-0.012691144600444293
6429	84.94	-0.012702319337403178
6433	84.98	-0.013173494073614567
6434	84.99	-0.013141287757643116